<?xml version="1.0" encoding="utf-8"?>
<mujoco model="door_knob">
	<compiler angle="radian"/>
	<include file="../../robot/blue_floatinghook.xml"/>
	<option gravity="0 0 0" timestep="0.001"/>
	<visual>
		<map fogend="5" fogstart="3" force="0.1" zfar="10" znear="0.01"/>
		<quality shadowsize="2048"/>
		<global offheight="256" offwidth="256"/>
	</visual>
	<asset>
		<mesh file="../../door/pullknobs/1555111995/body_1.stl" name="door_knob_1" scale="0.001 0.001 0.001"/>
		<mesh file="../../door/pullknobs/1555111995/body_2.stl" name="door_knob_2" scale="0.001 0.001 0.001"/>
		<mesh file="../../door/pullknobs/1555111995/body_3.stl" name="door_knob_3" scale="0.001 0.001 0.001"/>
		<mesh file="../../door/pullknobs/1555111995/body_4.stl" name="door_knob_4" scale="0.001 0.001 0.001"/>
		<mesh file="../../door/pullknobs/1555111995/body_5.stl" name="door_knob_5" scale="0.001 0.001 0.001"/>
		<mesh file="../../door/pullknobs/1555111995/body_6.stl" name="door_knob_6" scale="0.001 0.001 0.001"/>
		<mesh file="../../door/pullknobs/1555111995/body_7.stl" name="door_knob_7" scale="0.001 0.001 0.001"/>
		<mesh file="../../door/pullknobs/1555111995/body_8.stl" name="door_knob_8" scale="0.001 0.001 0.001"/>
		<texture builtin="flat" height="32" name="wall_geom" type="2d" width="32"/>
		<texture builtin="flat" height="32" name="frame_geom" type="2d" width="32"/>
		<texture builtin="flat" height="32" name="door_geom" type="2d" width="32"/>
		<texture builtin="flat" height="32" name="knob_geom" type="2d" width="32"/>
		<texture builtin="gradient" height="128" rgb1="0.4 0.6 0.8" rgb2="0 0 0" type="skybox" width="128"/>
		<texture builtin="checker" height="512" name="texplane" rgb1="0.2 0.3 0.4" rgb2="0.1 0.15 0.2" type="2d" width="512"/>
		<material name="Paint" shininess="0.31" specular="0.3" texture="wall_geom"/>
		<material name="Wood" shininess="0.1" specular="0.1" texture="frame_geom"/>
		<material name="Carpet" shininess="0.02" specular="0.03" texture="door_geom"/>
		<material name="Metal" shininess="0.9" specular="0.96" texture="knob_geom"/>
		<material name="Floor" texture="texplane"/>
	</asset>
	<contact>
		<pair geom1="doorstopper" geom2="door0" solref="0.01 1"/>
	</contact>
	<default>
		<joint armature="1" damping="1" limited="true"/>
		<default class="wall">
			<geom rgba="0.06 0.24 0.09 1.0" type="mesh"/>
		</default>
		<default class="frame">
			<geom rgba="0.82 0.74 0.78 1.0" type="mesh"/>
		</default>
		<default class="door">
			<geom rgba="0.7 0.77 0.68 1.0" type="mesh"/>
		</default>
		<default class="door_knob">
			<geom condim="4" rgba="0.16 0.89 0.52 1.0" type="mesh"/>
		</default>
		<default class="robot">
			<joint damping="0.1"/>
		</default>
	</default>
	<worldbody>
		<light diffuse="1.0 0.9 0.9" dir="-0.03 0.46 -0.33" directional="true" pos="4.04 -3.67 4.45"/>
		<light diffuse="1.0 0.9 0.9" dir="-0.14 -0.25 -0.34" directional="true" pos="1.28 -1.46 5.42"/>
		<geom material="Floor" name="floor" pos="0 0 -0.05" size="40.0 40.0 0.05" type="plane"/>
		<camera fovy="60" mode="fixed" name="camera1" pos="0.99 -0.5 1.0" euler="0.0 1.57 1.57"/>
		<camera fovy="60" mode="fixed" name="camera2" pos="0.5 0.0 1.99" euler="0 0 0"/>
		<body childclass="wall" name="wall_link" pos="0.0 -0.07 0.0">
			<inertial mass="100" pos="0 0 0" diaginertia="0.0001 0.0001 0.0001"/>
			<geom material="Wood" name="wall_0" pos="0 -1.622 1.116" size="0.15 1.0 1.116" type="box" euler="0 0 0"/>
			<geom material="Wood" name="wall_1" pos="0 1.6520000000000001 1.116" size="0.15 1.0 1.116" type="box" euler="0 0 0"/>
			<geom material="Wood" name="wall_2" pos="0 0 2.732" size="0.15 2.652 0.5" type="box" euler="0 0 0"/>
			<body childclass="frame" name="frame_link" pos="0 -0.35328000000000004 1.009">
				<inertial mass="500" pos="0 0 0" diaginertia="0.0001 0.0001 0.0001"/>
				<geom material="Metal" name="doorstopper" pos="-0.013999999999999999 -0.04872000000000001 1.0730000000000002" size="0.01 0.05 0.025" type="box" euler="0 0 0"/>
				<geom material="Wood" name="door_frame_0" pos="0 -0.25872 0.1070000000000002" size="0.01 0.05 1.116" type="box" euler="0 0 0"/>
				<geom material="Wood" name="door_frame_1" pos="0 0.9652800000000001 0.1070000000000002" size="0.01 0.05 1.116" type="box" euler="0 0 0"/>
				<geom material="Wood" name="door_frame_2" pos="0 0.35328000000000004 1.1730000000000003" size="0.01 0.652 0.05" type="box" euler="0 0 0"/>
				<geom material="Wood" name="door_frame_3" pos="-0.04625 -0.25872 0.1070000000000002" size="0.01 0.05 1.116" type="box" euler="0 0 0"/>
				<geom material="Wood" name="door_frame_4" pos="-0.04625 0.9652800000000001 0.1070000000000002" size="0.01 0.05 1.116" type="box" euler="0 0 0"/>
				<geom material="Wood" name="door_frame_5" pos="-0.04625 0.35328000000000004 1.1730000000000003" size="0.01 0.652 0.05" type="box" euler="0 0 0"/>
				<body childclass="door" name="door_link" pos="0.022000000000000002 0 0">
					<joint armature="0.0001" axis="0 0 1" damping="0.1" frictionloss="0" limited="false" name="hinge0" pos="0 0.9052800000000001 0" range="-0.5 0.5" stiffness="0.13" type="hinge"/>
					<geom material="Wood" name="door0" pos="0 0.35328000000000004 0.05700000000000016" size="0.01 0.552 1.05534" type="box" euler="0 0 0"/>
					<inertial mass="10.450552320000002" pos="0 0.35328000000000004 0.05700000000000016" diaginertia="5.019957642086402 3.9588642957926408 1.0617900497817603"/>
					<body childclass="door_knob" name="knob_link" pos="0 0 0">
						<inertial mass="1" pos="0 0 0" diaginertia="0.001 0.001 0.001"/>
						<joint armature="0" axis="0 1 0" damping="30000" frictionloss="0" limited="true" name="target0" range="-0.2 0.3" stiffness="0" type="slide"/>
						<joint armature="0" axis="0 0 1" damping="30000" frictionloss="0" limited="true" name="target1" range="-0.5 0.5" stiffness="0" type="slide"/>
						<body childclass="door_knob" name="pullknob_link" pos="0.004 0 0">
							<geom friction="0.62 0.002 0.001" material="Paint" mesh="door_knob_1" name="door_knob_1" euler="-1.57 1.57 0"/>
							<geom friction="0.62 0.002 0.001" material="Paint" mesh="door_knob_2" name="door_knob_2" euler="-1.57 1.57 0"/>
							<geom friction="0.62 0.002 0.001" material="Paint" mesh="door_knob_3" name="door_knob_3" euler="-1.57 1.57 0"/>
							<geom friction="0.62 0.002 0.001" material="Paint" mesh="door_knob_4" name="door_knob_4" euler="-1.57 1.57 0"/>
							<geom friction="0.62 0.002 0.001" material="Paint" mesh="door_knob_5" name="door_knob_5" euler="-1.57 1.57 0"/>
							<geom friction="0.62 0.002 0.001" material="Paint" mesh="door_knob_6" name="door_knob_6" euler="-1.57 1.57 0"/>
							<geom friction="0.62 0.002 0.001" material="Paint" mesh="door_knob_7" name="door_knob_7" euler="-1.57 1.57 0"/>
							<geom friction="0.62 0.002 0.001" material="Paint" mesh="door_knob_8" name="door_knob_8" euler="-1.57 1.57 0"/>
						</body>
					</body>
				</body>
			</body>
		</body>
	</worldbody>
</mujoco>