<?xml version="1.0" encoding="utf-8"?>
<mujoco model="door_knob">
	<compiler angle="radian"/>
	<include file="../../robot/blue_floatinghook.xml"/>
	<option gravity="0 0 0" timestep="0.001"/>
	<visual>
		<map fogend="5" fogstart="3" force="0.1" zfar="10" znear="0.01"/>
		<quality shadowsize="2048"/>
		<global offheight="256" offwidth="256"/>
	</visual>
	<asset>
		<mesh file="../../door/pullknobs/1555112008/body_1.stl" name="door_knob_1" scale="0.001 0.001 0.001"/>
		<mesh file="../../door/pullknobs/1555112008/body_2.stl" name="door_knob_2" scale="0.001 0.001 0.001"/>
		<mesh file="../../door/pullknobs/1555112008/body_3.stl" name="door_knob_3" scale="0.001 0.001 0.001"/>
		<mesh file="../../door/pullknobs/1555112008/body_4.stl" name="door_knob_4" scale="0.001 0.001 0.001"/>
		<mesh file="../../door/pullknobs/1555112008/body_5.stl" name="door_knob_5" scale="0.001 0.001 0.001"/>
		<mesh file="../../door/pullknobs/1555112008/body_6.stl" name="door_knob_6" scale="0.001 0.001 0.001"/>
		<mesh file="../../door/pullknobs/1555112008/body_7.stl" name="door_knob_7" scale="0.001 0.001 0.001"/>
		<mesh file="../../door/pullknobs/1555112008/body_8.stl" name="door_knob_8" scale="0.001 0.001 0.001"/>
		<texture builtin="flat" height="32" name="wall_geom" type="2d" width="32"/>
		<texture builtin="flat" height="32" name="frame_geom" type="2d" width="32"/>
		<texture builtin="flat" height="32" name="door_geom" type="2d" width="32"/>
		<texture builtin="flat" height="32" name="knob_geom" type="2d" width="32"/>
		<texture builtin="gradient" height="128" rgb1="0.4 0.6 0.8" rgb2="0 0 0" type="skybox" width="128"/>
		<texture builtin="checker" height="512" name="texplane" rgb1="0.2 0.3 0.4" rgb2="0.1 0.15 0.2" type="2d" width="512"/>
		<material name="Paint" shininess="0.12" specular="0.44" texture="wall_geom"/>
		<material name="Wood" shininess="0.06" specular="0.11" texture="frame_geom"/>
		<material name="Carpet" shininess="0.04" specular="0.01" texture="door_geom"/>
		<material name="Metal" shininess="0.94" specular="0.83" texture="knob_geom"/>
		<material name="Floor" texture="texplane"/>
	</asset>
	<contact>
		<pair geom1="doorstopper" geom2="door0" solref="0.01 1"/>
	</contact>
	<default>
		<joint armature="1" damping="1" limited="true"/>
		<default class="wall">
			<geom rgba="0.65 0.33 0.22 1.0" type="mesh"/>
		</default>
		<default class="frame">
			<geom rgba="0.75 0.73 0.77 1.0" type="mesh"/>
		</default>
		<default class="door">
			<geom rgba="0.56 0.95 0.22 1.0" type="mesh"/>
		</default>
		<default class="door_knob">
			<geom condim="4" rgba="0.05 0.07 0.9 1.0" type="mesh"/>
		</default>
		<default class="robot">
			<joint damping="0.1"/>
		</default>
	</default>
	<worldbody>
		<light diffuse="1.0 0.9 1.0" dir="0.21 0.0 -0.36" directional="true" pos="0.13 0.26 3.05"/>
		<light diffuse="0.9 1.0 0.9" dir="-0.45 0.14 -0.41" directional="true" pos="1.31 -0.83 4.17"/>
		<light diffuse="0.9 1.0 0.9" dir="-0.04 -0.27 -0.33" directional="true" pos="2.2 -2.44 5.69"/>
		<light diffuse="0.9 1.0 1.0" dir="-0.27 0.44 -0.3" directional="true" pos="1.5 -0.53 6.67"/>
		<light diffuse="0.9 0.9 0.9" dir="0.1 -0.11 -0.32" directional="true" pos="1.36 0.7 6.11"/>
		<geom material="Floor" name="floor" pos="0 0 -0.05" size="40.0 40.0 0.05" type="plane"/>
		<camera fovy="60" mode="fixed" name="camera1" pos="0.99 -0.5 1.0" euler="0.0 1.57 1.57"/>
		<camera fovy="60" mode="fixed" name="camera2" pos="0.5 0.0 1.99" euler="0 0 0"/>
		<body childclass="wall" name="wall_link" pos="0.0 -0.001 0.0">
			<inertial mass="100" pos="0 0 0" diaginertia="0.0001 0.0001 0.0001"/>
			<geom material="Carpet" name="wall_0" pos="0 -1.5704999999999998 1.1765" size="0.15 1.0 1.1765" type="box" euler="0 0 0"/>
			<geom material="Carpet" name="wall_1" pos="0 1.6004999999999998 1.1765" size="0.15 1.0 1.1765" type="box" euler="0 0 0"/>
			<geom material="Carpet" name="wall_2" pos="0 0 2.853" size="0.15 2.6005 0.5" type="box" euler="0 0 0"/>
			<body childclass="frame" name="frame_link" pos="0 -0.3303299999999999 1.0">
				<inertial mass="500" pos="0 0 0" diaginertia="0.0001 0.0001 0.0001"/>
				<geom material="Metal" name="doorstopper" pos="-0.0168 -0.020169999999999993 1.203" size="0.012 0.05 0.025" type="box" euler="0 0 0"/>
				<geom material="Paint" name="door_frame_0" pos="0 -0.23016999999999999 0.1765000000000001" size="0.012 0.05 1.1765" type="box" euler="0 0 0"/>
				<geom material="Paint" name="door_frame_1" pos="0 0.89083 0.1765000000000001" size="0.012 0.05 1.1765" type="box" euler="0 0 0"/>
				<geom material="Paint" name="door_frame_2" pos="0 0.33032999999999996 1.3030000000000002" size="0.012 0.6004999999999999 0.05" type="box" euler="0 0 0"/>
				<geom material="Paint" name="door_frame_3" pos="-0.05025 -0.23016999999999999 0.1765000000000001" size="0.012 0.05 1.1765" type="box" euler="0 0 0"/>
				<geom material="Paint" name="door_frame_4" pos="-0.05025 0.89083 0.1765000000000001" size="0.012 0.05 1.1765" type="box" euler="0 0 0"/>
				<geom material="Paint" name="door_frame_5" pos="-0.05025 0.33032999999999996 1.3030000000000002" size="0.012 0.6004999999999999 0.05" type="box" euler="0 0 0"/>
				<body childclass="door" name="door_link" pos="0.026400000000000003 0 0">
					<joint armature="0.0001" axis="0 0 1" damping="0.11" frictionloss="0" limited="false" name="hinge0" pos="0 0.83083 0" range="-0.5 0.5" stiffness="0.17" type="hinge"/>
					<geom material="Carpet" name="door0" pos="0 0.33032999999999996 0.12650000000000006" size="0.012 0.5005 1.115235" type="box" euler="0 0 0"/>
					<inertial mass="14.614039439999999" pos="0 0.33032999999999996 0.12650000000000006" diaginertia="7.4020231547262005 6.1824511175427 1.2209749849697396"/>
					<body childclass="door_knob" name="knob_link" pos="0 0 0">
						<inertial mass="1" pos="0 0 0" diaginertia="0.001 0.001 0.001"/>
						<joint armature="0" axis="0 1 0" damping="30000" frictionloss="0" limited="true" name="target0" range="-0.2 0.3" stiffness="0" type="slide"/>
						<joint armature="0" axis="0 0 1" damping="30000" frictionloss="0" limited="true" name="target1" range="-0.5 0.5" stiffness="0" type="slide"/>
						<body childclass="door_knob" name="pullknob_link" pos="0.006 0 0">
							<geom friction="0.89 0.001 0.001" material="Carpet" mesh="door_knob_1" name="door_knob_1" euler="-1.57 1.57 0"/>
							<geom friction="0.89 0.001 0.001" material="Carpet" mesh="door_knob_2" name="door_knob_2" euler="-1.57 1.57 0"/>
							<geom friction="0.89 0.001 0.001" material="Carpet" mesh="door_knob_3" name="door_knob_3" euler="-1.57 1.57 0"/>
							<geom friction="0.89 0.001 0.001" material="Carpet" mesh="door_knob_4" name="door_knob_4" euler="-1.57 1.57 0"/>
							<geom friction="0.89 0.001 0.001" material="Carpet" mesh="door_knob_5" name="door_knob_5" euler="-1.57 1.57 0"/>
							<geom friction="0.89 0.001 0.001" material="Carpet" mesh="door_knob_6" name="door_knob_6" euler="-1.57 1.57 0"/>
							<geom friction="0.89 0.001 0.001" material="Carpet" mesh="door_knob_7" name="door_knob_7" euler="-1.57 1.57 0"/>
							<geom friction="0.89 0.001 0.001" material="Carpet" mesh="door_knob_8" name="door_knob_8" euler="-1.57 1.57 0"/>
						</body>
					</body>
				</body>
			</body>
		</body>
	</worldbody>
</mujoco>