<?xml version="1.0" encoding="utf-8"?>
<mujoco model="door_knob">
	<compiler angle="radian"/>
	<include file="../../robot/blue_floatinghook.xml"/>
	<option gravity="0 0 0" timestep="0.001"/>
	<visual>
		<map fogend="5" fogstart="3" force="0.1" zfar="10" znear="0.01"/>
		<quality shadowsize="2048"/>
		<global offheight="256" offwidth="256"/>
	</visual>
	<asset>
		<mesh file="../../door/pullknobs/1555111999/body_1.stl" name="door_knob_1" scale="0.001 0.001 0.001"/>
		<mesh file="../../door/pullknobs/1555111999/body_2.stl" name="door_knob_2" scale="0.001 0.001 0.001"/>
		<mesh file="../../door/pullknobs/1555111999/body_3.stl" name="door_knob_3" scale="0.001 0.001 0.001"/>
		<mesh file="../../door/pullknobs/1555111999/body_4.stl" name="door_knob_4" scale="0.001 0.001 0.001"/>
		<mesh file="../../door/pullknobs/1555111999/body_5.stl" name="door_knob_5" scale="0.001 0.001 0.001"/>
		<mesh file="../../door/pullknobs/1555111999/body_6.stl" name="door_knob_6" scale="0.001 0.001 0.001"/>
		<mesh file="../../door/pullknobs/1555111999/body_7.stl" name="door_knob_7" scale="0.001 0.001 0.001"/>
		<mesh file="../../door/pullknobs/1555111999/body_8.stl" name="door_knob_8" scale="0.001 0.001 0.001"/>
		<texture builtin="flat" height="32" name="wall_geom" type="2d" width="32"/>
		<texture builtin="flat" height="32" name="frame_geom" type="2d" width="32"/>
		<texture builtin="flat" height="32" name="door_geom" type="2d" width="32"/>
		<texture builtin="flat" height="32" name="knob_geom" type="2d" width="32"/>
		<texture builtin="gradient" height="128" rgb1="0.4 0.6 0.8" rgb2="0 0 0" type="skybox" width="128"/>
		<texture builtin="checker" height="512" name="texplane" rgb1="0.2 0.3 0.4" rgb2="0.1 0.15 0.2" type="2d" width="512"/>
		<material name="Paint" shininess="0.1" specular="0.11" texture="wall_geom"/>
		<material name="Wood" shininess="0.11" specular="0.13" texture="frame_geom"/>
		<material name="Carpet" shininess="0.02" specular="0.02" texture="door_geom"/>
		<material name="Metal" shininess="0.85" specular="0.88" texture="knob_geom"/>
		<material name="Floor" texture="texplane"/>
	</asset>
	<contact>
		<pair geom1="doorstopper" geom2="door0" solref="0.01 1"/>
	</contact>
	<default>
		<joint armature="1" damping="1" limited="true"/>
		<default class="wall">
			<geom rgba="0.62 0.15 0.01 1.0" type="mesh"/>
		</default>
		<default class="frame">
			<geom rgba="0.77 0.72 0.7 1.0" type="mesh"/>
		</default>
		<default class="door">
			<geom rgba="0.67 0.13 0.91 1.0" type="mesh"/>
		</default>
		<default class="door_knob">
			<geom condim="4" rgba="0.61 0.94 0.43 1.0" type="mesh"/>
		</default>
		<default class="robot">
			<joint damping="0.09"/>
		</default>
	</default>
	<worldbody>
		<light diffuse="0.9 0.9 0.9" dir="-0.2 -0.17 -0.28" directional="true" pos="4.06 -4.24 6.79"/>
		<light diffuse="1.0 0.9 1.0" dir="-0.3 -0.29 -0.28" directional="true" pos="1.27 -3.87 5.76"/>
		<light diffuse="0.9 1.0 0.9" dir="-0.31 0.35 -0.26" directional="true" pos="2.46 0.93 6.62"/>
		<geom material="Floor" name="floor" pos="0 0 -0.05" size="40.0 40.0 0.05" type="plane"/>
		<camera fovy="60" mode="fixed" name="camera1" pos="0.99 -0.5 1.0" euler="0.0 1.57 1.57"/>
		<camera fovy="60" mode="fixed" name="camera2" pos="0.5 0.0 1.99" euler="0 0 0"/>
		<body childclass="wall" name="wall_link" pos="0.0 0.048 0.0">
			<inertial mass="100" pos="0 0 0" diaginertia="0.0001 0.0001 0.0001"/>
			<geom material="Carpet" name="wall_0" pos="0 -1.489 1.1395" size="0.15 1.0 1.1395" type="box" euler="0 0 0"/>
			<geom material="Carpet" name="wall_1" pos="0 1.5190000000000001 1.1395" size="0.15 1.0 1.1395" type="box" euler="0 0 0"/>
			<geom material="Carpet" name="wall_2" pos="0 0 2.779" size="0.15 2.519 0.5" type="box" euler="0 0 0"/>
			<body childclass="frame" name="frame_link" pos="0 -0.26816 0.994">
				<inertial mass="500" pos="0 0 0" diaginertia="0.0001 0.0001 0.0001"/>
				<geom material="Metal" name="doorstopper" pos="-0.018199999999999997 -0.0008400000000000074 1.1349999999999998" size="0.013 0.05 0.025" type="box" euler="0 0 0"/>
				<geom material="Paint" name="door_frame_0" pos="0 -0.21084000000000003 0.14549999999999996" size="0.013 0.05 1.1395" type="box" euler="0 0 0"/>
				<geom material="Paint" name="door_frame_1" pos="0 0.74716 0.14549999999999996" size="0.013 0.05 1.1395" type="box" euler="0 0 0"/>
				<geom material="Paint" name="door_frame_2" pos="0 0.26815999999999995 1.2349999999999999" size="0.013 0.519 0.05" type="box" euler="0 0 0"/>
				<geom material="Paint" name="door_frame_3" pos="-0.052250000000000005 -0.21084000000000003 0.14549999999999996" size="0.013 0.05 1.1395" type="box" euler="0 0 0"/>
				<geom material="Paint" name="door_frame_4" pos="-0.052250000000000005 0.74716 0.14549999999999996" size="0.013 0.05 1.1395" type="box" euler="0 0 0"/>
				<geom material="Paint" name="door_frame_5" pos="-0.052250000000000005 0.26815999999999995 1.2349999999999999" size="0.013 0.519 0.05" type="box" euler="0 0 0"/>
				<body childclass="door" name="door_link" pos="0.0286 0 0">
					<joint armature="0.0001" axis="0 0 1" damping="0.19" frictionloss="0" limited="false" name="hinge0" pos="0 0.68716 0" range="-0.5 0.5" stiffness="0.17" type="hinge"/>
					<geom material="Carpet" name="door0" pos="0 0.26815999999999995 0.09549999999999992" size="0.013 0.419 1.0786049999999998" type="box" euler="0 0 0"/>
					<inertial mass="9.590162503999998" pos="0 0.26815999999999995 0.09549999999999992" diaginertia="4.355759903592801 3.795080642958946 0.5617597522759732"/>
					<body childclass="door_knob" name="knob_link" pos="0 0 0">
						<inertial mass="1" pos="0 0 0" diaginertia="0.001 0.001 0.001"/>
						<joint armature="0" axis="0 1 0" damping="30000" frictionloss="0" limited="true" name="target0" range="-0.2 0.3" stiffness="0" type="slide"/>
						<joint armature="0" axis="0 0 1" damping="30000" frictionloss="0" limited="true" name="target1" range="-0.5 0.5" stiffness="0" type="slide"/>
						<body childclass="door_knob" name="pullknob_link" pos="0.006999999999999999 0 0">
							<geom friction="0.52 0.004 0.002" material="Wood" mesh="door_knob_1" name="door_knob_1" euler="-1.57 1.57 0"/>
							<geom friction="0.52 0.004 0.002" material="Wood" mesh="door_knob_2" name="door_knob_2" euler="-1.57 1.57 0"/>
							<geom friction="0.52 0.004 0.002" material="Wood" mesh="door_knob_3" name="door_knob_3" euler="-1.57 1.57 0"/>
							<geom friction="0.52 0.004 0.002" material="Wood" mesh="door_knob_4" name="door_knob_4" euler="-1.57 1.57 0"/>
							<geom friction="0.52 0.004 0.002" material="Wood" mesh="door_knob_5" name="door_knob_5" euler="-1.57 1.57 0"/>
							<geom friction="0.52 0.004 0.002" material="Wood" mesh="door_knob_6" name="door_knob_6" euler="-1.57 1.57 0"/>
							<geom friction="0.52 0.004 0.002" material="Wood" mesh="door_knob_7" name="door_knob_7" euler="-1.57 1.57 0"/>
							<geom friction="0.52 0.004 0.002" material="Wood" mesh="door_knob_8" name="door_knob_8" euler="-1.57 1.57 0"/>
						</body>
					</body>
				</body>
			</body>
		</body>
	</worldbody>
</mujoco>