<?xml version="1.0" encoding="utf-8"?>
<mujoco model="door_knob">
	<compiler angle="radian"/>
	<include file="../../robot/blue_floatinghook.xml"/>
	<option gravity="0 0 0" timestep="0.001"/>
	<visual>
		<map fogend="5" fogstart="3" force="0.1" zfar="10" znear="0.01"/>
		<quality shadowsize="2048"/>
		<global offheight="256" offwidth="256"/>
	</visual>
	<asset>
		<mesh file="../../door/pullknobs/1555111995/body_1.stl" name="door_knob_1" scale="0.001 0.001 0.001"/>
		<mesh file="../../door/pullknobs/1555111995/body_2.stl" name="door_knob_2" scale="0.001 0.001 0.001"/>
		<mesh file="../../door/pullknobs/1555111995/body_3.stl" name="door_knob_3" scale="0.001 0.001 0.001"/>
		<mesh file="../../door/pullknobs/1555111995/body_4.stl" name="door_knob_4" scale="0.001 0.001 0.001"/>
		<mesh file="../../door/pullknobs/1555111995/body_5.stl" name="door_knob_5" scale="0.001 0.001 0.001"/>
		<mesh file="../../door/pullknobs/1555111995/body_6.stl" name="door_knob_6" scale="0.001 0.001 0.001"/>
		<mesh file="../../door/pullknobs/1555111995/body_7.stl" name="door_knob_7" scale="0.001 0.001 0.001"/>
		<mesh file="../../door/pullknobs/1555111995/body_8.stl" name="door_knob_8" scale="0.001 0.001 0.001"/>
		<texture builtin="flat" height="32" name="wall_geom" type="2d" width="32"/>
		<texture builtin="flat" height="32" name="frame_geom" type="2d" width="32"/>
		<texture builtin="flat" height="32" name="door_geom" type="2d" width="32"/>
		<texture builtin="flat" height="32" name="knob_geom" type="2d" width="32"/>
		<texture builtin="gradient" height="128" rgb1="0.4 0.6 0.8" rgb2="0 0 0" type="skybox" width="128"/>
		<texture builtin="checker" height="512" name="texplane" rgb1="0.2 0.3 0.4" rgb2="0.1 0.15 0.2" type="2d" width="512"/>
		<material name="Paint" shininess="0.3" specular="0.06" texture="wall_geom"/>
		<material name="Wood" shininess="0.09" specular="0.02" texture="frame_geom"/>
		<material name="Carpet" shininess="0.01" specular="0.02" texture="door_geom"/>
		<material name="Metal" shininess="0.88" specular="0.98" texture="knob_geom"/>
		<material name="Floor" texture="texplane"/>
	</asset>
	<contact>
		<pair geom1="doorstopper" geom2="door0" solref="0.01 1"/>
	</contact>
	<default>
		<joint armature="1" damping="1" limited="true"/>
		<default class="wall">
			<geom rgba="0.14 0.15 0.36 1.0" type="mesh"/>
		</default>
		<default class="frame">
			<geom rgba="0.71 0.72 0.75 1.0" type="mesh"/>
		</default>
		<default class="door">
			<geom rgba="0.3 0.11 0.15 1.0" type="mesh"/>
		</default>
		<default class="door_knob">
			<geom condim="4" rgba="0.86 0.62 0.83 1.0" type="mesh"/>
		</default>
		<default class="robot">
			<joint damping="0.1"/>
		</default>
	</default>
	<worldbody>
		<light diffuse="1.0 1.0 0.9" dir="-0.22 0.3 -0.4" directional="true" pos="0.24 -3.75 5.55"/>
		<light diffuse="0.9 0.9 1.0" dir="-0.29 0.04 -0.5" directional="true" pos="0.19 0.85 3.91"/>
		<light diffuse="0.9 0.9 0.9" dir="0.12 0.08 -0.38" directional="true" pos="3.91 -3.45 4.8"/>
		<geom material="Floor" name="floor" pos="0 0 -0.05" size="40.0 40.0 0.05" type="plane"/>
		<camera fovy="60" mode="fixed" name="camera1" pos="0.99 -0.5 1.0" euler="0.0 1.57 1.57"/>
		<camera fovy="60" mode="fixed" name="camera2" pos="0.5 0.0 1.99" euler="0 0 0"/>
		<body childclass="wall" name="wall_link" pos="0.0 0.073 0.0">
			<inertial mass="100" pos="0 0 0" diaginertia="0.0001 0.0001 0.0001"/>
			<geom material="Wood" name="wall_0" pos="0 -1.508 1.2925" size="0.15 1.0 1.2925" type="box" euler="0 0 0"/>
			<geom material="Wood" name="wall_1" pos="0 1.538 1.2925" size="0.15 1.0 1.2925" type="box" euler="0 0 0"/>
			<geom material="Wood" name="wall_2" pos="0 0 3.085" size="0.15 2.5380000000000003 0.5" type="box" euler="0 0 0"/>
			<body childclass="frame" name="frame_link" pos="0 -0.29784 0.994">
				<inertial mass="500" pos="0 0 0" diaginertia="0.0001 0.0001 0.0001"/>
				<geom material="Metal" name="doorstopper" pos="-0.0189 0.009839999999999988 1.4409999999999998" size="0.0135 0.05 0.025" type="box" euler="0 0 0"/>
				<geom material="Wood" name="door_frame_0" pos="0 -0.20016 0.2985" size="0.0135 0.05 1.2925" type="box" euler="0 0 0"/>
				<geom material="Wood" name="door_frame_1" pos="0 0.7958400000000001 0.2985" size="0.0135 0.05 1.2925" type="box" euler="0 0 0"/>
				<geom material="Wood" name="door_frame_2" pos="0 0.29784 1.541" size="0.0135 0.538 0.05" type="box" euler="0 0 0"/>
				<geom material="Wood" name="door_frame_3" pos="-0.053250000000000006 -0.20016 0.2985" size="0.0135 0.05 1.2925" type="box" euler="0 0 0"/>
				<geom material="Wood" name="door_frame_4" pos="-0.053250000000000006 0.7958400000000001 0.2985" size="0.0135 0.05 1.2925" type="box" euler="0 0 0"/>
				<geom material="Wood" name="door_frame_5" pos="-0.053250000000000006 0.29784 1.541" size="0.0135 0.538 0.05" type="box" euler="0 0 0"/>
				<body childclass="door" name="door_link" pos="0.0297 0 0">
					<joint armature="0.0001" axis="0 0 1" damping="0.14" frictionloss="0" limited="false" name="hinge0" pos="0 0.73584 0" range="-0.5 0.5" stiffness="0.19" type="hinge"/>
					<geom material="Carpet" name="door0" pos="0 0.29784 0.24849999999999994" size="0.0135 0.438 1.230075" type="box" euler="0 0 0"/>
					<inertial mass="12.0489201" pos="0 0.29784 0.24849999999999994" diaginertia="6.970903727931675 6.201131357272949 0.771236314450875"/>
					<body childclass="door_knob" name="knob_link" pos="0 0 0">
						<inertial mass="1" pos="0 0 0" diaginertia="0.001 0.001 0.001"/>
						<joint armature="0" axis="0 1 0" damping="30000" frictionloss="0" limited="true" name="target0" range="-0.2 0.3" stiffness="0" type="slide"/>
						<joint armature="0" axis="0 0 1" damping="30000" frictionloss="0" limited="true" name="target1" range="-0.5 0.5" stiffness="0" type="slide"/>
						<body childclass="door_knob" name="pullknob_link" pos="0.0075 0 0">
							<geom friction="0.68 0.001 0.003" material="Carpet" mesh="door_knob_1" name="door_knob_1" euler="-1.57 1.57 0"/>
							<geom friction="0.68 0.001 0.003" material="Carpet" mesh="door_knob_2" name="door_knob_2" euler="-1.57 1.57 0"/>
							<geom friction="0.68 0.001 0.003" material="Carpet" mesh="door_knob_3" name="door_knob_3" euler="-1.57 1.57 0"/>
							<geom friction="0.68 0.001 0.003" material="Carpet" mesh="door_knob_4" name="door_knob_4" euler="-1.57 1.57 0"/>
							<geom friction="0.68 0.001 0.003" material="Carpet" mesh="door_knob_5" name="door_knob_5" euler="-1.57 1.57 0"/>
							<geom friction="0.68 0.001 0.003" material="Carpet" mesh="door_knob_6" name="door_knob_6" euler="-1.57 1.57 0"/>
							<geom friction="0.68 0.001 0.003" material="Carpet" mesh="door_knob_7" name="door_knob_7" euler="-1.57 1.57 0"/>
							<geom friction="0.68 0.001 0.003" material="Carpet" mesh="door_knob_8" name="door_knob_8" euler="-1.57 1.57 0"/>
						</body>
					</body>
				</body>
			</body>
		</body>
	</worldbody>
</mujoco>