<?xml version="1.0" encoding="utf-8"?>
<mujoco model="door_knob">
	<compiler angle="radian"/>
	<include file="../../robot/blue_floatinghook.xml"/>
	<option gravity="0 0 0" timestep="0.001"/>
	<visual>
		<map fogend="5" fogstart="3" force="0.1" zfar="10" znear="0.01"/>
		<quality shadowsize="2048"/>
		<global offheight="256" offwidth="256"/>
	</visual>
	<asset>
		<mesh file="../../door/pullknobs/1555112003/body_1.stl" name="door_knob_1" scale="0.001 0.001 0.001"/>
		<mesh file="../../door/pullknobs/1555112003/body_2.stl" name="door_knob_2" scale="0.001 0.001 0.001"/>
		<mesh file="../../door/pullknobs/1555112003/body_3.stl" name="door_knob_3" scale="0.001 0.001 0.001"/>
		<mesh file="../../door/pullknobs/1555112003/body_4.stl" name="door_knob_4" scale="0.001 0.001 0.001"/>
		<mesh file="../../door/pullknobs/1555112003/body_5.stl" name="door_knob_5" scale="0.001 0.001 0.001"/>
		<mesh file="../../door/pullknobs/1555112003/body_6.stl" name="door_knob_6" scale="0.001 0.001 0.001"/>
		<mesh file="../../door/pullknobs/1555112003/body_7.stl" name="door_knob_7" scale="0.001 0.001 0.001"/>
		<mesh file="../../door/pullknobs/1555112003/body_8.stl" name="door_knob_8" scale="0.001 0.001 0.001"/>
		<texture builtin="flat" height="32" name="wall_geom" type="2d" width="32"/>
		<texture builtin="flat" height="32" name="frame_geom" type="2d" width="32"/>
		<texture builtin="flat" height="32" name="door_geom" type="2d" width="32"/>
		<texture builtin="flat" height="32" name="knob_geom" type="2d" width="32"/>
		<texture builtin="gradient" height="128" rgb1="0.4 0.6 0.8" rgb2="0 0 0" type="skybox" width="128"/>
		<texture builtin="checker" height="512" name="texplane" rgb1="0.2 0.3 0.4" rgb2="0.1 0.15 0.2" type="2d" width="512"/>
		<material name="Paint" shininess="0.39" specular="0.26" texture="wall_geom"/>
		<material name="Wood" shininess="0.18" specular="0.17" texture="frame_geom"/>
		<material name="Carpet" shininess="0.03" specular="0.01" texture="door_geom"/>
		<material name="Metal" shininess="0.9" specular="0.82" texture="knob_geom"/>
		<material name="Floor" texture="texplane"/>
	</asset>
	<contact>
		<pair geom1="doorstopper" geom2="door0" solref="0.01 1"/>
	</contact>
	<default>
		<joint armature="1" damping="1" limited="true"/>
		<default class="wall">
			<geom rgba="0.01 0.05 0.08 1.0" type="mesh"/>
		</default>
		<default class="frame">
			<geom rgba="0.83 0.74 0.8 1.0" type="mesh"/>
		</default>
		<default class="door">
			<geom rgba="0.91 0.57 0.44 1.0" type="mesh"/>
		</default>
		<default class="door_knob">
			<geom condim="4" rgba="0.53 0.37 0.06 1.0" type="mesh"/>
		</default>
		<default class="robot">
			<joint damping="0.1"/>
		</default>
	</default>
	<worldbody>
		<light diffuse="0.9 0.9 1.0" dir="0.35 0.3 -0.5" directional="true" pos="0.12 2.02 6.53"/>
		<light diffuse="1.0 1.0 0.9" dir="0.34 0.04 -0.27" directional="true" pos="3.11 -3.26 6.05"/>
		<light diffuse="0.9 0.9 0.9" dir="0.17 -0.37 -0.28" directional="true" pos="3.57 3.74 4.67"/>
		<light diffuse="0.9 0.9 1.0" dir="0.19 -0.43 -0.28" directional="true" pos="3.2 -3.7 3.57"/>
		<light diffuse="0.9 0.9 0.9" dir="0.31 0.05 -0.31" directional="true" pos="4.59 4.38 4.94"/>
		<geom material="Floor" name="floor" pos="0 0 -0.05" size="40.0 40.0 0.05" type="plane"/>
		<camera fovy="60" mode="fixed" name="camera1" pos="0.99 -0.5 1.0" euler="0.0 1.57 1.57"/>
		<camera fovy="60" mode="fixed" name="camera2" pos="0.5 0.0 1.99" euler="0 0 0"/>
		<body childclass="wall" name="wall_link" pos="0.0 0.025 0.0">
			<inertial mass="100" pos="0 0 0" diaginertia="0.0001 0.0001 0.0001"/>
			<geom material="Paint" name="wall_0" pos="0 -1.5334999999999999 1.1680000000000001" size="0.15 1.0 1.1680000000000001" type="box" euler="0 0 0"/>
			<geom material="Paint" name="wall_1" pos="0 1.5635 1.1680000000000001" size="0.15 1.0 1.1680000000000001" type="box" euler="0 0 0"/>
			<geom material="Paint" name="wall_2" pos="0 0 2.8360000000000003" size="0.15 2.5635 0.5" type="box" euler="0 0 0"/>
			<body childclass="frame" name="frame_link" pos="0 -0.30590999999999996 1.0">
				<inertial mass="500" pos="0 0 0" diaginertia="0.0001 0.0001 0.0001"/>
				<geom material="Metal" name="doorstopper" pos="-0.015399999999999999 -0.007590000000000013 1.1860000000000002" size="0.011 0.05 0.025" type="box" euler="0 0 0"/>
				<geom material="Paint" name="door_frame_0" pos="0 -0.21759 0.16800000000000015" size="0.011 0.05 1.1680000000000001" type="box" euler="0 0 0"/>
				<geom material="Paint" name="door_frame_1" pos="0 0.8294100000000001 0.16800000000000015" size="0.011 0.05 1.1680000000000001" type="box" euler="0 0 0"/>
				<geom material="Paint" name="door_frame_2" pos="0 0.30591 1.2860000000000003" size="0.011 0.5635 0.05" type="box" euler="0 0 0"/>
				<geom material="Paint" name="door_frame_3" pos="-0.04825 -0.21759 0.16800000000000015" size="0.011 0.05 1.1680000000000001" type="box" euler="0 0 0"/>
				<geom material="Paint" name="door_frame_4" pos="-0.04825 0.8294100000000001 0.16800000000000015" size="0.011 0.05 1.1680000000000001" type="box" euler="0 0 0"/>
				<geom material="Paint" name="door_frame_5" pos="-0.04825 0.30591 1.2860000000000003" size="0.011 0.5635 0.05" type="box" euler="0 0 0"/>
				<body childclass="door" name="door_link" pos="0.0242 0 0">
					<joint armature="0.0001" axis="0 0 1" damping="0.13" frictionloss="0" limited="false" name="hinge0" pos="0 0.76941 0" range="-0.5 0.5" stiffness="0.12" type="hinge"/>
					<geom material="Wood" name="door0" pos="0 0.30591 0.1180000000000001" size="0.011 0.4635 1.1068200000000001" type="box" euler="0 0 0"/>
					<inertial mass="12.084260760000003" pos="0 0.30591 0.1180000000000001" diaginertia="5.900165491613252 5.035289913911402 0.8658503747364903"/>
					<body childclass="door_knob" name="knob_link" pos="0 0 0">
						<inertial mass="1" pos="0 0 0" diaginertia="0.001 0.001 0.001"/>
						<joint armature="0" axis="0 1 0" damping="30000" frictionloss="0" limited="true" name="target0" range="-0.2 0.3" stiffness="0" type="slide"/>
						<joint armature="0" axis="0 0 1" damping="30000" frictionloss="0" limited="true" name="target1" range="-0.5 0.5" stiffness="0" type="slide"/>
						<body childclass="door_knob" name="pullknob_link" pos="0.004999999999999999 0 0">
							<geom friction="0.63 0.004 0.001" material="Carpet" mesh="door_knob_1" name="door_knob_1" euler="-1.57 1.57 0"/>
							<geom friction="0.63 0.004 0.001" material="Carpet" mesh="door_knob_2" name="door_knob_2" euler="-1.57 1.57 0"/>
							<geom friction="0.63 0.004 0.001" material="Carpet" mesh="door_knob_3" name="door_knob_3" euler="-1.57 1.57 0"/>
							<geom friction="0.63 0.004 0.001" material="Carpet" mesh="door_knob_4" name="door_knob_4" euler="-1.57 1.57 0"/>
							<geom friction="0.63 0.004 0.001" material="Carpet" mesh="door_knob_5" name="door_knob_5" euler="-1.57 1.57 0"/>
							<geom friction="0.63 0.004 0.001" material="Carpet" mesh="door_knob_6" name="door_knob_6" euler="-1.57 1.57 0"/>
							<geom friction="0.63 0.004 0.001" material="Carpet" mesh="door_knob_7" name="door_knob_7" euler="-1.57 1.57 0"/>
							<geom friction="0.63 0.004 0.001" material="Carpet" mesh="door_knob_8" name="door_knob_8" euler="-1.57 1.57 0"/>
						</body>
					</body>
				</body>
			</body>
		</body>
	</worldbody>
</mujoco>