<?xml version="1.0" encoding="utf-8"?>
<mujoco model="door_knob">
	<compiler angle="radian"/>
	<include file="../../robot/baxter_rightarm.xml"/>
	<option gravity="0 0 0" timestep="0.001"/>
	<visual>
		<map fogend="5" fogstart="3" force="0.1" zfar="10" znear="0.01"/>
		<quality shadowsize="2048"/>
		<global offheight="256" offwidth="256"/>
	</visual>
	<asset>
		<mesh file="../../door/leverknobs/1551849041/body_1.stl" name="door_knob_1" scale="0.0015 0.0015 0.0015"/>
		<mesh file="../../door/leverknobs/1551849041/body_2.stl" name="door_knob_2" scale="0.0015 0.0015 0.0015"/>
		<mesh file="../../door/leverknobs/1551849041/body_3.stl" name="door_knob_3" scale="0.0015 0.0015 0.0015"/>
		<mesh file="../../door/leverknobs/1551849041/body_4.stl" name="door_knob_4" scale="0.0015 0.0015 0.0015"/>
		<mesh file="../../door/leverknobs/1551849041/body_5.stl" name="door_knob_5" scale="0.0015 0.0015 0.0015"/>
		<texture builtin="flat" height="32" name="wall_geom" type="2d" width="32"/>
		<texture builtin="flat" height="32" name="frame_geom" type="2d" width="32"/>
		<texture builtin="flat" height="32" name="door_geom" type="2d" width="32"/>
		<texture builtin="flat" height="32" name="knob_geom" type="2d" width="32"/>
		<texture builtin="gradient" height="128" rgb1="0.4 0.6 0.8" rgb2="0 0 0" type="skybox" width="128"/>
		<texture builtin="gradient" height="512" name="texplane" rgb1="0.13 0.37 0.36" rgb2="0.36 0.42 0.2" type="2d" width="512"/>
		<material name="Paint" shininess="0.22" specular="0.15" texture="wall_geom"/>
		<material name="Wood" shininess="0.01" specular="0.1" texture="frame_geom"/>
		<material name="Carpet" shininess="0.04" specular="0.01" texture="door_geom"/>
		<material name="Metal" shininess="0.89" specular="0.94" texture="knob_geom"/>
		<material name="Floor" texture="texplane"/>
	</asset>
	<contact>
		<pair geom1="knob_latch" geom2="door_frame_0" solref="0.01 1"/>
		<pair geom1="knob_latch" geom2="door_frame_1" solref="0.01 1"/>
		<pair geom1="knob_latch" geom2="door_frame_2" solref="0.01 1"/>
		<pair geom1="knob_latch" geom2="door_frame_3" solref="0.01 1"/>
	</contact>
	<default>
		<joint armature="1" damping="1" limited="true"/>
		<default class="wall">
			<geom rgba="0.6 0.28 0.56 1.0" type="mesh"/>
		</default>
		<default class="frame">
			<geom rgba="0.76 0.84 0.78 1.0" type="mesh"/>
		</default>
		<default class="door">
			<geom rgba="0.31 0.2 0.66 1.0" type="mesh"/>
		</default>
		<default class="door_knob">
			<geom condim="4" rgba="0.61 0.6 0.73 1.0" type="mesh"/>
		</default>
		<default class="robot">
			<joint damping="0.1"/>
		</default>
	</default>
	<worldbody>
		<light diffuse="1.0 0.9 0.9" dir="-0.42 0.09 -0.46" directional="true" pos="0.11 4.94 3.27"/>
		<light diffuse="1.0 1.0 0.9" dir="0.29 -0.19 -0.36" directional="true" pos="2.21 2.8 3.88"/>
		<light diffuse="1.0 0.9 1.0" dir="-0.06 -0.4 -0.45" directional="true" pos="2.82 -4.64 6.88"/>
		<light diffuse="1.0 0.9 0.9" dir="0.34 -0.11 -0.42" directional="true" pos="4.9 2.85 3.06"/>
		<light diffuse="0.9 0.9 1.0" dir="-0.23 0.32 -0.27" directional="true" pos="4.89 3.44 5.02"/>
		<geom material="Floor" name="floor" pos="0 0 -0.05" size="15.0 15.0 0.05" type="plane"/>
		<camera fovy="60" mode="fixed" name="camera1" pos="0.99 -0.5 1.0" euler="0.0 1.57 1.57"/>
		<camera fovy="60" mode="fixed" name="camera2" pos="0.5 0.0 1.99" euler="0 0 0"/>
		<body childclass="wall" name="wall_link" pos="0.0 -0.031 0.0">
			<inertial mass="100" pos="0 0 0" diaginertia="0.0001 0.0001 0.0001"/>
			<geom material="Paint" name="wall_0" pos="0 -1.5479999999999998 1.1380000000000001" size="0.15 1.0 1.1380000000000001" type="box" euler="0 0 0"/>
			<geom material="Paint" name="wall_1" pos="0 1.5779999999999998 1.1380000000000001" size="0.15 1.0 1.1380000000000001" type="box" euler="0 0 0"/>
			<geom material="Paint" name="wall_2" pos="0 0 2.7760000000000002" size="0.15 2.578 0.5" type="box" euler="0 0 0"/>
			<body childclass="frame" name="frame_link" pos="0 -0.3824 0.942">
				<inertial mass="500" pos="0 0 0" diaginertia="0.0001 0.0001 0.0001"/>
				<geom material="Paint" name="door_frame_0" pos="0 -0.15560000000000002 0.19600000000000017" size="0.0115 0.05 1.1380000000000001" type="box" euler="0 0 0"/>
				<geom material="Paint" name="door_frame_1" pos="0 0.9204 0.19600000000000017" size="0.0115 0.05 1.1380000000000001" type="box" euler="0 0 0"/>
				<geom material="Paint" name="door_frame_2" pos="0 0.38239999999999996 1.2840000000000003" size="0.0115 0.578 0.05" type="box" euler="0 0 0"/>
				<geom material="Paint" name="door_frame_3" pos="-0.042499999999999996 -0.15560000000000002 0.19600000000000017" size="0.0115 0.05 1.1380000000000001" type="box" euler="0 0 0"/>
				<geom material="Paint" name="door_frame_4" pos="-0.042499999999999996 0.9204 0.19600000000000017" size="0.0115 0.05 1.1380000000000001" type="box" euler="0 0 0"/>
				<geom material="Paint" name="door_frame_5" pos="-0.042499999999999996 0.38239999999999996 1.2840000000000003" size="0.0115 0.578 0.05" type="box" euler="0 0 0"/>
				<body childclass="door" name="door_link" pos="0.025300000000000003 0 0">
					<joint armature="0.0001" axis="0 0 1" damping="1.6" frictionloss="0" limited="true" name="hinge0" pos="0 0.8603999999999999 0" range="-0.0 1.57" stiffness="0.15" type="hinge"/>
					<geom material="Carpet" name="door0" pos="0 0.38239999999999996 0.14600000000000013" size="0.0115 0.478 1.07712" type="box" euler="0 0 0"/>
					<inertial mass="12.631314431999998" pos="0 0.38239999999999996 0.14600000000000013" diaginertia="5.946098639224831 4.98463772077568 0.9625745793382399"/>
					<body childclass="door_knob" name="knob_link" pos="0 0 0">
						<inertial mass="1" pos="0 0 0" diaginertia="0.001 0.001 0.001"/>
						<joint armature="0" axis="0 1 0" damping="30000" frictionloss="0" limited="true" name="target0" range="-0.2 0.3" stiffness="0" type="slide"/>
						<joint armature="0" axis="0 0 1" damping="30000" frictionloss="0" limited="true" name="target1" range="-0.5 0.5" stiffness="0" type="slide"/>
						<joint armature="0.0001" axis="1 0 0" damping="0.18" frictionloss="0" limited="true" name="hinge1" pos="0 0 0" range="-1.3432222222222223 1.3432222222222223" stiffness="0.12" type="hinge"/>
						<body childclass="door_knob" name="leverknob_link" pos="0.0115 0 0">
							<geom friction="0.65 0.001 0.004" material="Paint" mesh="door_knob_1" name="door_knob_1" euler="-1.57 1.57 0"/>
							<geom friction="0.65 0.001 0.004" material="Paint" mesh="door_knob_2" name="door_knob_2" euler="-1.57 1.57 0"/>
							<geom friction="0.65 0.001 0.004" material="Paint" mesh="door_knob_3" name="door_knob_3" euler="-1.57 1.57 0"/>
							<geom friction="0.65 0.001 0.004" material="Paint" mesh="door_knob_4" name="door_knob_4" euler="-1.57 1.57 0"/>
							<geom friction="0.65 0.001 0.004" material="Paint" mesh="door_knob_5" name="door_knob_5" euler="-1.57 1.57 0"/>
							<geom material="Wood" name="knob_latch" pos="-0.058050000000000004 0 0" size="0.0075 0.12893333333333334 0.05" type="box" euler="0 0 0"/>
							<inertial mass="1" pos="-0.058050000000000004 0 0" diaginertia="0.0015936503703703705 0.00022708333333333337 0.0014040670370370372"/>
						</body>
					</body>
				</body>
			</body>
		</body>
	</worldbody>
</mujoco>