<?xml version="1.0" encoding="utf-8"?>
<mujoco model="door_knob">
	<compiler angle="radian"/>
	<include file="../../robot/baxter_rightarm.xml"/>
	<option gravity="0 0 0" timestep="0.001"/>
	<visual>
		<map fogend="5" fogstart="3" force="0.1" zfar="10" znear="0.01"/>
		<quality shadowsize="2048"/>
		<global offheight="256" offwidth="256"/>
	</visual>
	<asset>
		<mesh file="../../door/leverknobs/1551849051/body_1.stl" name="door_knob_1" scale="0.0015 0.0015 0.0015"/>
		<mesh file="../../door/leverknobs/1551849051/body_2.stl" name="door_knob_2" scale="0.0015 0.0015 0.0015"/>
		<mesh file="../../door/leverknobs/1551849051/body_3.stl" name="door_knob_3" scale="0.0015 0.0015 0.0015"/>
		<mesh file="../../door/leverknobs/1551849051/body_4.stl" name="door_knob_4" scale="0.0015 0.0015 0.0015"/>
		<mesh file="../../door/leverknobs/1551849051/body_5.stl" name="door_knob_5" scale="0.0015 0.0015 0.0015"/>
		<texture builtin="flat" height="32" name="wall_geom" type="2d" width="32"/>
		<texture builtin="flat" height="32" name="frame_geom" type="2d" width="32"/>
		<texture builtin="flat" height="32" name="door_geom" type="2d" width="32"/>
		<texture builtin="flat" height="32" name="knob_geom" type="2d" width="32"/>
		<texture builtin="gradient" height="128" rgb1="0.4 0.6 0.8" rgb2="0 0 0" type="skybox" width="128"/>
		<texture builtin="gradient" height="512" name="texplane" rgb1="0.39 0.45 0.12" rgb2="0.1 0.29 0.23" type="2d" width="512"/>
		<material name="Paint" shininess="0.35" specular="0.26" texture="wall_geom"/>
		<material name="Wood" shininess="0.03" specular="0.15" texture="frame_geom"/>
		<material name="Carpet" shininess="0.02" specular="0.04" texture="door_geom"/>
		<material name="Metal" shininess="0.88" specular="0.82" texture="knob_geom"/>
		<material name="Floor" texture="texplane"/>
	</asset>
	<contact>
		<pair geom1="knob_latch" geom2="door_frame_0" solref="0.01 1"/>
		<pair geom1="knob_latch" geom2="door_frame_1" solref="0.01 1"/>
		<pair geom1="knob_latch" geom2="door_frame_2" solref="0.01 1"/>
		<pair geom1="knob_latch" geom2="door_frame_3" solref="0.01 1"/>
	</contact>
	<default>
		<joint armature="1" damping="1" limited="true"/>
		<default class="wall">
			<geom rgba="0.05 0.76 0.31 1.0" type="mesh"/>
		</default>
		<default class="frame">
			<geom rgba="0.84 0.74 0.72 1.0" type="mesh"/>
		</default>
		<default class="door">
			<geom rgba="0.88 0.92 0.78 1.0" type="mesh"/>
		</default>
		<default class="door_knob">
			<geom condim="4" rgba="0.87 0.66 0.09 1.0" type="mesh"/>
		</default>
		<default class="robot">
			<joint damping="0.09"/>
		</default>
	</default>
	<worldbody>
		<light diffuse="0.9 1.0 1.0" dir="-0.33 0.08 -0.49" directional="true" pos="3.07 4.15 4.98"/>
		<light diffuse="0.9 0.9 0.9" dir="-0.15 0.25 -0.28" directional="true" pos="1.29 0.76 3.87"/>
		<geom material="Floor" name="floor" pos="0 0 -0.05" size="15.0 15.0 0.05" type="plane"/>
		<camera fovy="60" mode="fixed" name="camera1" pos="0.99 -0.5 1.0" euler="0.0 1.57 1.57"/>
		<camera fovy="60" mode="fixed" name="camera2" pos="0.5 0.0 1.99" euler="0 0 0"/>
		<body childclass="wall" name="wall_link" pos="0.0 -0.076 0.0">
			<inertial mass="100" pos="0 0 0" diaginertia="0.0001 0.0001 0.0001"/>
			<geom material="Paint" name="wall_0" pos="0 -1.631 1.0845" size="0.15 1.0 1.0845" type="box" euler="0 0 0"/>
			<geom material="Paint" name="wall_1" pos="0 1.661 1.0845" size="0.15 1.0 1.0845" type="box" euler="0 0 0"/>
			<geom material="Paint" name="wall_2" pos="0 0 2.669" size="0.15 2.661 0.5" type="box" euler="0 0 0"/>
			<body childclass="frame" name="frame_link" pos="0 -0.4488000000000001 1.001">
				<inertial mass="500" pos="0 0 0" diaginertia="0.0001 0.0001 0.0001"/>
				<geom material="Carpet" name="door_frame_0" pos="0 -0.17220000000000002 0.08350000000000013" size="0.0115 0.05 1.0845" type="box" euler="0 0 0"/>
				<geom material="Carpet" name="door_frame_1" pos="0 1.0698 0.08350000000000013" size="0.0115 0.05 1.0845" type="box" euler="0 0 0"/>
				<geom material="Carpet" name="door_frame_2" pos="0 0.44880000000000003 1.118" size="0.0115 0.661 0.05" type="box" euler="0 0 0"/>
				<geom material="Carpet" name="door_frame_3" pos="-0.042499999999999996 -0.17220000000000002 0.08350000000000013" size="0.0115 0.05 1.0845" type="box" euler="0 0 0"/>
				<geom material="Carpet" name="door_frame_4" pos="-0.042499999999999996 1.0698 0.08350000000000013" size="0.0115 0.05 1.0845" type="box" euler="0 0 0"/>
				<geom material="Carpet" name="door_frame_5" pos="-0.042499999999999996 0.44880000000000003 1.118" size="0.0115 0.661 0.05" type="box" euler="0 0 0"/>
				<body childclass="door" name="door_link" pos="0.025300000000000003 0 0">
					<joint armature="0.0001" axis="0 0 1" damping="1.9" frictionloss="0" limited="true" name="hinge0" pos="0 1.0098 0" range="-0.0 1.57" stiffness="0.19" type="hinge"/>
					<geom material="Paint" name="door0" pos="0 0.44880000000000003 0.033500000000000085" size="0.0115 0.561 1.024155" type="box" euler="0 0 0"/>
					<inertial mass="14.255827938" pos="0 0.44880000000000003 0.033500000000000085" diaginertia="6.5810188298001675 5.086111132723335 1.4961645859066999"/>
					<body childclass="door_knob" name="knob_link" pos="0 0 0">
						<inertial mass="1" pos="0 0 0" diaginertia="0.001 0.001 0.001"/>
						<joint armature="0" axis="0 1 0" damping="30000" frictionloss="0" limited="true" name="target0" range="-0.2 0.3" stiffness="0" type="slide"/>
						<joint armature="0" axis="0 0 1" damping="30000" frictionloss="0" limited="true" name="target1" range="-0.5 0.5" stiffness="0" type="slide"/>
						<joint armature="0.0001" axis="1 0 0" damping="0.11" frictionloss="0" limited="true" name="hinge1" pos="0 0 0" range="-1.378111111111111 1.378111111111111" stiffness="0.13" type="hinge"/>
						<body childclass="door_knob" name="leverknob_link" pos="0.0115 0 0">
							<geom friction="0.95 0.004 0.003" material="Paint" mesh="door_knob_1" name="door_knob_1" euler="-1.57 1.57 0"/>
							<geom friction="0.95 0.004 0.003" material="Paint" mesh="door_knob_2" name="door_knob_2" euler="-1.57 1.57 0"/>
							<geom friction="0.95 0.004 0.003" material="Paint" mesh="door_knob_3" name="door_knob_3" euler="-1.57 1.57 0"/>
							<geom friction="0.95 0.004 0.003" material="Paint" mesh="door_knob_4" name="door_knob_4" euler="-1.57 1.57 0"/>
							<geom friction="0.95 0.004 0.003" material="Paint" mesh="door_knob_5" name="door_knob_5" euler="-1.57 1.57 0"/>
							<geom material="Carpet" name="knob_latch" pos="-0.058050000000000004 0 0" size="0.0075 0.14553333333333335 0.05" type="box" euler="0 0 0"/>
							<inertial mass="1" pos="-0.058050000000000004 0 0" diaginertia="0.0019733292592592597 0.00022708333333333337 0.0017837459259259262"/>
						</body>
					</body>
				</body>
			</body>
		</body>
	</worldbody>
</mujoco>