<?xml version="1.0" encoding="utf-8"?>
<mujoco model="door_knob">
	<compiler angle="radian"/>
	<include file="../../robot/baxter_rightarm.xml"/>
	<option gravity="0 0 0" timestep="0.001"/>
	<visual>
		<map fogend="5" fogstart="3" force="0.1" zfar="10" znear="0.01"/>
		<quality shadowsize="2048"/>
		<global offheight="256" offwidth="256"/>
	</visual>
	<asset>
		<mesh file="../../door/leverknobs/1551849078/body_1.stl" name="door_knob_1" scale="0.0015 0.0015 0.0015"/>
		<mesh file="../../door/leverknobs/1551849078/body_2.stl" name="door_knob_2" scale="0.0015 0.0015 0.0015"/>
		<mesh file="../../door/leverknobs/1551849078/body_3.stl" name="door_knob_3" scale="0.0015 0.0015 0.0015"/>
		<mesh file="../../door/leverknobs/1551849078/body_4.stl" name="door_knob_4" scale="0.0015 0.0015 0.0015"/>
		<mesh file="../../door/leverknobs/1551849078/body_5.stl" name="door_knob_5" scale="0.0015 0.0015 0.0015"/>
		<texture builtin="flat" height="32" name="wall_geom" type="2d" width="32"/>
		<texture builtin="flat" height="32" name="frame_geom" type="2d" width="32"/>
		<texture builtin="flat" height="32" name="door_geom" type="2d" width="32"/>
		<texture builtin="flat" height="32" name="knob_geom" type="2d" width="32"/>
		<texture builtin="gradient" height="128" rgb1="0.4 0.6 0.8" rgb2="0 0 0" type="skybox" width="128"/>
		<texture builtin="gradient" height="512" name="texplane" rgb1="0.14 0.48 0.32" rgb2="0.01 0.15 0.42" type="2d" width="512"/>
		<material name="Paint" shininess="0.16" specular="0.15" texture="wall_geom"/>
		<material name="Wood" shininess="0.05" specular="0.12" texture="frame_geom"/>
		<material name="Carpet" shininess="0.04" specular="0.03" texture="door_geom"/>
		<material name="Metal" shininess="0.82" specular="0.93" texture="knob_geom"/>
		<material name="Floor" texture="texplane"/>
	</asset>
	<contact>
		<pair geom1="knob_latch" geom2="door_frame_0" solref="0.01 1"/>
		<pair geom1="knob_latch" geom2="door_frame_1" solref="0.01 1"/>
		<pair geom1="knob_latch" geom2="door_frame_2" solref="0.01 1"/>
		<pair geom1="knob_latch" geom2="door_frame_3" solref="0.01 1"/>
	</contact>
	<default>
		<joint armature="1" damping="1" limited="true"/>
		<default class="wall">
			<geom rgba="0.36 0.6 0.2 1.0" type="mesh"/>
		</default>
		<default class="frame">
			<geom rgba="0.7 0.82 0.77 1.0" type="mesh"/>
		</default>
		<default class="door">
			<geom rgba="0.96 0.63 0.91 1.0" type="mesh"/>
		</default>
		<default class="door_knob">
			<geom condim="4" rgba="0.57 0.21 0.89 1.0" type="mesh"/>
		</default>
		<default class="robot">
			<joint damping="0.09"/>
		</default>
	</default>
	<worldbody>
		<light diffuse="1.0 1.0 0.9" dir="0.4 0.04 -0.32" directional="true" pos="3.24 -2.43 3.23"/>
		<light diffuse="0.9 0.9 0.9" dir="0.32 -0.25 -0.27" directional="true" pos="2.04 3.55 5.16"/>
		<light diffuse="1.0 0.9 1.0" dir="-0.09 -0.08 -0.43" directional="true" pos="4.48 2.56 6.18"/>
		<geom material="Floor" name="floor" pos="0 0 -0.05" size="15.0 15.0 0.05" type="plane"/>
		<camera fovy="60" mode="fixed" name="camera1" pos="0.99 -0.5 1.0" euler="0.0 1.57 1.57"/>
		<camera fovy="60" mode="fixed" name="camera2" pos="0.5 0.0 1.99" euler="0 0 0"/>
		<body childclass="wall" name="wall_link" pos="0.0 -0.06 0.0">
			<inertial mass="100" pos="0 0 0" diaginertia="0.0001 0.0001 0.0001"/>
			<geom material="Carpet" name="wall_0" pos="0 -1.5334999999999999 1.0705" size="0.15 1.0 1.0705" type="box" euler="0 0 0"/>
			<geom material="Carpet" name="wall_1" pos="0 1.5635 1.0705" size="0.15 1.0 1.0705" type="box" euler="0 0 0"/>
			<geom material="Carpet" name="wall_2" pos="0 0 2.641" size="0.15 2.5635 0.5" type="box" euler="0 0 0"/>
			<body childclass="frame" name="frame_link" pos="0 -0.31517999999999996 1.047">
				<inertial mass="500" pos="0 0 0" diaginertia="0.0001 0.0001 0.0001"/>
				<geom material="Wood" name="door_frame_0" pos="0 -0.20832 0.023500000000000076" size="0.0105 0.05 1.0705" type="box" euler="0 0 0"/>
				<geom material="Wood" name="door_frame_1" pos="0 0.8386800000000001 0.023500000000000076" size="0.0105 0.05 1.0705" type="box" euler="0 0 0"/>
				<geom material="Wood" name="door_frame_2" pos="0 0.31518 1.044" size="0.0105 0.5635 0.05" type="box" euler="0 0 0"/>
				<geom material="Wood" name="door_frame_3" pos="-0.0405 -0.20832 0.023500000000000076" size="0.0105 0.05 1.0705" type="box" euler="0 0 0"/>
				<geom material="Wood" name="door_frame_4" pos="-0.0405 0.8386800000000001 0.023500000000000076" size="0.0105 0.05 1.0705" type="box" euler="0 0 0"/>
				<geom material="Wood" name="door_frame_5" pos="-0.0405 0.31518 1.044" size="0.0105 0.5635 0.05" type="box" euler="0 0 0"/>
				<body childclass="door" name="door_link" pos="0.023100000000000002 0 0">
					<joint armature="0.0001" axis="0 0 1" damping="1.6" frictionloss="0" limited="true" name="hinge0" pos="0 0.77868 0" range="-0.0 1.57" stiffness="0.11" type="hinge"/>
					<geom material="Wood" name="door0" pos="0 0.31518 -0.026499999999999968" size="0.0105 0.4635 1.010295" type="box" euler="0 0 0"/>
					<inertial mass="9.416518839" pos="0 0.31518 -0.026499999999999968" diaginertia="3.943175110930282 3.269197191547696 0.6746700335172526"/>
					<body childclass="door_knob" name="knob_link" pos="0 0 0">
						<inertial mass="1" pos="0 0 0" diaginertia="0.001 0.001 0.001"/>
						<joint armature="0" axis="0 1 0" damping="30000" frictionloss="0" limited="true" name="target0" range="-0.2 0.3" stiffness="0" type="slide"/>
						<joint armature="0" axis="0 0 1" damping="30000" frictionloss="0" limited="true" name="target1" range="-0.5 0.5" stiffness="0" type="slide"/>
						<joint armature="0.0001" axis="1 0 0" damping="0.18" frictionloss="0" limited="true" name="hinge1" pos="0 0 0" range="-1.378111111111111 1.378111111111111" stiffness="0.11" type="hinge"/>
						<body childclass="door_knob" name="leverknob_link" pos="0.0105 0 0">
							<geom friction="0.72 0.001 0.003" material="Wood" mesh="door_knob_1" name="door_knob_1" euler="-1.57 1.57 0"/>
							<geom friction="0.72 0.001 0.003" material="Wood" mesh="door_knob_2" name="door_knob_2" euler="-1.57 1.57 0"/>
							<geom friction="0.72 0.001 0.003" material="Wood" mesh="door_knob_3" name="door_knob_3" euler="-1.57 1.57 0"/>
							<geom friction="0.72 0.001 0.003" material="Wood" mesh="door_knob_4" name="door_knob_4" euler="-1.57 1.57 0"/>
							<geom friction="0.72 0.001 0.003" material="Wood" mesh="door_knob_5" name="door_knob_5" euler="-1.57 1.57 0"/>
							<geom material="Paint" name="knob_latch" pos="-0.05385000000000001 0 0" size="0.0075 0.18165333333333333 0.05" type="box" euler="0 0 0"/>
							<inertial mass="1" pos="-0.05385000000000001 0 0" diaginertia="0.002958161125925926 0.00022708333333333337 0.0027685777925925926"/>
						</body>
					</body>
				</body>
			</body>
		</body>
	</worldbody>
</mujoco>