<?xml version="1.0" encoding="utf-8"?>
<mujoco model="door_knob">
	<compiler angle="radian"/>
	<include file="../../robot/baxter_rightarm.xml"/>
	<option gravity="0 0 0" timestep="0.001"/>
	<visual>
		<map fogend="5" fogstart="3" force="0.1" zfar="10" znear="0.01"/>
		<quality shadowsize="2048"/>
		<global offheight="256" offwidth="256"/>
	</visual>
	<asset>
		<mesh file="../../door/pullknobs/1555112008/body_1.stl" name="door_knob_1" scale="0.001 0.001 0.001"/>
		<mesh file="../../door/pullknobs/1555112008/body_2.stl" name="door_knob_2" scale="0.001 0.001 0.001"/>
		<mesh file="../../door/pullknobs/1555112008/body_3.stl" name="door_knob_3" scale="0.001 0.001 0.001"/>
		<mesh file="../../door/pullknobs/1555112008/body_4.stl" name="door_knob_4" scale="0.001 0.001 0.001"/>
		<mesh file="../../door/pullknobs/1555112008/body_5.stl" name="door_knob_5" scale="0.001 0.001 0.001"/>
		<mesh file="../../door/pullknobs/1555112008/body_6.stl" name="door_knob_6" scale="0.001 0.001 0.001"/>
		<mesh file="../../door/pullknobs/1555112008/body_7.stl" name="door_knob_7" scale="0.001 0.001 0.001"/>
		<mesh file="../../door/pullknobs/1555112008/body_8.stl" name="door_knob_8" scale="0.001 0.001 0.001"/>
		<texture builtin="flat" height="32" name="wall_geom" type="2d" width="32"/>
		<texture builtin="flat" height="32" name="frame_geom" type="2d" width="32"/>
		<texture builtin="flat" height="32" name="door_geom" type="2d" width="32"/>
		<texture builtin="flat" height="32" name="knob_geom" type="2d" width="32"/>
		<texture builtin="gradient" height="128" rgb1="0.4 0.6 0.8" rgb2="0 0 0" type="skybox" width="128"/>
		<texture builtin="gradient" height="512" name="texplane" rgb1="0.19 0.29 0.39" rgb2="0.17 0.09 0.09" type="2d" width="512"/>
		<material name="Paint" shininess="0.08" specular="0.46" texture="wall_geom"/>
		<material name="Wood" shininess="0.14" specular="0.08" texture="frame_geom"/>
		<material name="Carpet" shininess="0.01" specular="0.01" texture="door_geom"/>
		<material name="Metal" shininess="0.94" specular="0.81" texture="knob_geom"/>
		<material name="Floor" texture="texplane"/>
	</asset>
	<contact/>
	<default>
		<joint armature="1" damping="1" limited="true"/>
		<default class="wall">
			<geom rgba="0.39 0.59 0.76 1.0" type="mesh"/>
		</default>
		<default class="frame">
			<geom rgba="0.7 0.84 0.79 1.0" type="mesh"/>
		</default>
		<default class="door">
			<geom rgba="0.43 0.22 0.24 1.0" type="mesh"/>
		</default>
		<default class="door_knob">
			<geom condim="4" rgba="0.34 0.11 0.89 1.0" type="mesh"/>
		</default>
		<default class="robot">
			<joint damping="0.1"/>
		</default>
	</default>
	<worldbody>
		<light diffuse="0.9 0.9 0.9" dir="-0.38 -0.13 -0.39" directional="true" pos="0.57 -3.41 5.4"/>
		<light diffuse="0.9 1.0 1.0" dir="-0.14 -0.5 -0.46" directional="true" pos="1.18 -4.18 6.88"/>
		<light diffuse="0.9 0.9 1.0" dir="0.11 -0.38 -0.32" directional="true" pos="4.06 1.02 6.0"/>
		<geom material="Floor" name="floor" pos="0 0 -0.05" size="15.0 15.0 0.05" type="plane"/>
		<camera fovy="60" mode="fixed" name="camera1" pos="0.99 0.5 1.0" euler="0.0 1.57 1.57"/>
		<camera fovy="60" mode="fixed" name="camera2" pos="0.5 0.0 1.99" euler="0 0 0"/>
		<body childclass="wall" name="wall_link" pos="0.0 0.0 0.0">
			<inertial mass="100" pos="0 0 0" diaginertia="0.0001 0.0001 0.0001"/>
			<geom material="Wood" name="wall_0" pos="-0.15 -1.57 1.2630000000000001" size="0.15 1.0 1.2630000000000001" type="box" euler="0 0 0"/>
			<geom material="Wood" name="wall_1" pos="-0.15 1.6 1.2630000000000001" size="0.15 1.0 1.2630000000000001" type="box" euler="0 0 0"/>
			<geom material="Wood" name="wall_2" pos="-0.15 0 3.0260000000000002" size="0.15 2.6 0.5" type="box" euler="0 0 0"/>
			<body childclass="frame" name="frame_link" pos="0 -0.35 1">
				<inertial mass="500" pos="0 0 0" diaginertia="0.0001 0.0001 0.0001"/>
				<geom material="Carpet" name="door_frame_0" pos="0 -0.21000000000000002 0.2630000000000001" size="0.0125 0.05 1.2630000000000001" type="box" euler="0 0 0"/>
				<geom material="Carpet" name="door_frame_1" pos="0 0.91 0.2630000000000001" size="0.0125 0.05 1.2630000000000001" type="box" euler="0 0 0"/>
				<geom material="Carpet" name="door_frame_2" pos="0 0.35 1.4760000000000002" size="0.0125 0.6 0.05" type="box" euler="0 0 0"/>
				<geom material="Carpet" name="door_frame_3" pos="-0.0445 -0.21000000000000002 0.2630000000000001" size="0.0125 0.05 1.2630000000000001" type="box" euler="0 0 0"/>
				<geom material="Carpet" name="door_frame_4" pos="-0.0445 0.91 0.2630000000000001" size="0.0125 0.05 1.2630000000000001" type="box" euler="0 0 0"/>
				<geom material="Carpet" name="door_frame_5" pos="-0.0445 0.35 1.4760000000000002" size="0.0125 0.6 0.05" type="box" euler="0 0 0"/>
				<body childclass="door" name="door_link" pos="0 0 0">
					<joint armature="0.0001" axis="0 0 1" damping="1.7" frictionloss="0" limited="true" name="hinge0" pos="0 -0.15 0" range="-1.57 0.0" stiffness="0.15" type="hinge"/>
					<geom material="Wood" name="door0" pos="0 0.35 0.21300000000000008" size="0.0125 0.5 1.20087" type="box" euler="0 0 0"/>
					<inertial mass="18.195000000000004" pos="0 0.35 0.21300000000000008" diaginertia="10.440102985000003 8.924800641250004 1.5171976562500005"/>
					<body childclass="door_knob" name="knob_link" pos="0 0.7 0">
						<inertial mass="1" pos="0 0 0" diaginertia="0.001 0.001 0.001"/>
						<joint armature="0" axis="0 1 0" damping="30000" frictionloss="0" limited="true" name="target0" range="-0.2 0.3" stiffness="0" type="slide"/>
						<joint armature="0" axis="0 0 1" damping="30000" frictionloss="0" limited="true" name="target1" range="-0.5 0.5" stiffness="0" type="slide"/>
						<body childclass="door_knob" name="pullknob_link" pos="0.006500000000000001 0 0">
							<geom friction="0.55 0.002 0.003" material="Carpet" mesh="door_knob_1" name="door_knob_1" euler="1.57 1.57 0"/>
							<geom friction="0.55 0.002 0.003" material="Carpet" mesh="door_knob_2" name="door_knob_2" euler="1.57 1.57 0"/>
							<geom friction="0.55 0.002 0.003" material="Carpet" mesh="door_knob_3" name="door_knob_3" euler="1.57 1.57 0"/>
							<geom friction="0.55 0.002 0.003" material="Carpet" mesh="door_knob_4" name="door_knob_4" euler="1.57 1.57 0"/>
							<geom friction="0.55 0.002 0.003" material="Carpet" mesh="door_knob_5" name="door_knob_5" euler="1.57 1.57 0"/>
							<geom friction="0.55 0.002 0.003" material="Carpet" mesh="door_knob_6" name="door_knob_6" euler="1.57 1.57 0"/>
							<geom friction="0.55 0.002 0.003" material="Carpet" mesh="door_knob_7" name="door_knob_7" euler="1.57 1.57 0"/>
							<geom friction="0.55 0.002 0.003" material="Carpet" mesh="door_knob_8" name="door_knob_8" euler="1.57 1.57 0"/>
						</body>
					</body>
				</body>
			</body>
		</body>
	</worldbody>
</mujoco>