<?xml version="1.0" encoding="utf-8"?>
<mujoco model="door_knob">
	<compiler angle="radian"/>
	<include file="../../robot/baxter_rightarm.xml"/>
	<option gravity="0 0 0" timestep="0.001"/>
	<visual>
		<map fogend="5" fogstart="3" force="0.1" zfar="10" znear="0.01"/>
		<quality shadowsize="2048"/>
		<global offheight="256" offwidth="256"/>
	</visual>
	<asset>
		<mesh file="../../door/pullknobs/1555111990/body_1.stl" name="door_knob_1" scale="0.001 0.001 0.001"/>
		<mesh file="../../door/pullknobs/1555111990/body_2.stl" name="door_knob_2" scale="0.001 0.001 0.001"/>
		<mesh file="../../door/pullknobs/1555111990/body_3.stl" name="door_knob_3" scale="0.001 0.001 0.001"/>
		<mesh file="../../door/pullknobs/1555111990/body_4.stl" name="door_knob_4" scale="0.001 0.001 0.001"/>
		<mesh file="../../door/pullknobs/1555111990/body_5.stl" name="door_knob_5" scale="0.001 0.001 0.001"/>
		<mesh file="../../door/pullknobs/1555111990/body_6.stl" name="door_knob_6" scale="0.001 0.001 0.001"/>
		<mesh file="../../door/pullknobs/1555111990/body_7.stl" name="door_knob_7" scale="0.001 0.001 0.001"/>
		<mesh file="../../door/pullknobs/1555111990/body_8.stl" name="door_knob_8" scale="0.001 0.001 0.001"/>
		<texture builtin="flat" height="32" name="wall_geom" type="2d" width="32"/>
		<texture builtin="flat" height="32" name="frame_geom" type="2d" width="32"/>
		<texture builtin="flat" height="32" name="door_geom" type="2d" width="32"/>
		<texture builtin="flat" height="32" name="knob_geom" type="2d" width="32"/>
		<texture builtin="gradient" height="128" rgb1="0.4 0.6 0.8" rgb2="0 0 0" type="skybox" width="128"/>
		<texture builtin="gradient" height="512" name="texplane" rgb1="0.08 0.11 0.07" rgb2="0.13 0.42 0.15" type="2d" width="512"/>
		<material name="Paint" shininess="0.41" specular="0.34" texture="wall_geom"/>
		<material name="Wood" shininess="0.16" specular="0.07" texture="frame_geom"/>
		<material name="Carpet" shininess="0.04" specular="0.03" texture="door_geom"/>
		<material name="Metal" shininess="0.86" specular="0.84" texture="knob_geom"/>
		<material name="Floor" texture="texplane"/>
	</asset>
	<contact/>
	<default>
		<joint armature="1" damping="1" limited="true"/>
		<default class="wall">
			<geom rgba="0.39 0.36 0.35 1.0" type="mesh"/>
		</default>
		<default class="frame">
			<geom rgba="0.74 0.8 0.76 1.0" type="mesh"/>
		</default>
		<default class="door">
			<geom rgba="0.22 0.74 0.02 1.0" type="mesh"/>
		</default>
		<default class="door_knob">
			<geom condim="4" rgba="0.08 0.71 0.78 1.0" type="mesh"/>
		</default>
		<default class="robot">
			<joint damping="0.1"/>
		</default>
	</default>
	<worldbody>
		<light diffuse="1.0 0.9 0.9" dir="0.13 -0.34 -0.41" directional="true" pos="0.51 4.43 5.51"/>
		<light diffuse="0.9 1.0 1.0" dir="0.38 -0.45 -0.48" directional="true" pos="0.19 2.92 6.23"/>
		<light diffuse="0.9 1.0 0.9" dir="0.44 -0.09 -0.41" directional="true" pos="2.99 -1.85 6.64"/>
		<light diffuse="1.0 1.0 1.0" dir="-0.11 0.45 -0.39" directional="true" pos="0.1 -2.99 3.15"/>
		<light diffuse="0.9 1.0 1.0" dir="-0.39 -0.33 -0.42" directional="true" pos="2.47 3.82 5.46"/>
		<geom material="Floor" name="floor" pos="0 0 -0.05" size="15.0 15.0 0.05" type="plane"/>
		<camera fovy="60" mode="fixed" name="camera1" pos="0.99 0.5 1.0" euler="0.0 1.57 1.57"/>
		<camera fovy="60" mode="fixed" name="camera2" pos="0.5 0.0 1.99" euler="0 0 0"/>
		<body childclass="wall" name="wall_link" pos="0.0 -0.074 0.0">
			<inertial mass="100" pos="0 0 0" diaginertia="0.0001 0.0001 0.0001"/>
			<geom material="Paint" name="wall_0" pos="-0.15 -1.4585000000000001 1.1360000000000001" size="0.15 1.0 1.1360000000000001" type="box" euler="0 0 0"/>
			<geom material="Paint" name="wall_1" pos="-0.15 1.4885000000000002 1.1360000000000001" size="0.15 1.0 1.1360000000000001" type="box" euler="0 0 0"/>
			<geom material="Paint" name="wall_2" pos="-0.15 0 2.7720000000000002" size="0.15 2.4885 0.5" type="box" euler="0 0 0"/>
			<body childclass="frame" name="frame_link" pos="0 -0.29526 1.075">
				<inertial mass="500" pos="0 0 0" diaginertia="0.0001 0.0001 0.0001"/>
				<geom material="Wood" name="door_frame_0" pos="0 -0.15324000000000002 0.061000000000000165" size="0.0115 0.05 1.1360000000000001" type="box" euler="0 0 0"/>
				<geom material="Wood" name="door_frame_1" pos="0 0.7437600000000001 0.061000000000000165" size="0.0115 0.05 1.1360000000000001" type="box" euler="0 0 0"/>
				<geom material="Wood" name="door_frame_2" pos="0 0.29526 1.1470000000000002" size="0.0115 0.48850000000000005 0.05" type="box" euler="0 0 0"/>
				<geom material="Wood" name="door_frame_3" pos="-0.042499999999999996 -0.15324000000000002 0.061000000000000165" size="0.0115 0.05 1.1360000000000001" type="box" euler="0 0 0"/>
				<geom material="Wood" name="door_frame_4" pos="-0.042499999999999996 0.7437600000000001 0.061000000000000165" size="0.0115 0.05 1.1360000000000001" type="box" euler="0 0 0"/>
				<geom material="Wood" name="door_frame_5" pos="-0.042499999999999996 0.29526 1.1470000000000002" size="0.0115 0.48850000000000005 0.05" type="box" euler="0 0 0"/>
				<body childclass="door" name="door_link" pos="0 0 0">
					<joint armature="0.0001" axis="0 0 1" damping="1.4" frictionloss="0" limited="true" name="hinge0" pos="0 -0.09324 0" range="-1.57 0.0" stiffness="0.14" type="hinge"/>
					<geom material="Wood" name="door0" pos="0 0.29526 0.01100000000000012" size="0.0115 0.3885 1.07514" type="box" euler="0 0 0"/>
					<inertial mass="36.137520972000004" pos="0 0.29526 0.01100000000000012" diaginertia="16.024921678006358 14.208408957147157 1.8196988456248986"/>
					<body childclass="door_knob" name="knob_link" pos="0 0.59052 0">
						<inertial mass="1" pos="0 0 0" diaginertia="0.001 0.001 0.001"/>
						<joint armature="0" axis="0 1 0" damping="30000" frictionloss="0" limited="true" name="target0" range="-0.2 0.3" stiffness="0" type="slide"/>
						<joint armature="0" axis="0 0 1" damping="30000" frictionloss="0" limited="true" name="target1" range="-0.5 0.5" stiffness="0" type="slide"/>
						<body childclass="door_knob" name="pullknob_link" pos="0.0055 0 0">
							<geom friction="0.96 0.003 0.002" material="Wood" mesh="door_knob_1" name="door_knob_1" euler="1.57 1.57 0"/>
							<geom friction="0.96 0.003 0.002" material="Wood" mesh="door_knob_2" name="door_knob_2" euler="1.57 1.57 0"/>
							<geom friction="0.96 0.003 0.002" material="Wood" mesh="door_knob_3" name="door_knob_3" euler="1.57 1.57 0"/>
							<geom friction="0.96 0.003 0.002" material="Wood" mesh="door_knob_4" name="door_knob_4" euler="1.57 1.57 0"/>
							<geom friction="0.96 0.003 0.002" material="Wood" mesh="door_knob_5" name="door_knob_5" euler="1.57 1.57 0"/>
							<geom friction="0.96 0.003 0.002" material="Wood" mesh="door_knob_6" name="door_knob_6" euler="1.57 1.57 0"/>
							<geom friction="0.96 0.003 0.002" material="Wood" mesh="door_knob_7" name="door_knob_7" euler="1.57 1.57 0"/>
							<geom friction="0.96 0.003 0.002" material="Wood" mesh="door_knob_8" name="door_knob_8" euler="1.57 1.57 0"/>
						</body>
					</body>
				</body>
			</body>
		</body>
	</worldbody>
</mujoco>