<?xml version="1.0" encoding="utf-8"?>
<mujoco model="door_knob">
	<compiler angle="radian"/>
	<include file="../../robot/baxter_rightarm.xml"/>
	<option gravity="0 0 0" timestep="0.001"/>
	<visual>
		<map fogend="5" fogstart="3" force="0.1" zfar="10" znear="0.01"/>
		<quality shadowsize="2048"/>
		<global offheight="256" offwidth="256"/>
	</visual>
	<asset>
		<mesh file="../../door/pullknobs/1555111999/body_1.stl" name="door_knob_1" scale="0.001 0.001 0.001"/>
		<mesh file="../../door/pullknobs/1555111999/body_2.stl" name="door_knob_2" scale="0.001 0.001 0.001"/>
		<mesh file="../../door/pullknobs/1555111999/body_3.stl" name="door_knob_3" scale="0.001 0.001 0.001"/>
		<mesh file="../../door/pullknobs/1555111999/body_4.stl" name="door_knob_4" scale="0.001 0.001 0.001"/>
		<mesh file="../../door/pullknobs/1555111999/body_5.stl" name="door_knob_5" scale="0.001 0.001 0.001"/>
		<mesh file="../../door/pullknobs/1555111999/body_6.stl" name="door_knob_6" scale="0.001 0.001 0.001"/>
		<mesh file="../../door/pullknobs/1555111999/body_7.stl" name="door_knob_7" scale="0.001 0.001 0.001"/>
		<mesh file="../../door/pullknobs/1555111999/body_8.stl" name="door_knob_8" scale="0.001 0.001 0.001"/>
		<texture builtin="flat" height="32" name="wall_geom" type="2d" width="32"/>
		<texture builtin="flat" height="32" name="frame_geom" type="2d" width="32"/>
		<texture builtin="flat" height="32" name="door_geom" type="2d" width="32"/>
		<texture builtin="flat" height="32" name="knob_geom" type="2d" width="32"/>
		<texture builtin="gradient" height="128" rgb1="0.4 0.6 0.8" rgb2="0 0 0" type="skybox" width="128"/>
		<texture builtin="gradient" height="512" name="texplane" rgb1="0.03 0.47 0.03" rgb2="0.21 0.35 0.25" type="2d" width="512"/>
		<material name="Paint" shininess="0.24" specular="0.07" texture="wall_geom"/>
		<material name="Wood" shininess="0.06" specular="0.09" texture="frame_geom"/>
		<material name="Carpet" shininess="0.04" specular="0.02" texture="door_geom"/>
		<material name="Metal" shininess="0.87" specular="0.8" texture="knob_geom"/>
		<material name="Floor" texture="texplane"/>
	</asset>
	<contact/>
	<default>
		<joint armature="1" damping="1" limited="true"/>
		<default class="wall">
			<geom rgba="0.27 0.12 0.15 1.0" type="mesh"/>
		</default>
		<default class="frame">
			<geom rgba="0.76 0.72 0.8 1.0" type="mesh"/>
		</default>
		<default class="door">
			<geom rgba="0.74 0.12 0.59 1.0" type="mesh"/>
		</default>
		<default class="door_knob">
			<geom condim="4" rgba="0.39 0.59 0.42 1.0" type="mesh"/>
		</default>
		<default class="robot">
			<joint damping="0.09"/>
		</default>
	</default>
	<worldbody>
		<light diffuse="0.9 0.9 0.9" dir="-0.3 -0.34 -0.28" directional="true" pos="1.29 1.34 5.5"/>
		<light diffuse="0.9 0.9 0.9" dir="-0.21 -0.23 -0.32" directional="true" pos="0.44 0.82 3.98"/>
		<geom material="Floor" name="floor" pos="0 0 -0.05" size="15.0 15.0 0.05" type="plane"/>
		<camera fovy="60" mode="fixed" name="camera1" pos="0.99 0.5 1.0" euler="0.0 1.57 1.57"/>
		<camera fovy="60" mode="fixed" name="camera2" pos="0.5 0.0 1.99" euler="0 0 0"/>
		<body childclass="wall" name="wall_link" pos="0.0 -0.081 0.0">
			<inertial mass="100" pos="0 0 0" diaginertia="0.0001 0.0001 0.0001"/>
			<geom material="Paint" name="wall_0" pos="-0.15 -1.504 1.1195" size="0.15 1.0 1.1195" type="box" euler="0 0 0"/>
			<geom material="Paint" name="wall_1" pos="-0.15 1.534 1.1195" size="0.15 1.0 1.1195" type="box" euler="0 0 0"/>
			<geom material="Paint" name="wall_2" pos="-0.15 0 2.739" size="0.15 2.534 0.5" type="box" euler="0 0 0"/>
			<body childclass="frame" name="frame_link" pos="0 -0.32984 0.974">
				<inertial mass="500" pos="0 0 0" diaginertia="0.0001 0.0001 0.0001"/>
				<geom material="Wood" name="door_frame_0" pos="0 -0.16416 0.14549999999999996" size="0.011 0.05 1.1195" type="box" euler="0 0 0"/>
				<geom material="Wood" name="door_frame_1" pos="0 0.82384 0.14549999999999996" size="0.011 0.05 1.1195" type="box" euler="0 0 0"/>
				<geom material="Wood" name="door_frame_2" pos="0 0.32984 1.2149999999999999" size="0.011 0.534 0.05" type="box" euler="0 0 0"/>
				<geom material="Wood" name="door_frame_3" pos="-0.041499999999999995 -0.16416 0.14549999999999996" size="0.011 0.05 1.1195" type="box" euler="0 0 0"/>
				<geom material="Wood" name="door_frame_4" pos="-0.041499999999999995 0.82384 0.14549999999999996" size="0.011 0.05 1.1195" type="box" euler="0 0 0"/>
				<geom material="Wood" name="door_frame_5" pos="-0.041499999999999995 0.32984 1.2149999999999999" size="0.011 0.534 0.05" type="box" euler="0 0 0"/>
				<body childclass="door" name="door_link" pos="0 0 0">
					<joint armature="0.0001" axis="0 0 1" damping="1.2" frictionloss="0" limited="true" name="hinge0" pos="0 -0.10415999999999999 0" range="-1.57 0.0" stiffness="0.1" type="hinge"/>
					<geom material="Carpet" name="door0" pos="0 0.32984 0.09549999999999992" size="0.011 0.434 1.058805" type="box" euler="0 0 0"/>
					<inertial mass="39.661800023999994" pos="0 0.32984 0.09549999999999992" diaginertia="17.612301547407483 15.123721904901604 2.491779027707816"/>
					<body childclass="door_knob" name="knob_link" pos="0 0.65968 0">
						<inertial mass="1" pos="0 0 0" diaginertia="0.001 0.001 0.001"/>
						<joint armature="0" axis="0 1 0" damping="30000" frictionloss="0" limited="true" name="target0" range="-0.2 0.3" stiffness="0" type="slide"/>
						<joint armature="0" axis="0 0 1" damping="30000" frictionloss="0" limited="true" name="target1" range="-0.5 0.5" stiffness="0" type="slide"/>
						<body childclass="door_knob" name="pullknob_link" pos="0.004999999999999999 0 0">
							<geom friction="0.67 0.002 0.002" material="Wood" mesh="door_knob_1" name="door_knob_1" euler="1.57 1.57 0"/>
							<geom friction="0.67 0.002 0.002" material="Wood" mesh="door_knob_2" name="door_knob_2" euler="1.57 1.57 0"/>
							<geom friction="0.67 0.002 0.002" material="Wood" mesh="door_knob_3" name="door_knob_3" euler="1.57 1.57 0"/>
							<geom friction="0.67 0.002 0.002" material="Wood" mesh="door_knob_4" name="door_knob_4" euler="1.57 1.57 0"/>
							<geom friction="0.67 0.002 0.002" material="Wood" mesh="door_knob_5" name="door_knob_5" euler="1.57 1.57 0"/>
							<geom friction="0.67 0.002 0.002" material="Wood" mesh="door_knob_6" name="door_knob_6" euler="1.57 1.57 0"/>
							<geom friction="0.67 0.002 0.002" material="Wood" mesh="door_knob_7" name="door_knob_7" euler="1.57 1.57 0"/>
							<geom friction="0.67 0.002 0.002" material="Wood" mesh="door_knob_8" name="door_knob_8" euler="1.57 1.57 0"/>
						</body>
					</body>
				</body>
			</body>
		</body>
	</worldbody>
</mujoco>