<?xml version="1.0" encoding="utf-8"?>
<mujoco model="door_knob">
	<compiler angle="radian"/>
	<include file="../../robot/baxter_rightarm.xml"/>
	<option gravity="0 0 0" timestep="0.001"/>
	<visual>
		<map fogend="5" fogstart="3" force="0.1" zfar="10" znear="0.01"/>
		<quality shadowsize="2048"/>
		<global offheight="256" offwidth="256"/>
	</visual>
	<asset>
		<mesh file="../../door/pullknobs/1555111995/body_1.stl" name="door_knob_1" scale="0.001 0.001 0.001"/>
		<mesh file="../../door/pullknobs/1555111995/body_2.stl" name="door_knob_2" scale="0.001 0.001 0.001"/>
		<mesh file="../../door/pullknobs/1555111995/body_3.stl" name="door_knob_3" scale="0.001 0.001 0.001"/>
		<mesh file="../../door/pullknobs/1555111995/body_4.stl" name="door_knob_4" scale="0.001 0.001 0.001"/>
		<mesh file="../../door/pullknobs/1555111995/body_5.stl" name="door_knob_5" scale="0.001 0.001 0.001"/>
		<mesh file="../../door/pullknobs/1555111995/body_6.stl" name="door_knob_6" scale="0.001 0.001 0.001"/>
		<mesh file="../../door/pullknobs/1555111995/body_7.stl" name="door_knob_7" scale="0.001 0.001 0.001"/>
		<mesh file="../../door/pullknobs/1555111995/body_8.stl" name="door_knob_8" scale="0.001 0.001 0.001"/>
		<texture builtin="flat" height="32" name="wall_geom" type="2d" width="32"/>
		<texture builtin="flat" height="32" name="frame_geom" type="2d" width="32"/>
		<texture builtin="flat" height="32" name="door_geom" type="2d" width="32"/>
		<texture builtin="flat" height="32" name="knob_geom" type="2d" width="32"/>
		<texture builtin="gradient" height="128" rgb1="0.4 0.6 0.8" rgb2="0 0 0" type="skybox" width="128"/>
		<texture builtin="gradient" height="512" name="texplane" rgb1="0.43 0.14 0.16" rgb2="0.48 0.45 0.29" type="2d" width="512"/>
		<material name="Paint" shininess="0.26" specular="0.04" texture="wall_geom"/>
		<material name="Wood" shininess="0.13" specular="0.11" texture="frame_geom"/>
		<material name="Carpet" shininess="0.01" specular="0.01" texture="door_geom"/>
		<material name="Metal" shininess="0.85" specular="0.93" texture="knob_geom"/>
		<material name="Floor" texture="texplane"/>
	</asset>
	<contact/>
	<default>
		<joint armature="1" damping="1" limited="true"/>
		<default class="wall">
			<geom rgba="0.23 0.27 0.31 1.0" type="mesh"/>
		</default>
		<default class="frame">
			<geom rgba="0.73 0.81 0.84 1.0" type="mesh"/>
		</default>
		<default class="door">
			<geom rgba="0.22 0.12 0.34 1.0" type="mesh"/>
		</default>
		<default class="door_knob">
			<geom condim="4" rgba="0.57 0.19 0.61 1.0" type="mesh"/>
		</default>
		<default class="robot">
			<joint damping="0.1"/>
		</default>
	</default>
	<worldbody>
		<light diffuse="1.0 0.9 1.0" dir="0.2 0.08 -0.5" directional="true" pos="3.77 4.71 3.11"/>
		<light diffuse="0.9 0.9 1.0" dir="0.48 -0.03 -0.34" directional="true" pos="2.08 0.49 3.96"/>
		<light diffuse="0.9 0.9 1.0" dir="-0.11 0.11 -0.45" directional="true" pos="0.45 4.24 4.47"/>
		<geom material="Floor" name="floor" pos="0 0 -0.05" size="15.0 15.0 0.05" type="plane"/>
		<camera fovy="60" mode="fixed" name="camera1" pos="0.99 0.5 1.0" euler="0.0 1.57 1.57"/>
		<camera fovy="60" mode="fixed" name="camera2" pos="0.5 0.0 1.99" euler="0 0 0"/>
		<body childclass="wall" name="wall_link" pos="0.0 -0.076 0.0">
			<inertial mass="100" pos="0 0 0" diaginertia="0.0001 0.0001 0.0001"/>
			<geom material="Paint" name="wall_0" pos="-0.15 -1.6365 1.254" size="0.15 1.0 1.254" type="box" euler="0 0 0"/>
			<geom material="Paint" name="wall_1" pos="-0.15 1.6665 1.254" size="0.15 1.0 1.254" type="box" euler="0 0 0"/>
			<geom material="Paint" name="wall_2" pos="-0.15 0 3.008" size="0.15 2.6665 0.5" type="box" euler="0 0 0"/>
			<body childclass="frame" name="frame_link" pos="0 -0.41920999999999997 1.041">
				<inertial mass="500" pos="0 0 0" diaginertia="0.0001 0.0001 0.0001"/>
				<geom material="Carpet" name="door_frame_0" pos="0 -0.20729000000000003 0.21300000000000008" size="0.0105 0.05 1.254" type="box" euler="0 0 0"/>
				<geom material="Carpet" name="door_frame_1" pos="0 1.04571 0.21300000000000008" size="0.0105 0.05 1.254" type="box" euler="0 0 0"/>
				<geom material="Carpet" name="door_frame_2" pos="0 0.41920999999999997 1.417" size="0.0105 0.6665 0.05" type="box" euler="0 0 0"/>
				<geom material="Carpet" name="door_frame_3" pos="-0.0405 -0.20729000000000003 0.21300000000000008" size="0.0105 0.05 1.254" type="box" euler="0 0 0"/>
				<geom material="Carpet" name="door_frame_4" pos="-0.0405 1.04571 0.21300000000000008" size="0.0105 0.05 1.254" type="box" euler="0 0 0"/>
				<geom material="Carpet" name="door_frame_5" pos="-0.0405 0.41920999999999997 1.417" size="0.0105 0.6665 0.05" type="box" euler="0 0 0"/>
				<body childclass="door" name="door_link" pos="0 0 0">
					<joint armature="0.0001" axis="0 0 1" damping="1.4" frictionloss="0" limited="true" name="hinge0" pos="0 -0.14729 0" range="-1.57 0.0" stiffness="0.19" type="hinge"/>
					<geom material="Wood" name="door0" pos="0 0.41920999999999997 0.16300000000000003" size="0.0105 0.5665 1.19196" type="box" euler="0 0 0"/>
					<inertial mass="52.824647568" pos="0 0.41920999999999997 0.16300000000000003" diaginertia="31.17601968730449 25.52709274210942 5.65280955679132"/>
					<body childclass="door_knob" name="knob_link" pos="0 0.8384199999999999 0">
						<inertial mass="1" pos="0 0 0" diaginertia="0.001 0.001 0.001"/>
						<joint armature="0" axis="0 1 0" damping="30000" frictionloss="0" limited="true" name="target0" range="-0.2 0.3" stiffness="0" type="slide"/>
						<joint armature="0" axis="0 0 1" damping="30000" frictionloss="0" limited="true" name="target1" range="-0.5 0.5" stiffness="0" type="slide"/>
						<body childclass="door_knob" name="pullknob_link" pos="0.0045000000000000005 0 0">
							<geom friction="0.56 0.001 0.003" material="Paint" mesh="door_knob_1" name="door_knob_1" euler="1.57 1.57 0"/>
							<geom friction="0.56 0.001 0.003" material="Paint" mesh="door_knob_2" name="door_knob_2" euler="1.57 1.57 0"/>
							<geom friction="0.56 0.001 0.003" material="Paint" mesh="door_knob_3" name="door_knob_3" euler="1.57 1.57 0"/>
							<geom friction="0.56 0.001 0.003" material="Paint" mesh="door_knob_4" name="door_knob_4" euler="1.57 1.57 0"/>
							<geom friction="0.56 0.001 0.003" material="Paint" mesh="door_knob_5" name="door_knob_5" euler="1.57 1.57 0"/>
							<geom friction="0.56 0.001 0.003" material="Paint" mesh="door_knob_6" name="door_knob_6" euler="1.57 1.57 0"/>
							<geom friction="0.56 0.001 0.003" material="Paint" mesh="door_knob_7" name="door_knob_7" euler="1.57 1.57 0"/>
							<geom friction="0.56 0.001 0.003" material="Paint" mesh="door_knob_8" name="door_knob_8" euler="1.57 1.57 0"/>
						</body>
					</body>
				</body>
			</body>
		</body>
	</worldbody>
</mujoco>