<?xml version="1.0" encoding="utf-8"?>
<mujoco model="door_knob">
	<compiler angle="radian"/>
	<include file="../../robot/blue_right_v2_position.xml"/>
	<option gravity="0 0 -9.81" timestep="0.001"/>
	<visual>
		<map fogend="5" fogstart="3" force="0.1" zfar="10" znear="0.01"/>
		<quality shadowsize="2048"/>
		<global offheight="256" offwidth="256"/>
	</visual>
	<asset>
		<mesh file="../../door/pullknobs/1555111995/body_1.stl" name="door_knob_1" scale="0.001 0.001 0.001"/>
		<mesh file="../../door/pullknobs/1555111995/body_2.stl" name="door_knob_2" scale="0.001 0.001 0.001"/>
		<mesh file="../../door/pullknobs/1555111995/body_3.stl" name="door_knob_3" scale="0.001 0.001 0.001"/>
		<mesh file="../../door/pullknobs/1555111995/body_4.stl" name="door_knob_4" scale="0.001 0.001 0.001"/>
		<mesh file="../../door/pullknobs/1555111995/body_5.stl" name="door_knob_5" scale="0.001 0.001 0.001"/>
		<mesh file="../../door/pullknobs/1555111995/body_6.stl" name="door_knob_6" scale="0.001 0.001 0.001"/>
		<mesh file="../../door/pullknobs/1555111995/body_7.stl" name="door_knob_7" scale="0.001 0.001 0.001"/>
		<mesh file="../../door/pullknobs/1555111995/body_8.stl" name="door_knob_8" scale="0.001 0.001 0.001"/>
		<texture builtin="flat" height="32" name="wall_geom" type="2d" width="32"/>
		<texture builtin="flat" height="32" name="frame_geom" type="2d" width="32"/>
		<texture builtin="flat" height="32" name="door_geom" type="2d" width="32"/>
		<texture builtin="flat" height="32" name="knob_geom" type="2d" width="32"/>
		<texture builtin="gradient" height="128" rgb1="0.4 0.6 0.8" rgb2="0 0 0" type="skybox" width="128"/>
		<texture builtin="gradient" height="512" name="texplane" rgb1="0.34 0.02 0.3" rgb2="0.06 0.12 0.12" type="2d" width="512"/>
		<material name="Paint" shininess="0.07" specular="0.42" texture="wall_geom"/>
		<material name="Wood" shininess="0.17" specular="0.17" texture="frame_geom"/>
		<material name="Carpet" shininess="0.01" specular="0.03" texture="door_geom"/>
		<material name="Metal" shininess="0.84" specular="0.95" texture="knob_geom"/>
		<material name="Floor" texture="texplane"/>
	</asset>
	<contact/>
	<default>
		<joint armature="1" damping="1" limited="true"/>
		<default class="wall">
			<geom rgba="0.1 0.39 0.39 1.0" type="mesh"/>
		</default>
		<default class="frame">
			<geom rgba="0.72 0.84 0.79 1.0" type="mesh"/>
		</default>
		<default class="door">
			<geom rgba="0.34 0.76 0.6 1.0" type="mesh"/>
		</default>
		<default class="door_knob">
			<geom condim="4" rgba="0.45 0.52 0.77 1.0" type="mesh"/>
		</default>
		<default class="robot">
			<joint damping="0.1"/>
		</default>
	</default>
	<worldbody>
		<light diffuse="1.0 0.9 1.0" dir="0.27 0.08 -0.42" directional="true" pos="1.19 3.81 3.58"/>
		<light diffuse="1.0 0.9 0.9" dir="0.17 -0.32 -0.44" directional="true" pos="2.99 -2.4 6.7"/>
		<light diffuse="0.9 1.0 1.0" dir="-0.14 -0.46 -0.38" directional="true" pos="0.57 -1.51 3.67"/>
		<light diffuse="0.9 0.9 1.0" dir="0.0 0.46 -0.41" directional="true" pos="0.49 -0.73 4.55"/>
		<geom material="Floor" name="floor" pos="0 0 -0.05" size="15.0 15.0 0.05" type="plane"/>
		<camera fovy="60" mode="fixed" name="camera1" pos="0.99 -0.5 1.0" euler="0.0 1.57 1.57"/>
		<camera fovy="60" mode="fixed" name="camera2" pos="0.5 0.0 1.99" euler="0 0 0"/>
		<body childclass="wall" name="wall_link" pos="0.0 -0.072 0.0">
			<inertial mass="100" pos="0 0 0" diaginertia="0.0001 0.0001 0.0001"/>
			<geom material="Carpet" name="wall_0" pos="-0.15 -1.48 1.201" size="0.15 1.0 1.201" type="box" euler="0 0 0"/>
			<geom material="Carpet" name="wall_1" pos="-0.15 1.51 1.201" size="0.15 1.0 1.201" type="box" euler="0 0 0"/>
			<geom material="Carpet" name="wall_2" pos="-0.15 0 2.902" size="0.15 2.51 0.5" type="box" euler="0 0 0"/>
			<body childclass="frame" name="frame_link" pos="0 -0.29519999999999996 1.086">
				<inertial mass="500" pos="0 0 0" diaginertia="0.0001 0.0001 0.0001"/>
				<geom material="Wood" name="door_frame_0" pos="0 -0.1748 0.11499999999999999" size="0.012 0.05 1.201" type="box" euler="0 0 0"/>
				<geom material="Wood" name="door_frame_1" pos="0 0.7652 0.11499999999999999" size="0.012 0.05 1.201" type="box" euler="0 0 0"/>
				<geom material="Wood" name="door_frame_2" pos="0 0.29519999999999996 1.266" size="0.012 0.51 0.05" type="box" euler="0 0 0"/>
				<geom material="Wood" name="door_frame_3" pos="-0.0435 -0.1748 0.11499999999999999" size="0.012 0.05 1.201" type="box" euler="0 0 0"/>
				<geom material="Wood" name="door_frame_4" pos="-0.0435 0.7652 0.11499999999999999" size="0.012 0.05 1.201" type="box" euler="0 0 0"/>
				<geom material="Wood" name="door_frame_5" pos="-0.0435 0.29519999999999996 1.266" size="0.012 0.51 0.05" type="box" euler="0 0 0"/>
				<body childclass="door" name="door_link" pos="0 0 0">
					<joint armature="0.0001" axis="0 0 1" damping="1.7" frictionloss="0" limited="true" name="hinge0" pos="0 0.7051999999999999 0" range="-0.0 1.57" stiffness="0.11" type="hinge"/>
					<geom material="Wood" name="door0" pos="0 0.29519999999999996 0.06499999999999995" size="0.012 0.41 1.1394900000000001" type="box" euler="0 0 0"/>
					<inertial mass="43.44592224" pos="0 0.29519999999999996 0.06499999999999995" diaginertia="21.620153586006083 19.1878191474256 2.43650524711552"/>
					<body childclass="door_knob" name="knob_link" pos="0 0 0">
						<inertial mass="1" pos="0 0 0" diaginertia="0.001 0.001 0.001"/>
						<joint armature="0" axis="0 1 0" damping="30000" frictionloss="0" limited="true" name="target0" range="-0.2 0.3" stiffness="0" type="slide"/>
						<joint armature="0" axis="0 0 1" damping="30000" frictionloss="0" limited="true" name="target1" range="-0.5 0.5" stiffness="0" type="slide"/>
						<body childclass="door_knob" name="pullknob_link" pos="0.006 0 0">
							<geom friction="0.67 0.002 0.001" material="Carpet" mesh="door_knob_1" name="door_knob_1" euler="-1.57 1.57 0"/>
							<geom friction="0.67 0.002 0.001" material="Carpet" mesh="door_knob_2" name="door_knob_2" euler="-1.57 1.57 0"/>
							<geom friction="0.67 0.002 0.001" material="Carpet" mesh="door_knob_3" name="door_knob_3" euler="-1.57 1.57 0"/>
							<geom friction="0.67 0.002 0.001" material="Carpet" mesh="door_knob_4" name="door_knob_4" euler="-1.57 1.57 0"/>
							<geom friction="0.67 0.002 0.001" material="Carpet" mesh="door_knob_5" name="door_knob_5" euler="-1.57 1.57 0"/>
							<geom friction="0.67 0.002 0.001" material="Carpet" mesh="door_knob_6" name="door_knob_6" euler="-1.57 1.57 0"/>
							<geom friction="0.67 0.002 0.001" material="Carpet" mesh="door_knob_7" name="door_knob_7" euler="-1.57 1.57 0"/>
							<geom friction="0.67 0.002 0.001" material="Carpet" mesh="door_knob_8" name="door_knob_8" euler="-1.57 1.57 0"/>
						</body>
					</body>
				</body>
			</body>
		</body>
	</worldbody>
</mujoco>