<?xml version="1.0" encoding="utf-8"?>
<mujoco model="door_knob">
	<compiler angle="radian"/>
	<include file="../../robot/blue_right_v2_motor.xml"/>
	<option gravity="0 0 -9.81" timestep="0.001"/>
	<visual>
		<map fogend="5" fogstart="3" force="0.1" zfar="10" znear="0.01"/>
		<quality shadowsize="2048"/>
		<global offheight="256" offwidth="256"/>
	</visual>
	<asset>
		<mesh file="../../door/pullknobs/1555112003/body_1.stl" name="door_knob_1" scale="0.001 0.001 0.001"/>
		<mesh file="../../door/pullknobs/1555112003/body_2.stl" name="door_knob_2" scale="0.001 0.001 0.001"/>
		<mesh file="../../door/pullknobs/1555112003/body_3.stl" name="door_knob_3" scale="0.001 0.001 0.001"/>
		<mesh file="../../door/pullknobs/1555112003/body_4.stl" name="door_knob_4" scale="0.001 0.001 0.001"/>
		<mesh file="../../door/pullknobs/1555112003/body_5.stl" name="door_knob_5" scale="0.001 0.001 0.001"/>
		<mesh file="../../door/pullknobs/1555112003/body_6.stl" name="door_knob_6" scale="0.001 0.001 0.001"/>
		<mesh file="../../door/pullknobs/1555112003/body_7.stl" name="door_knob_7" scale="0.001 0.001 0.001"/>
		<mesh file="../../door/pullknobs/1555112003/body_8.stl" name="door_knob_8" scale="0.001 0.001 0.001"/>
		<texture builtin="flat" height="32" name="wall_geom" type="2d" width="32"/>
		<texture builtin="flat" height="32" name="frame_geom" type="2d" width="32"/>
		<texture builtin="flat" height="32" name="door_geom" type="2d" width="32"/>
		<texture builtin="flat" height="32" name="knob_geom" type="2d" width="32"/>
		<texture builtin="gradient" height="128" rgb1="0.4 0.6 0.8" rgb2="0 0 0" type="skybox" width="128"/>
		<texture builtin="gradient" height="512" name="texplane" rgb1="0.19 0.04 0.26" rgb2="0.15 0.09 0.33" type="2d" width="512"/>
		<material name="Paint" shininess="0.03" specular="0.32" texture="wall_geom"/>
		<material name="Wood" shininess="0.14" specular="0.16" texture="frame_geom"/>
		<material name="Carpet" shininess="0.02" specular="0.03" texture="door_geom"/>
		<material name="Metal" shininess="0.88" specular="0.89" texture="knob_geom"/>
		<material name="Floor" texture="texplane"/>
	</asset>
	<contact/>
	<default>
		<joint armature="1" damping="1" limited="true"/>
		<default class="wall">
			<geom rgba="0.52 0.7 0.84 1.0" type="mesh"/>
		</default>
		<default class="frame">
			<geom rgba="0.74 0.74 0.77 1.0" type="mesh"/>
		</default>
		<default class="door">
			<geom rgba="0.68 0.53 0.7 1.0" type="mesh"/>
		</default>
		<default class="door_knob">
			<geom condim="4" rgba="0.99 0.05 0.87 1.0" type="mesh"/>
		</default>
		<default class="robot">
			<joint damping="0.1"/>
		</default>
	</default>
	<worldbody>
		<light diffuse="0.9 1.0 1.0" dir="0.23 -0.29 -0.43" directional="true" pos="4.94 2.11 4.67"/>
		<light diffuse="0.9 1.0 0.9" dir="-0.37 -0.24 -0.41" directional="true" pos="3.61 0.72 4.86"/>
		<light diffuse="1.0 0.9 1.0" dir="-0.26 0.29 -0.26" directional="true" pos="4.3 1.06 3.19"/>
		<light diffuse="0.9 1.0 1.0" dir="0.44 -0.01 -0.4" directional="true" pos="3.38 4.24 6.92"/>
		<light diffuse="0.9 0.9 0.9" dir="0.02 0.35 -0.48" directional="true" pos="0.03 -4.23 4.68"/>
		<geom material="Floor" name="floor" pos="0 0 -0.05" size="15.0 15.0 0.05" type="plane"/>
		<camera fovy="60" mode="fixed" name="camera1" pos="0.99 -0.5 1.0" euler="0.0 1.57 1.57"/>
		<camera fovy="60" mode="fixed" name="camera2" pos="0.5 0.0 1.99" euler="0 0 0"/>
		<body childclass="wall" name="wall_link" pos="0.0 0.064 0.0">
			<inertial mass="100" pos="0 0 0" diaginertia="0.0001 0.0001 0.0001"/>
			<geom material="Wood" name="wall_0" pos="-0.15 -1.6504999999999999 1.112" size="0.15 1.0 1.112" type="box" euler="0 0 0"/>
			<geom material="Wood" name="wall_1" pos="-0.15 1.6804999999999999 1.112" size="0.15 1.0 1.112" type="box" euler="0 0 0"/>
			<geom material="Wood" name="wall_2" pos="-0.15 0 2.724" size="0.15 2.6805 0.5" type="box" euler="0 0 0"/>
			<body childclass="frame" name="frame_link" pos="0 -0.41796 1.061">
				<inertial mass="500" pos="0 0 0" diaginertia="0.0001 0.0001 0.0001"/>
				<geom material="Paint" name="door_frame_0" pos="0 -0.22254000000000002 0.051000000000000156" size="0.012 0.05 1.112" type="box" euler="0 0 0"/>
				<geom material="Paint" name="door_frame_1" pos="0 1.05846 0.051000000000000156" size="0.012 0.05 1.112" type="box" euler="0 0 0"/>
				<geom material="Paint" name="door_frame_2" pos="0 0.41796 1.1130000000000002" size="0.012 0.6805 0.05" type="box" euler="0 0 0"/>
				<geom material="Paint" name="door_frame_3" pos="-0.0435 -0.22254000000000002 0.051000000000000156" size="0.012 0.05 1.112" type="box" euler="0 0 0"/>
				<geom material="Paint" name="door_frame_4" pos="-0.0435 1.05846 0.051000000000000156" size="0.012 0.05 1.112" type="box" euler="0 0 0"/>
				<geom material="Paint" name="door_frame_5" pos="-0.0435 0.41796 1.1130000000000002" size="0.012 0.6805 0.05" type="box" euler="0 0 0"/>
				<body childclass="door" name="door_link" pos="0 0 0">
					<joint armature="0.0001" axis="0 0 1" damping="1.9" frictionloss="0" limited="true" name="hinge0" pos="0 0.99846 0" range="-0.0 1.57" stiffness="0.16" type="hinge"/>
					<geom material="Paint" name="door0" pos="0 0.41796 0.001000000000000112" size="0.012 0.5805 1.05138" type="box" euler="0 0 0"/>
					<inertial mass="55.92806352" pos="0 0.41796 0.001000000000000112" diaginertia="27.308261233212125 21.02872817126592 6.2849021560441205"/>
					<body childclass="door_knob" name="knob_link" pos="0 0 0">
						<inertial mass="1" pos="0 0 0" diaginertia="0.001 0.001 0.001"/>
						<joint armature="0" axis="0 1 0" damping="30000" frictionloss="0" limited="true" name="target0" range="-0.2 0.3" stiffness="0" type="slide"/>
						<joint armature="0" axis="0 0 1" damping="30000" frictionloss="0" limited="true" name="target1" range="-0.5 0.5" stiffness="0" type="slide"/>
						<body childclass="door_knob" name="pullknob_link" pos="0.006 0 0">
							<geom friction="0.79 0.001 0.003" material="Paint" mesh="door_knob_1" name="door_knob_1" euler="-1.57 1.57 0"/>
							<geom friction="0.79 0.001 0.003" material="Paint" mesh="door_knob_2" name="door_knob_2" euler="-1.57 1.57 0"/>
							<geom friction="0.79 0.001 0.003" material="Paint" mesh="door_knob_3" name="door_knob_3" euler="-1.57 1.57 0"/>
							<geom friction="0.79 0.001 0.003" material="Paint" mesh="door_knob_4" name="door_knob_4" euler="-1.57 1.57 0"/>
							<geom friction="0.79 0.001 0.003" material="Paint" mesh="door_knob_5" name="door_knob_5" euler="-1.57 1.57 0"/>
							<geom friction="0.79 0.001 0.003" material="Paint" mesh="door_knob_6" name="door_knob_6" euler="-1.57 1.57 0"/>
							<geom friction="0.79 0.001 0.003" material="Paint" mesh="door_knob_7" name="door_knob_7" euler="-1.57 1.57 0"/>
							<geom friction="0.79 0.001 0.003" material="Paint" mesh="door_knob_8" name="door_knob_8" euler="-1.57 1.57 0"/>
						</body>
					</body>
				</body>
			</body>
		</body>
	</worldbody>
</mujoco>