<?xml version="1.0" encoding="utf-8"?>
<mujoco model="door_knob">
	<compiler angle="radian"/>
	<include file="../../robot/blue_right_v2_gripper_motor.xml"/>
	<option gravity="0 0 0" timestep="0.001"/>
	<visual>
		<map fogend="5" fogstart="3" force="0.1" zfar="10" znear="0.01"/>
		<quality shadowsize="2048"/>
		<global offheight="256" offwidth="256"/>
	</visual>
	<asset>
		<mesh file="../../door/pullknobs/1555111990/body_1.stl" name="door_knob_1" scale="0.001 0.001 0.001"/>
		<mesh file="../../door/pullknobs/1555111990/body_2.stl" name="door_knob_2" scale="0.001 0.001 0.001"/>
		<mesh file="../../door/pullknobs/1555111990/body_3.stl" name="door_knob_3" scale="0.001 0.001 0.001"/>
		<mesh file="../../door/pullknobs/1555111990/body_4.stl" name="door_knob_4" scale="0.001 0.001 0.001"/>
		<mesh file="../../door/pullknobs/1555111990/body_5.stl" name="door_knob_5" scale="0.001 0.001 0.001"/>
		<mesh file="../../door/pullknobs/1555111990/body_6.stl" name="door_knob_6" scale="0.001 0.001 0.001"/>
		<mesh file="../../door/pullknobs/1555111990/body_7.stl" name="door_knob_7" scale="0.001 0.001 0.001"/>
		<mesh file="../../door/pullknobs/1555111990/body_8.stl" name="door_knob_8" scale="0.001 0.001 0.001"/>
		<texture builtin="flat" height="32" name="wall_geom" type="2d" width="32"/>
		<texture builtin="flat" height="32" name="frame_geom" type="2d" width="32"/>
		<texture builtin="flat" height="32" name="door_geom" type="2d" width="32"/>
		<texture builtin="flat" height="32" name="knob_geom" type="2d" width="32"/>
		<texture builtin="gradient" height="128" rgb1="0.4 0.6 0.8" rgb2="0 0 0" type="skybox" width="128"/>
		<texture builtin="gradient" height="512" name="texplane" rgb1="0.46 0.2 0.07" rgb2="0.15 0.47 0.44" type="2d" width="512"/>
		<material name="Paint" shininess="0.43" specular="0.42" texture="wall_geom"/>
		<material name="Wood" shininess="0.03" specular="0.01" texture="frame_geom"/>
		<material name="Carpet" shininess="0.03" specular="0.04" texture="door_geom"/>
		<material name="Metal" shininess="0.94" specular="0.82" texture="knob_geom"/>
		<material name="Floor" texture="texplane"/>
	</asset>
	<contact/>
	<default>
		<joint armature="1" damping="1" limited="true"/>
		<default class="wall">
			<geom rgba="0.64 0.08 0.66 1.0" type="mesh"/>
		</default>
		<default class="frame">
			<geom rgba="0.72 0.76 0.8 1.0" type="mesh"/>
		</default>
		<default class="door">
			<geom rgba="0.47 0.79 0.44 1.0" type="mesh"/>
		</default>
		<default class="door_knob">
			<geom condim="4" rgba="0.03 0.62 0.24 1.0" type="mesh"/>
		</default>
		<default class="robot">
			<joint damping="0.1"/>
		</default>
	</default>
	<worldbody>
		<light diffuse="1.0 0.9 1.0" dir="0.05 -0.31 -0.35" directional="true" pos="2.96 1.91 6.42"/>
		<light diffuse="1.0 0.9 1.0" dir="-0.01 0.19 -0.4" directional="true" pos="2.05 -0.9 5.74"/>
		<geom material="Floor" name="floor" pos="0 0 -0.05" size="15.0 15.0 0.05" type="plane"/>
		<camera fovy="60" mode="fixed" name="camera1" pos="0.99 -0.5 1.0" euler="0.0 1.57 1.57"/>
		<camera fovy="60" mode="fixed" name="camera2" pos="0.5 0.0 1.99" euler="0 0 0"/>
		<body childclass="wall" name="wall_link" pos="0.0 0.042 0.0">
			<inertial mass="100" pos="0 0 0" diaginertia="0.0001 0.0001 0.0001"/>
			<geom material="Wood" name="wall_0" pos="-0.15 -1.6119999999999999 1.2305000000000001" size="0.15 1.0 1.2305000000000001" type="box" euler="0 0 0"/>
			<geom material="Wood" name="wall_1" pos="-0.15 1.642 1.2305000000000001" size="0.15 1.0 1.2305000000000001" type="box" euler="0 0 0"/>
			<geom material="Wood" name="wall_2" pos="-0.15 0 2.9610000000000003" size="0.15 2.642 0.5" type="box" euler="0 0 0"/>
			<body childclass="frame" name="frame_link" pos="0 -0.40108000000000005 1.038">
				<inertial mass="500" pos="0 0 0" diaginertia="0.0001 0.0001 0.0001"/>
				<geom material="Carpet" name="door_frame_0" pos="0 -0.20092000000000004 0.19250000000000012" size="0.013 0.05 1.2305000000000001" type="box" euler="0 0 0"/>
				<geom material="Carpet" name="door_frame_1" pos="0 1.00308 0.19250000000000012" size="0.013 0.05 1.2305000000000001" type="box" euler="0 0 0"/>
				<geom material="Carpet" name="door_frame_2" pos="0 0.40108 1.3730000000000002" size="0.013 0.642 0.05" type="box" euler="0 0 0"/>
				<geom material="Carpet" name="door_frame_3" pos="-0.0455 -0.20092000000000004 0.19250000000000012" size="0.013 0.05 1.2305000000000001" type="box" euler="0 0 0"/>
				<geom material="Carpet" name="door_frame_4" pos="-0.0455 1.00308 0.19250000000000012" size="0.013 0.05 1.2305000000000001" type="box" euler="0 0 0"/>
				<geom material="Carpet" name="door_frame_5" pos="-0.0455 0.40108 1.3730000000000002" size="0.013 0.642 0.05" type="box" euler="0 0 0"/>
				<body childclass="door" name="door_link" pos="0 0 0">
					<joint armature="0.0001" axis="0 0 1" damping="1.1" frictionloss="0" limited="true" name="hinge0" pos="0 0.94308 0" range="-0.0 1.57" stiffness="0.11" type="hinge"/>
					<geom material="Wood" name="door0" pos="0 0.40108 0.14250000000000007" size="0.013 0.542 1.168695" type="box" euler="0 0 0"/>
					<inertial mass="62.68296340800001" pos="0 0.40108 0.14250000000000007" diaginertia="35.25591262648308 29.121444412559164 6.141530494467889"/>
					<body childclass="door_knob" name="knob_link" pos="0 0 0">
						<inertial mass="1" pos="0 0 0" diaginertia="0.001 0.001 0.001"/>
						<joint armature="0" axis="0 1 0" damping="30000" frictionloss="0" limited="true" name="target0" range="-0.2 0.3" stiffness="0" type="slide"/>
						<joint armature="0" axis="0 0 1" damping="30000" frictionloss="0" limited="true" name="target1" range="-0.5 0.5" stiffness="0" type="slide"/>
						<body childclass="door_knob" name="pullknob_link" pos="0.006999999999999999 0 0">
							<geom friction="0.55 0.002 0.004" material="Paint" mesh="door_knob_1" name="door_knob_1" euler="-1.57 1.57 0"/>
							<geom friction="0.55 0.002 0.004" material="Paint" mesh="door_knob_2" name="door_knob_2" euler="-1.57 1.57 0"/>
							<geom friction="0.55 0.002 0.004" material="Paint" mesh="door_knob_3" name="door_knob_3" euler="-1.57 1.57 0"/>
							<geom friction="0.55 0.002 0.004" material="Paint" mesh="door_knob_4" name="door_knob_4" euler="-1.57 1.57 0"/>
							<geom friction="0.55 0.002 0.004" material="Paint" mesh="door_knob_5" name="door_knob_5" euler="-1.57 1.57 0"/>
							<geom friction="0.55 0.002 0.004" material="Paint" mesh="door_knob_6" name="door_knob_6" euler="-1.57 1.57 0"/>
							<geom friction="0.55 0.002 0.004" material="Paint" mesh="door_knob_7" name="door_knob_7" euler="-1.57 1.57 0"/>
							<geom friction="0.55 0.002 0.004" material="Paint" mesh="door_knob_8" name="door_knob_8" euler="-1.57 1.57 0"/>
						</body>
					</body>
				</body>
			</body>
		</body>
	</worldbody>
</mujoco>