<?xml version="1.0" encoding="utf-8"?>
<mujoco model="door_knob">
	<compiler angle="radian"/>
	<include file="../../robot/blue_right_v2_gripper_motor.xml"/>
	<option gravity="0 0 -9.81" timestep="0.001"/>
	<visual>
		<map fogend="5" fogstart="3" force="0.1" zfar="10" znear="0.01"/>
		<quality shadowsize="2048"/>
		<global offheight="256" offwidth="256"/>
	</visual>
	<asset>
		<mesh file="../../door/pullknobs/1555112003/body_1.stl" name="door_knob_1" scale="0.001 0.001 0.001"/>
		<mesh file="../../door/pullknobs/1555112003/body_2.stl" name="door_knob_2" scale="0.001 0.001 0.001"/>
		<mesh file="../../door/pullknobs/1555112003/body_3.stl" name="door_knob_3" scale="0.001 0.001 0.001"/>
		<mesh file="../../door/pullknobs/1555112003/body_4.stl" name="door_knob_4" scale="0.001 0.001 0.001"/>
		<mesh file="../../door/pullknobs/1555112003/body_5.stl" name="door_knob_5" scale="0.001 0.001 0.001"/>
		<mesh file="../../door/pullknobs/1555112003/body_6.stl" name="door_knob_6" scale="0.001 0.001 0.001"/>
		<mesh file="../../door/pullknobs/1555112003/body_7.stl" name="door_knob_7" scale="0.001 0.001 0.001"/>
		<mesh file="../../door/pullknobs/1555112003/body_8.stl" name="door_knob_8" scale="0.001 0.001 0.001"/>
		<texture builtin="flat" height="32" name="wall_geom" type="2d" width="32"/>
		<texture builtin="flat" height="32" name="frame_geom" type="2d" width="32"/>
		<texture builtin="flat" height="32" name="door_geom" type="2d" width="32"/>
		<texture builtin="flat" height="32" name="knob_geom" type="2d" width="32"/>
		<texture builtin="gradient" height="128" rgb1="0.4 0.6 0.8" rgb2="0 0 0" type="skybox" width="128"/>
		<texture builtin="gradient" height="512" name="texplane" rgb1="0.36 0.36 0.06" rgb2="0.4 0.05 0.15" type="2d" width="512"/>
		<material name="Paint" shininess="0.31" specular="0.07" texture="wall_geom"/>
		<material name="Wood" shininess="0.19" specular="0.02" texture="frame_geom"/>
		<material name="Carpet" shininess="0.01" specular="0.03" texture="door_geom"/>
		<material name="Metal" shininess="0.98" specular="0.92" texture="knob_geom"/>
		<material name="Floor" texture="texplane"/>
	</asset>
	<contact/>
	<default>
		<joint armature="1" damping="1" limited="true"/>
		<default class="wall">
			<geom rgba="0.5 0.51 0.13 1.0" type="mesh"/>
		</default>
		<default class="frame">
			<geom rgba="0.7 0.71 0.73 1.0" type="mesh"/>
		</default>
		<default class="door">
			<geom rgba="0.98 0.51 0.69 1.0" type="mesh"/>
		</default>
		<default class="door_knob">
			<geom condim="4" rgba="0.38 0.37 0.38 1.0" type="mesh"/>
		</default>
		<default class="robot">
			<joint damping="0.1"/>
		</default>
	</default>
	<worldbody>
		<light diffuse="1.0 1.0 1.0" dir="0.18 -0.05 -0.43" directional="true" pos="0.51 2.22 3.5"/>
		<light diffuse="0.9 0.9 0.9" dir="-0.23 0.15 -0.29" directional="true" pos="2.94 -3.26 6.6"/>
		<light diffuse="0.9 1.0 1.0" dir="0.06 -0.28 -0.32" directional="true" pos="0.96 4.04 5.56"/>
		<light diffuse="0.9 0.9 1.0" dir="-0.22 -0.01 -0.36" directional="true" pos="1.84 2.01 6.32"/>
		<light diffuse="1.0 1.0 1.0" dir="-0.32 0.1 -0.39" directional="true" pos="1.86 -3.05 3.56"/>
		<geom material="Floor" name="floor" pos="0 0 -0.05" size="15.0 15.0 0.05" type="plane"/>
		<camera fovy="60" mode="fixed" name="camera1" pos="0.99 -0.5 1.0" euler="0.0 1.57 1.57"/>
		<camera fovy="60" mode="fixed" name="camera2" pos="0.5 0.0 1.99" euler="0 0 0"/>
		<body childclass="wall" name="wall_link" pos="0.0 -0.077 0.0">
			<inertial mass="100" pos="0 0 0" diaginertia="0.0001 0.0001 0.0001"/>
			<geom material="Paint" name="wall_0" pos="-0.15 -1.485 1.1545" size="0.15 1.0 1.1545" type="box" euler="0 0 0"/>
			<geom material="Paint" name="wall_1" pos="-0.15 1.5150000000000001 1.1545" size="0.15 1.0 1.1545" type="box" euler="0 0 0"/>
			<geom material="Paint" name="wall_2" pos="-0.15 0 2.809" size="0.15 2.515 0.5" type="box" euler="0 0 0"/>
			<body childclass="frame" name="frame_link" pos="0 -0.332 1.053">
				<inertial mass="500" pos="0 0 0" diaginertia="0.0001 0.0001 0.0001"/>
				<geom material="Paint" name="door_frame_0" pos="0 -0.14300000000000002 0.10150000000000015" size="0.014 0.05 1.1545" type="box" euler="0 0 0"/>
				<geom material="Paint" name="door_frame_1" pos="0 0.807 0.10150000000000015" size="0.014 0.05 1.1545" type="box" euler="0 0 0"/>
				<geom material="Paint" name="door_frame_2" pos="0 0.33199999999999996 1.2060000000000002" size="0.014 0.515 0.05" type="box" euler="0 0 0"/>
				<geom material="Paint" name="door_frame_3" pos="-0.0475 -0.14300000000000002 0.10150000000000015" size="0.014 0.05 1.1545" type="box" euler="0 0 0"/>
				<geom material="Paint" name="door_frame_4" pos="-0.0475 0.807 0.10150000000000015" size="0.014 0.05 1.1545" type="box" euler="0 0 0"/>
				<geom material="Paint" name="door_frame_5" pos="-0.0475 0.33199999999999996 1.2060000000000002" size="0.014 0.515 0.05" type="box" euler="0 0 0"/>
				<body childclass="door" name="door_link" pos="0 0 0">
					<joint armature="0.0001" axis="0 0 1" damping="1.1" frictionloss="0" limited="true" name="hinge0" pos="0 0.747 0" range="-0.0 1.57" stiffness="0.16" type="hinge"/>
					<geom material="Wood" name="door0" pos="0 0.33199999999999996 0.0515000000000001" size="0.014 0.415 1.093455" type="box" euler="0 0 0"/>
					<inertial mass="47.38419868" pos="0 0.33199999999999996 0.0515000000000001" diaginertia="21.98856237247276 19.271410267565518 2.7233436402014264"/>
					<body childclass="door_knob" name="knob_link" pos="0 0 0">
						<inertial mass="1" pos="0 0 0" diaginertia="0.001 0.001 0.001"/>
						<joint armature="0" axis="0 1 0" damping="30000" frictionloss="0" limited="true" name="target0" range="-0.2 0.3" stiffness="0" type="slide"/>
						<joint armature="0" axis="0 0 1" damping="30000" frictionloss="0" limited="true" name="target1" range="-0.5 0.5" stiffness="0" type="slide"/>
						<body childclass="door_knob" name="pullknob_link" pos="0.008 0 0">
							<geom friction="0.83 0.001 0.002" material="Carpet" mesh="door_knob_1" name="door_knob_1" euler="-1.57 1.57 0"/>
							<geom friction="0.83 0.001 0.002" material="Carpet" mesh="door_knob_2" name="door_knob_2" euler="-1.57 1.57 0"/>
							<geom friction="0.83 0.001 0.002" material="Carpet" mesh="door_knob_3" name="door_knob_3" euler="-1.57 1.57 0"/>
							<geom friction="0.83 0.001 0.002" material="Carpet" mesh="door_knob_4" name="door_knob_4" euler="-1.57 1.57 0"/>
							<geom friction="0.83 0.001 0.002" material="Carpet" mesh="door_knob_5" name="door_knob_5" euler="-1.57 1.57 0"/>
							<geom friction="0.83 0.001 0.002" material="Carpet" mesh="door_knob_6" name="door_knob_6" euler="-1.57 1.57 0"/>
							<geom friction="0.83 0.001 0.002" material="Carpet" mesh="door_knob_7" name="door_knob_7" euler="-1.57 1.57 0"/>
							<geom friction="0.83 0.001 0.002" material="Carpet" mesh="door_knob_8" name="door_knob_8" euler="-1.57 1.57 0"/>
						</body>
					</body>
				</body>
			</body>
		</body>
	</worldbody>
</mujoco>