<?xml version="1.0" encoding="utf-8"?>
<mujoco model="door_knob">
	<compiler angle="radian"/>
	<include file="../../robot/blue_right_v2_position.xml"/>
	<option gravity="0 0 -9.81" timestep="0.001"/>
	<visual>
		<map fogend="5" fogstart="3" force="0.1" zfar="10" znear="0.01"/>
		<quality shadowsize="2048"/>
		<global offheight="256" offwidth="256"/>
	</visual>
	<asset>
		<mesh file="../../door/roundknobs/1558288443/body_1.stl" name="door_knob_1" scale="0.001 0.001 0.001"/>
		<mesh file="../../door/roundknobs/1558288443/body_2.stl" name="door_knob_2" scale="0.001 0.001 0.001"/>
		<texture builtin="flat" height="32" name="wall_geom" type="2d" width="32"/>
		<texture builtin="flat" height="32" name="frame_geom" type="2d" width="32"/>
		<texture builtin="flat" height="32" name="door_geom" type="2d" width="32"/>
		<texture builtin="flat" height="32" name="knob_geom" type="2d" width="32"/>
		<texture builtin="gradient" height="128" rgb1="0.4 0.6 0.8" rgb2="0 0 0" type="skybox" width="128"/>
		<texture builtin="gradient" height="512" name="texplane" rgb1="0.15 0.07 0.42" rgb2="0.22 0.38 0.12" type="2d" width="512"/>
		<material name="Paint" shininess="0.31" specular="0.28" texture="wall_geom"/>
		<material name="Wood" shininess="0.09" specular="0.16" texture="frame_geom"/>
		<material name="Carpet" shininess="0.03" specular="0.01" texture="door_geom"/>
		<material name="Metal" shininess="0.96" specular="0.89" texture="knob_geom"/>
		<material name="Floor" texture="texplane"/>
	</asset>
	<contact>
		<pair geom1="knob_latch" geom2="door_frame_0" solref="0.01 1"/>
		<pair geom1="knob_latch" geom2="door_frame_1" solref="0.01 1"/>
		<pair geom1="knob_latch" geom2="door_frame_2" solref="0.01 1"/>
		<pair geom1="knob_latch" geom2="door_frame_3" solref="0.01 1"/>
	</contact>
	<default>
		<joint armature="1" damping="1" limited="true"/>
		<default class="wall">
			<geom rgba="0.18 0.73 0.27 1.0" type="mesh"/>
		</default>
		<default class="frame">
			<geom rgba="0.78 0.76 0.77 1.0" type="mesh"/>
		</default>
		<default class="door">
			<geom rgba="0.95 0.59 0.3 1.0" type="mesh"/>
		</default>
		<default class="door_knob">
			<geom condim="4" rgba="0.74 0.16 0.79 1.0" type="mesh"/>
		</default>
		<default class="robot">
			<joint damping="0.09"/>
		</default>
	</default>
	<worldbody>
		<light diffuse="1.0 0.9 1.0" dir="0.08 -0.44 -0.34" directional="true" pos="2.91 -3.16 6.35"/>
		<light diffuse="1.0 1.0 0.9" dir="-0.26 0.29 -0.39" directional="true" pos="3.53 -0.96 4.15"/>
		<light diffuse="0.9 1.0 0.9" dir="0.04 -0.24 -0.45" directional="true" pos="3.61 -0.64 6.47"/>
		<geom material="Floor" name="floor" pos="0 0 -0.05" size="15.0 15.0 0.05" type="plane"/>
		<camera fovy="60" mode="fixed" name="camera1" pos="0.99 -0.5 1.0" euler="0.0 1.57 1.57"/>
		<camera fovy="60" mode="fixed" name="camera2" pos="0.5 0.0 1.99" euler="0 0 0"/>
		<body childclass="wall" name="wall_link" pos="0.0 -0.007 0.0">
			<inertial mass="100" pos="0 0 0" diaginertia="0.0001 0.0001 0.0001"/>
			<geom material="Paint" name="wall_0" pos="-0.15 -1.5919999999999999 1.252" size="0.15 1.0 1.252" type="box" euler="0 0 0"/>
			<geom material="Paint" name="wall_1" pos="-0.15 1.6219999999999999 1.252" size="0.15 1.0 1.252" type="box" euler="0 0 0"/>
			<geom material="Paint" name="wall_2" pos="-0.15 0 3.004" size="0.15 2.622 0.5" type="box" euler="0 0 0"/>
			<body childclass="frame" name="frame_link" pos="0 -0.32364 1.041">
				<inertial mass="500" pos="0 0 0" diaginertia="0.0001 0.0001 0.0001"/>
				<geom material="Paint" name="door_frame_0" pos="0 -0.25836000000000003 0.21100000000000008" size="0.0105 0.05 1.252" type="box" euler="0 0 0"/>
				<geom material="Paint" name="door_frame_1" pos="0 0.9056400000000001 0.21100000000000008" size="0.0105 0.05 1.252" type="box" euler="0 0 0"/>
				<geom material="Paint" name="door_frame_2" pos="0 0.32364000000000004 1.413" size="0.0105 0.622 0.05" type="box" euler="0 0 0"/>
				<geom material="Paint" name="door_frame_3" pos="-0.0405 -0.25836000000000003 0.21100000000000008" size="0.0105 0.05 1.252" type="box" euler="0 0 0"/>
				<geom material="Paint" name="door_frame_4" pos="-0.0405 0.9056400000000001 0.21100000000000008" size="0.0105 0.05 1.252" type="box" euler="0 0 0"/>
				<geom material="Paint" name="door_frame_5" pos="-0.0405 0.32364000000000004 1.413" size="0.0105 0.622 0.05" type="box" euler="0 0 0"/>
				<body childclass="door" name="door_link" pos="0 0 0">
					<joint armature="0.0001" axis="0 0 1" damping="1.0" frictionloss="0" limited="true" name="hinge0" pos="0 0.8456400000000001 0" range="-0.0 1.57" stiffness="0.17" type="hinge"/>
					<geom material="Carpet" name="door0" pos="0 0.32364000000000004 0.16100000000000003" size="0.0105 0.522 1.18998" type="box" euler="0 0 0"/>
					<inertial mass="50.59708416000001" pos="0 0.32364000000000004 0.16100000000000003" diaginertia="28.963255154319366 24.369482637077766 4.597491402927361"/>
					<body childclass="door_knob" name="knob_link" pos="0 0 0">
						<inertial mass="1" pos="0 0 0" diaginertia="0.001 0.001 0.001"/>
						<joint armature="0" axis="0 1 0" damping="30000" frictionloss="0" limited="true" name="target0" range="-0.2 0.3" stiffness="0" type="slide"/>
						<joint armature="0" axis="0 0 1" damping="30000" frictionloss="0" limited="true" name="target1" range="-0.5 0.5" stiffness="0" type="slide"/>
						<joint armature="0.0001" axis="1 0 0" damping="1.37" frictionloss="0" limited="true" name="hinge1" pos="0 0 0" range="-1.325777777777778 1.325777777777778" stiffness="1.04" type="hinge"/>
						<body childclass="door_knob" name="roundknob_link" pos="0.0105 0 0">
							<geom friction="0.81 0.003 0.003" material="Carpet" mesh="door_knob_1" name="door_knob_1" euler="-1.57 1.57 0"/>
							<geom friction="0.81 0.003 0.003" material="Carpet" mesh="door_knob_2" name="door_knob_2" euler="-1.57 1.57 0"/>
							<geom material="Wood" name="knob_latch" pos="-0.03075 0 0" size="0.0075 0.23169333333333333 0.05" type="box" euler="0 0 0"/>
							<inertial mass="1" pos="-0.05385000000000001 0 0" diaginertia="0.004681816725925925 0.00022708333333333337 0.004492233392592592"/>
						</body>
					</body>
				</body>
			</body>
		</body>
	</worldbody>
</mujoco>