<?xml version="1.0" encoding="utf-8"?>
<mujoco model="door_knob">
	<compiler angle="radian"/>
	<include file="../../robot/blue_right_v2_position.xml"/>
	<option gravity="0 0 -9.81" timestep="0.001"/>
	<visual>
		<map fogend="5" fogstart="3" force="0.1" zfar="10" znear="0.01"/>
		<quality shadowsize="2048"/>
		<global offheight="256" offwidth="256"/>
	</visual>
	<asset>
		<mesh file="../../door/roundknobs/1558288447/body_1.stl" name="door_knob_1" scale="0.001 0.001 0.001"/>
		<mesh file="../../door/roundknobs/1558288447/body_2.stl" name="door_knob_2" scale="0.001 0.001 0.001"/>
		<texture builtin="flat" height="32" name="wall_geom" type="2d" width="32"/>
		<texture builtin="flat" height="32" name="frame_geom" type="2d" width="32"/>
		<texture builtin="flat" height="32" name="door_geom" type="2d" width="32"/>
		<texture builtin="flat" height="32" name="knob_geom" type="2d" width="32"/>
		<texture builtin="gradient" height="128" rgb1="0.4 0.6 0.8" rgb2="0 0 0" type="skybox" width="128"/>
		<texture builtin="gradient" height="512" name="texplane" rgb1="0.35 0.39 0.05" rgb2="0.37 0.32 0.09" type="2d" width="512"/>
		<material name="Paint" shininess="0.46" specular="0.14" texture="wall_geom"/>
		<material name="Wood" shininess="0.18" specular="0.11" texture="frame_geom"/>
		<material name="Carpet" shininess="0.02" specular="0.01" texture="door_geom"/>
		<material name="Metal" shininess="0.85" specular="0.97" texture="knob_geom"/>
		<material name="Floor" texture="texplane"/>
	</asset>
	<contact>
		<pair geom1="knob_latch" geom2="door_frame_0" solref="0.01 1"/>
		<pair geom1="knob_latch" geom2="door_frame_1" solref="0.01 1"/>
		<pair geom1="knob_latch" geom2="door_frame_2" solref="0.01 1"/>
		<pair geom1="knob_latch" geom2="door_frame_3" solref="0.01 1"/>
	</contact>
	<default>
		<joint armature="1" damping="1" limited="true"/>
		<default class="wall">
			<geom rgba="0.34 0.74 0.45 1.0" type="mesh"/>
		</default>
		<default class="frame">
			<geom rgba="0.75 0.72 0.83 1.0" type="mesh"/>
		</default>
		<default class="door">
			<geom rgba="0.23 0.02 0.4 1.0" type="mesh"/>
		</default>
		<default class="door_knob">
			<geom condim="4" rgba="0.29 0.66 0.73 1.0" type="mesh"/>
		</default>
		<default class="robot">
			<joint damping="0.09"/>
		</default>
	</default>
	<worldbody>
		<light diffuse="1.0 1.0 0.9" dir="-0.49 0.08 -0.5" directional="true" pos="0.39 -3.83 5.79"/>
		<light diffuse="1.0 0.9 0.9" dir="-0.34 0.33 -0.43" directional="true" pos="4.88 2.5 6.59"/>
		<light diffuse="0.9 1.0 1.0" dir="0.14 0.21 -0.46" directional="true" pos="4.63 4.92 4.96"/>
		<geom material="Floor" name="floor" pos="0 0 -0.05" size="15.0 15.0 0.05" type="plane"/>
		<camera fovy="60" mode="fixed" name="camera1" pos="0.99 -0.5 1.0" euler="0.0 1.57 1.57"/>
		<camera fovy="60" mode="fixed" name="camera2" pos="0.5 0.0 1.99" euler="0 0 0"/>
		<body childclass="wall" name="wall_link" pos="0.0 -0.078 0.0">
			<inertial mass="100" pos="0 0 0" diaginertia="0.0001 0.0001 0.0001"/>
			<geom material="Carpet" name="wall_0" pos="-0.15 -1.5995 1.2675" size="0.15 1.0 1.2675" type="box" euler="0 0 0"/>
			<geom material="Carpet" name="wall_1" pos="-0.15 1.6295 1.2675" size="0.15 1.0 1.2675" type="box" euler="0 0 0"/>
			<geom material="Carpet" name="wall_2" pos="-0.15 0 3.035" size="0.15 2.6295 0.5" type="box" euler="0 0 0"/>
			<body childclass="frame" name="frame_link" pos="0 -0.38123999999999997 0.938">
				<inertial mass="500" pos="0 0 0" diaginertia="0.0001 0.0001 0.0001"/>
				<geom material="Paint" name="door_frame_0" pos="0 -0.20826 0.3295000000000001" size="0.01 0.05 1.2675" type="box" euler="0 0 0"/>
				<geom material="Paint" name="door_frame_1" pos="0 0.9707399999999999 0.3295000000000001" size="0.01 0.05 1.2675" type="box" euler="0 0 0"/>
				<geom material="Paint" name="door_frame_2" pos="0 0.38123999999999997 1.5470000000000002" size="0.01 0.6295 0.05" type="box" euler="0 0 0"/>
				<geom material="Paint" name="door_frame_3" pos="-0.0395 -0.20826 0.3295000000000001" size="0.01 0.05 1.2675" type="box" euler="0 0 0"/>
				<geom material="Paint" name="door_frame_4" pos="-0.0395 0.9707399999999999 0.3295000000000001" size="0.01 0.05 1.2675" type="box" euler="0 0 0"/>
				<geom material="Paint" name="door_frame_5" pos="-0.0395 0.38123999999999997 1.5470000000000002" size="0.01 0.6295 0.05" type="box" euler="0 0 0"/>
				<body childclass="door" name="door_link" pos="0 0 0">
					<joint armature="0.0001" axis="0 0 1" damping="1.8" frictionloss="0" limited="true" name="hinge0" pos="0 0.9107399999999999 0" range="-0.0 1.57" stiffness="0.15" type="hinge"/>
					<geom material="Paint" name="door0" pos="0 0.38123999999999997 0.2795000000000001" size="0.01 0.5295 1.205325" type="box" euler="0 0 0"/>
					<inertial mass="50.4386874" pos="0 0.38123999999999997 0.2795000000000001" diaginertia="29.635696323608702 24.923541814518753 4.71551708824995"/>
					<body childclass="door_knob" name="knob_link" pos="0 0 0">
						<inertial mass="1" pos="0 0 0" diaginertia="0.001 0.001 0.001"/>
						<joint armature="0" axis="0 1 0" damping="30000" frictionloss="0" limited="true" name="target0" range="-0.2 0.3" stiffness="0" type="slide"/>
						<joint armature="0" axis="0 0 1" damping="30000" frictionloss="0" limited="true" name="target1" range="-0.5 0.5" stiffness="0" type="slide"/>
						<joint armature="0.0001" axis="1 0 0" damping="1.77" frictionloss="0" limited="true" name="hinge1" pos="0 0 0" range="-1.3606666666666667 1.3606666666666667" stiffness="1.26" type="hinge"/>
						<body childclass="door_knob" name="roundknob_link" pos="0.01 0 0">
							<geom friction="0.53 0.001 0.003" material="Wood" mesh="door_knob_1" name="door_knob_1" euler="-1.57 1.57 0"/>
							<geom friction="0.53 0.001 0.003" material="Wood" mesh="door_knob_2" name="door_knob_2" euler="-1.57 1.57 0"/>
							<geom material="Wood" name="knob_latch" pos="-0.02975 0 0" size="0.0075 0.18159333333333333 0.05" type="box" euler="0 0 0"/>
							<inertial mass="1" pos="-0.051750000000000004 0 0" diaginertia="0.0029563448925925924 0.00022708333333333337 0.002766761559259259"/>
						</body>
					</body>
				</body>
			</body>
		</body>
	</worldbody>
</mujoco>