<?xml version="1.0" encoding="utf-8"?>
<mujoco model="door_knob">
	<compiler angle="radian"/>
	<include file="../../robot/blue_right_v2_position.xml"/>
	<option gravity="0 0 -9.81" timestep="0.001"/>
	<visual>
		<map fogend="5" fogstart="3" force="0.1" zfar="10" znear="0.01"/>
		<quality shadowsize="2048"/>
		<global offheight="256" offwidth="256"/>
	</visual>
	<asset>
		<mesh file="../../door/roundknobs/1558288438/body_1.stl" name="door_knob_1" scale="0.001 0.001 0.001"/>
		<mesh file="../../door/roundknobs/1558288438/body_2.stl" name="door_knob_2" scale="0.001 0.001 0.001"/>
		<texture builtin="flat" height="32" name="wall_geom" type="2d" width="32"/>
		<texture builtin="flat" height="32" name="frame_geom" type="2d" width="32"/>
		<texture builtin="flat" height="32" name="door_geom" type="2d" width="32"/>
		<texture builtin="flat" height="32" name="knob_geom" type="2d" width="32"/>
		<texture builtin="gradient" height="128" rgb1="0.4 0.6 0.8" rgb2="0 0 0" type="skybox" width="128"/>
		<texture builtin="gradient" height="512" name="texplane" rgb1="0.15 0.28 0.08" rgb2="0.3 0.13 0.15" type="2d" width="512"/>
		<material name="Paint" shininess="0.03" specular="0.29" texture="wall_geom"/>
		<material name="Wood" shininess="0.16" specular="0.16" texture="frame_geom"/>
		<material name="Carpet" shininess="0.02" specular="0.02" texture="door_geom"/>
		<material name="Metal" shininess="0.9" specular="0.9" texture="knob_geom"/>
		<material name="Floor" texture="texplane"/>
	</asset>
	<contact>
		<pair geom1="knob_latch" geom2="door_frame_0" solref="0.01 1"/>
		<pair geom1="knob_latch" geom2="door_frame_1" solref="0.01 1"/>
		<pair geom1="knob_latch" geom2="door_frame_2" solref="0.01 1"/>
		<pair geom1="knob_latch" geom2="door_frame_3" solref="0.01 1"/>
	</contact>
	<default>
		<joint armature="1" damping="1" limited="true"/>
		<default class="wall">
			<geom rgba="0.3 0.6 0.81 1.0" type="mesh"/>
		</default>
		<default class="frame">
			<geom rgba="0.75 0.73 0.79 1.0" type="mesh"/>
		</default>
		<default class="door">
			<geom rgba="0.25 0.23 0.51 1.0" type="mesh"/>
		</default>
		<default class="door_knob">
			<geom condim="4" rgba="0.85 0.62 0.16 1.0" type="mesh"/>
		</default>
		<default class="robot">
			<joint damping="0.1"/>
		</default>
	</default>
	<worldbody>
		<light diffuse="0.9 1.0 0.9" dir="-0.31 -0.48 -0.27" directional="true" pos="4.21 -2.72 3.55"/>
		<light diffuse="1.0 0.9 0.9" dir="0.39 -0.14 -0.48" directional="true" pos="1.83 -2.8 4.95"/>
		<light diffuse="0.9 1.0 0.9" dir="-0.15 -0.17 -0.35" directional="true" pos="2.3 1.89 6.96"/>
		<light diffuse="0.9 1.0 1.0" dir="-0.28 0.34 -0.35" directional="true" pos="0.77 2.77 5.07"/>
		<geom material="Floor" name="floor" pos="0 0 -0.05" size="15.0 15.0 0.05" type="plane"/>
		<camera fovy="60" mode="fixed" name="camera1" pos="0.99 -0.5 1.0" euler="0.0 1.57 1.57"/>
		<camera fovy="60" mode="fixed" name="camera2" pos="0.5 0.0 1.99" euler="0 0 0"/>
		<body childclass="wall" name="wall_link" pos="0.0 0.063 0.0">
			<inertial mass="100" pos="0 0 0" diaginertia="0.0001 0.0001 0.0001"/>
			<geom material="Carpet" name="wall_0" pos="-0.15 -1.5935 1.2645" size="0.15 1.0 1.2645" type="box" euler="0 0 0"/>
			<geom material="Carpet" name="wall_1" pos="-0.15 1.6235 1.2645" size="0.15 1.0 1.2645" type="box" euler="0 0 0"/>
			<geom material="Carpet" name="wall_2" pos="-0.15 0 3.029" size="0.15 2.6235 0.5" type="box" euler="0 0 0"/>
			<body childclass="frame" name="frame_link" pos="0 -0.4188 1.01">
				<inertial mass="500" pos="0 0 0" diaginertia="0.0001 0.0001 0.0001"/>
				<geom material="Paint" name="door_frame_0" pos="0 -0.1647 0.25449999999999995" size="0.012 0.05 1.2645" type="box" euler="0 0 0"/>
				<geom material="Paint" name="door_frame_1" pos="0 1.0023 0.25449999999999995" size="0.012 0.05 1.2645" type="box" euler="0 0 0"/>
				<geom material="Paint" name="door_frame_2" pos="0 0.41879999999999995 1.4689999999999999" size="0.012 0.6234999999999999 0.05" type="box" euler="0 0 0"/>
				<geom material="Paint" name="door_frame_3" pos="-0.0435 -0.1647 0.25449999999999995" size="0.012 0.05 1.2645" type="box" euler="0 0 0"/>
				<geom material="Paint" name="door_frame_4" pos="-0.0435 1.0023 0.25449999999999995" size="0.012 0.05 1.2645" type="box" euler="0 0 0"/>
				<geom material="Paint" name="door_frame_5" pos="-0.0435 0.41879999999999995 1.4689999999999999" size="0.012 0.6234999999999999 0.05" type="box" euler="0 0 0"/>
				<body childclass="door" name="door_link" pos="0 0 0">
					<joint armature="0.0001" axis="0 0 1" damping="1.7" frictionloss="0" limited="true" name="hinge0" pos="0 0.9422999999999999 0" range="-0.0 1.57" stiffness="0.13" type="hinge"/>
					<geom material="Carpet" name="door0" pos="0 0.41879999999999995 0.2044999999999999" size="0.012 0.5235 1.2023549999999998" type="box" euler="0 0 0"/>
					<inertial mass="60.852804264" pos="0 0.41879999999999995 0.2044999999999999" diaginertia="35.4784526526675 29.92242427815257 5.561870243724269"/>
					<body childclass="door_knob" name="knob_link" pos="0 0 0">
						<inertial mass="1" pos="0 0 0" diaginertia="0.001 0.001 0.001"/>
						<joint armature="0" axis="0 1 0" damping="30000" frictionloss="0" limited="true" name="target0" range="-0.2 0.3" stiffness="0" type="slide"/>
						<joint armature="0" axis="0 0 1" damping="30000" frictionloss="0" limited="true" name="target1" range="-0.5 0.5" stiffness="0" type="slide"/>
						<joint armature="0.0001" axis="1 0 0" damping="1.9" frictionloss="0" limited="true" name="hinge1" pos="0 0 0" range="-1.3432222222222223 1.3432222222222223" stiffness="1.46" type="hinge"/>
						<body childclass="door_knob" name="roundknob_link" pos="0.012 0 0">
							<geom friction="0.98 0.004 0.004" material="Carpet" mesh="door_knob_1" name="door_knob_1" euler="-1.57 1.57 0"/>
							<geom friction="0.98 0.004 0.004" material="Carpet" mesh="door_knob_2" name="door_knob_2" euler="-1.57 1.57 0"/>
							<geom material="Paint" name="knob_latch" pos="-0.03375 0 0" size="0.0075 0.13803333333333334 0.05" type="box" euler="0 0 0"/>
							<inertial mass="1" pos="-0.06015 0 0" diaginertia="0.0017961000925925928 0.00022708333333333337 0.0016065167592592593"/>
						</body>
					</body>
				</body>
			</body>
		</body>
	</worldbody>
</mujoco>