<?xml version="1.0" encoding="utf-8"?>
<mujoco model="door_knob">
	<compiler angle="radian"/>
	<include file="../../robot/blue_right_v2_position.xml"/>
	<option gravity="0 0 -9.81" timestep="0.001"/>
	<visual>
		<map fogend="5" fogstart="3" force="0.1" zfar="10" znear="0.01"/>
		<quality shadowsize="2048"/>
		<global offheight="256" offwidth="256"/>
	</visual>
	<asset>
		<mesh file="../../door/roundknobs/1558288450/body_1.stl" name="door_knob_1" scale="0.001 0.001 0.001"/>
		<mesh file="../../door/roundknobs/1558288450/body_2.stl" name="door_knob_2" scale="0.001 0.001 0.001"/>
		<texture builtin="flat" height="32" name="wall_geom" type="2d" width="32"/>
		<texture builtin="flat" height="32" name="frame_geom" type="2d" width="32"/>
		<texture builtin="flat" height="32" name="door_geom" type="2d" width="32"/>
		<texture builtin="flat" height="32" name="knob_geom" type="2d" width="32"/>
		<texture builtin="gradient" height="128" rgb1="0.4 0.6 0.8" rgb2="0 0 0" type="skybox" width="128"/>
		<texture builtin="gradient" height="512" name="texplane" rgb1="0.32 0.08 0.19" rgb2="0.47 0.34 0.39" type="2d" width="512"/>
		<material name="Paint" shininess="0.4" specular="0.24" texture="wall_geom"/>
		<material name="Wood" shininess="0.19" specular="0.14" texture="frame_geom"/>
		<material name="Carpet" shininess="0.03" specular="0.04" texture="door_geom"/>
		<material name="Metal" shininess="0.99" specular="0.92" texture="knob_geom"/>
		<material name="Floor" texture="texplane"/>
	</asset>
	<contact>
		<pair geom1="knob_latch" geom2="door_frame_0" solref="0.01 1"/>
		<pair geom1="knob_latch" geom2="door_frame_1" solref="0.01 1"/>
		<pair geom1="knob_latch" geom2="door_frame_2" solref="0.01 1"/>
		<pair geom1="knob_latch" geom2="door_frame_3" solref="0.01 1"/>
	</contact>
	<default>
		<joint armature="1" damping="1" limited="true"/>
		<default class="wall">
			<geom rgba="0.82 0.76 0.26 1.0" type="mesh"/>
		</default>
		<default class="frame">
			<geom rgba="0.84 0.76 0.83 1.0" type="mesh"/>
		</default>
		<default class="door">
			<geom rgba="0.36 0.62 0.75 1.0" type="mesh"/>
		</default>
		<default class="door_knob">
			<geom condim="4" rgba="0.56 0.45 0.59 1.0" type="mesh"/>
		</default>
		<default class="robot">
			<joint damping="0.1"/>
		</default>
	</default>
	<worldbody>
		<light diffuse="1.0 1.0 0.9" dir="0.35 0.19 -0.5" directional="true" pos="0.58 4.65 5.91"/>
		<light diffuse="0.9 0.9 0.9" dir="-0.05 0.15 -0.43" directional="true" pos="2.17 2.77 4.88"/>
		<light diffuse="1.0 0.9 1.0" dir="-0.31 0.45 -0.29" directional="true" pos="0.99 -0.45 4.74"/>
		<light diffuse="1.0 0.9 0.9" dir="0.42 0.36 -0.27" directional="true" pos="2.47 3.58 3.6"/>
		<geom material="Floor" name="floor" pos="0 0 -0.05" size="15.0 15.0 0.05" type="plane"/>
		<camera fovy="60" mode="fixed" name="camera1" pos="0.99 -0.5 1.0" euler="0.0 1.57 1.57"/>
		<camera fovy="60" mode="fixed" name="camera2" pos="0.5 0.0 1.99" euler="0 0 0"/>
		<body childclass="wall" name="wall_link" pos="0.0 0.058 0.0">
			<inertial mass="100" pos="0 0 0" diaginertia="0.0001 0.0001 0.0001"/>
			<geom material="Paint" name="wall_0" pos="-0.15 -1.468 1.1275" size="0.15 1.0 1.1275" type="box" euler="0 0 0"/>
			<geom material="Paint" name="wall_1" pos="-0.15 1.498 1.1275" size="0.15 1.0 1.1275" type="box" euler="0 0 0"/>
			<geom material="Paint" name="wall_2" pos="-0.15 0 2.755" size="0.15 2.498 0.5" type="box" euler="0 0 0"/>
			<body childclass="frame" name="frame_link" pos="0 -0.24676 1.083">
				<inertial mass="500" pos="0 0 0" diaginertia="0.0001 0.0001 0.0001"/>
				<geom material="Paint" name="door_frame_0" pos="0 -0.21124000000000004 0.044499999999999984" size="0.0105 0.05 1.1275" type="box" euler="0 0 0"/>
				<geom material="Paint" name="door_frame_1" pos="0 0.70476 0.044499999999999984" size="0.0105 0.05 1.1275" type="box" euler="0 0 0"/>
				<geom material="Paint" name="door_frame_2" pos="0 0.24676 1.1219999999999999" size="0.0105 0.498 0.05" type="box" euler="0 0 0"/>
				<geom material="Paint" name="door_frame_3" pos="-0.0405 -0.21124000000000004 0.044499999999999984" size="0.0105 0.05 1.1275" type="box" euler="0 0 0"/>
				<geom material="Paint" name="door_frame_4" pos="-0.0405 0.70476 0.044499999999999984" size="0.0105 0.05 1.1275" type="box" euler="0 0 0"/>
				<geom material="Paint" name="door_frame_5" pos="-0.0405 0.24676 1.1219999999999999" size="0.0105 0.498 0.05" type="box" euler="0 0 0"/>
				<body childclass="door" name="door_link" pos="0 0 0">
					<joint armature="0.0001" axis="0 0 1" damping="1.7" frictionloss="0" limited="true" name="hinge0" pos="0 0.64476 0" range="-0.0 1.57" stiffness="0.16" type="hinge"/>
					<geom material="Carpet" name="door0" pos="0 0.24676 -0.00550000000000006" size="0.0105 0.398 1.066725" type="box" euler="0 0 0"/>
					<inertial mass="33.141141600000005" pos="0 0.24676 -0.00550000000000006" diaginertia="14.5755873079138 12.826908780198801 1.7511144016226006"/>
					<body childclass="door_knob" name="knob_link" pos="0 0 0">
						<inertial mass="1" pos="0 0 0" diaginertia="0.001 0.001 0.001"/>
						<joint armature="0" axis="0 1 0" damping="30000" frictionloss="0" limited="true" name="target0" range="-0.2 0.3" stiffness="0" type="slide"/>
						<joint armature="0" axis="0 0 1" damping="30000" frictionloss="0" limited="true" name="target1" range="-0.5 0.5" stiffness="0" type="slide"/>
						<joint armature="0.0001" axis="1 0 0" damping="1.92" frictionloss="0" limited="true" name="hinge1" pos="0 0 0" range="-1.3432222222222223 1.3432222222222223" stiffness="1.12" type="hinge"/>
						<body childclass="door_knob" name="roundknob_link" pos="0.0105 0 0">
							<geom friction="0.9 0.002 0.002" material="Carpet" mesh="door_knob_1" name="door_knob_1" euler="-1.57 1.57 0"/>
							<geom friction="0.9 0.002 0.002" material="Carpet" mesh="door_knob_2" name="door_knob_2" euler="-1.57 1.57 0"/>
							<geom material="Carpet" name="knob_latch" pos="-0.03075 0 0" size="0.0075 0.18457333333333334 0.05" type="box" euler="0 0 0"/>
							<inertial mass="1" pos="-0.05385000000000001 0 0" diaginertia="0.003047276281481482 0.00022708333333333337 0.0028576929481481488"/>
						</body>
					</body>
				</body>
			</body>
		</body>
	</worldbody>
</mujoco>