<?xml version="1.0" encoding="utf-8"?>
<mujoco model="door_knob">
	<compiler angle="radian"/>
	<include file="../../robot/blue_right_v2_position.xml"/>
	<option gravity="0 0 -9.81" timestep="0.001"/>
	<visual>
		<map fogend="5" fogstart="3" force="0.1" zfar="10" znear="0.01"/>
		<quality shadowsize="2048"/>
		<global offheight="256" offwidth="256"/>
	</visual>
	<asset>
		<mesh file="../../door/roundknobs/1558288445/body_1.stl" name="door_knob_1" scale="0.001 0.001 0.001"/>
		<mesh file="../../door/roundknobs/1558288445/body_2.stl" name="door_knob_2" scale="0.001 0.001 0.001"/>
		<texture builtin="flat" height="32" name="wall_geom" type="2d" width="32"/>
		<texture builtin="flat" height="32" name="frame_geom" type="2d" width="32"/>
		<texture builtin="flat" height="32" name="door_geom" type="2d" width="32"/>
		<texture builtin="flat" height="32" name="knob_geom" type="2d" width="32"/>
		<texture builtin="gradient" height="128" rgb1="0.4 0.6 0.8" rgb2="0 0 0" type="skybox" width="128"/>
		<texture builtin="gradient" height="512" name="texplane" rgb1="0.43 0.06 0.49" rgb2="0.47 0.31 0.19" type="2d" width="512"/>
		<material name="Paint" shininess="0.33" specular="0.11" texture="wall_geom"/>
		<material name="Wood" shininess="0.04" specular="0.05" texture="frame_geom"/>
		<material name="Carpet" shininess="0.03" specular="0.01" texture="door_geom"/>
		<material name="Metal" shininess="0.99" specular="0.89" texture="knob_geom"/>
		<material name="Floor" texture="texplane"/>
	</asset>
	<contact>
		<pair geom1="knob_latch" geom2="door_frame_0" solref="0.01 1"/>
		<pair geom1="knob_latch" geom2="door_frame_1" solref="0.01 1"/>
		<pair geom1="knob_latch" geom2="door_frame_2" solref="0.01 1"/>
		<pair geom1="knob_latch" geom2="door_frame_3" solref="0.01 1"/>
	</contact>
	<default>
		<joint armature="1" damping="1" limited="true"/>
		<default class="wall">
			<geom rgba="0.6 0.15 0.16 1.0" type="mesh"/>
		</default>
		<default class="frame">
			<geom rgba="0.72 0.72 0.71 1.0" type="mesh"/>
		</default>
		<default class="door">
			<geom rgba="0.87 0.71 0.03 1.0" type="mesh"/>
		</default>
		<default class="door_knob">
			<geom condim="4" rgba="0.15 0.46 0.76 1.0" type="mesh"/>
		</default>
		<default class="robot">
			<joint damping="0.09"/>
		</default>
	</default>
	<worldbody>
		<light diffuse="0.9 1.0 0.9" dir="0.2 -0.17 -0.32" directional="true" pos="4.1 -3.95 3.94"/>
		<light diffuse="0.9 0.9 1.0" dir="0.02 0.06 -0.45" directional="true" pos="4.7 2.83 6.58"/>
		<light diffuse="1.0 1.0 0.9" dir="0.12 -0.3 -0.32" directional="true" pos="0.67 1.77 6.37"/>
		<light diffuse="1.0 0.9 0.9" dir="-0.48 0.15 -0.45" directional="true" pos="1.19 2.95 5.48"/>
		<geom material="Floor" name="floor" pos="0 0 -0.05" size="15.0 15.0 0.05" type="plane"/>
		<camera fovy="60" mode="fixed" name="camera1" pos="0.99 -0.5 1.0" euler="0.0 1.57 1.57"/>
		<camera fovy="60" mode="fixed" name="camera2" pos="0.5 0.0 1.99" euler="0 0 0"/>
		<body childclass="wall" name="wall_link" pos="0.0 -0.093 0.0">
			<inertial mass="100" pos="0 0 0" diaginertia="0.0001 0.0001 0.0001"/>
			<geom material="Carpet" name="wall_0" pos="-0.15 -1.5315 1.201" size="0.15 1.0 1.201" type="box" euler="0 0 0"/>
			<geom material="Carpet" name="wall_1" pos="-0.15 1.5615 1.201" size="0.15 1.0 1.201" type="box" euler="0 0 0"/>
			<geom material="Carpet" name="wall_2" pos="-0.15 0 2.902" size="0.15 2.5615 0.5" type="box" euler="0 0 0"/>
			<body childclass="frame" name="frame_link" pos="0 -0.35997 1.091">
				<inertial mass="500" pos="0 0 0" diaginertia="0.0001 0.0001 0.0001"/>
				<geom material="Carpet" name="door_frame_0" pos="0 -0.16153 0.1100000000000001" size="0.0125 0.05 1.201" type="box" euler="0 0 0"/>
				<geom material="Carpet" name="door_frame_1" pos="0 0.8814700000000001 0.1100000000000001" size="0.0125 0.05 1.201" type="box" euler="0 0 0"/>
				<geom material="Carpet" name="door_frame_2" pos="0 0.35997 1.2610000000000001" size="0.0125 0.5615 0.05" type="box" euler="0 0 0"/>
				<geom material="Carpet" name="door_frame_3" pos="-0.0445 -0.16153 0.1100000000000001" size="0.0125 0.05 1.201" type="box" euler="0 0 0"/>
				<geom material="Carpet" name="door_frame_4" pos="-0.0445 0.8814700000000001 0.1100000000000001" size="0.0125 0.05 1.201" type="box" euler="0 0 0"/>
				<geom material="Carpet" name="door_frame_5" pos="-0.0445 0.35997 1.2610000000000001" size="0.0125 0.5615 0.05" type="box" euler="0 0 0"/>
				<body childclass="door" name="door_link" pos="0 0 0">
					<joint armature="0.0001" axis="0 0 1" damping="1.7" frictionloss="0" limited="true" name="hinge0" pos="0 0.82147 0" range="-0.0 1.57" stiffness="0.1" type="hinge"/>
					<geom material="Paint" name="door0" pos="0 0.35997 0.06000000000000005" size="0.0125 0.4615 1.1394900000000001" type="box" euler="0 0 0"/>
					<inertial mass="48.869158000000006" pos="0 0.35997 0.06000000000000005" diaginertia="25.05005753800117 21.583181731165173 3.471966344127667"/>
					<body childclass="door_knob" name="knob_link" pos="0 0 0">
						<inertial mass="1" pos="0 0 0" diaginertia="0.001 0.001 0.001"/>
						<joint armature="0" axis="0 1 0" damping="30000" frictionloss="0" limited="true" name="target0" range="-0.2 0.3" stiffness="0" type="slide"/>
						<joint armature="0" axis="0 0 1" damping="30000" frictionloss="0" limited="true" name="target1" range="-0.5 0.5" stiffness="0" type="slide"/>
						<joint armature="0.0001" axis="1 0 0" damping="1.81" frictionloss="0" limited="true" name="hinge1" pos="0 0 0" range="-1.3083333333333333 1.3083333333333333" stiffness="1.13" type="hinge"/>
						<body childclass="door_knob" name="roundknob_link" pos="0.0125 0 0">
							<geom friction="0.52 0.001 0.003" material="Carpet" mesh="door_knob_1" name="door_knob_1" euler="-1.57 1.57 0"/>
							<geom friction="0.52 0.001 0.003" material="Carpet" mesh="door_knob_2" name="door_knob_2" euler="-1.57 1.57 0"/>
							<geom material="Paint" name="knob_latch" pos="-0.03475 0 0" size="0.0075 0.13486333333333334 0.05" type="box" euler="0 0 0"/>
							<inertial mass="1" pos="-0.06225000000000001 0 0" diaginertia="0.0017240098898148146 0.00022708333333333337 0.0015344265564814813"/>
						</body>
					</body>
				</body>
			</body>
		</body>
	</worldbody>
</mujoco>