<mujoco model="doorenv">
	<compiler angle="radian" inertiafromgeom="true"/>
    <asset> 
        <mesh name="wrist_roll_link" file="robotSTL/hand_base_link.STL" />
        <mesh name="hook_0" file="robotSTL/hook_0.STL" scale="0.001 0.001 0.001"/>
        <mesh name="hook_1" file="robotSTL/hook_1.STL" scale="0.001 0.001 0.001"/>
        <mesh name="hook_2" file="robotSTL/hook_2.STL" scale="0.001 0.001 0.001"/>
        <mesh name="hook_3" file="robotSTL/hook_3.STL" scale="0.001 0.001 0.001"/>
        <mesh file="knobSTL/body_1.stl" name="door_knob_1" scale="0.001 0.001 0.001"/>
		<mesh file="knobSTL/body_2.stl" name="door_knob_2" scale="0.001 0.001 0.001"/>
		<mesh file="knobSTL/body_3.stl" name="door_knob_3" scale="0.001 0.001 0.001"/>
		<mesh file="knobSTL/body_4.stl" name="door_knob_4" scale="0.001 0.001 0.001"/>
		<mesh file="knobSTL/body_5.stl" name="door_knob_5" scale="0.001 0.001 0.001"/>
		<mesh file="knobSTL/body_6.stl" name="door_knob_6" scale="0.001 0.001 0.001"/>
		<mesh file="knobSTL/body_7.stl" name="door_knob_7" scale="0.001 0.001 0.001"/>
		<mesh file="knobSTL/body_8.stl" name="door_knob_8" scale="0.001 0.001 0.001"/>
    </asset>
	<default>
		<joint armature="1" damping="1" limited="true"/>
		<geom contype="3" friction="1.0 0.1 0.1" rgba="0.7 0.7 0 1"/>
        <default class="wall">
            <geom rgba="0.12 0.51 0.09 1.0" type="mesh"/>
        </default>
        <default class="frame">
            <geom rgba="0.7 0.8 0.73 1.0" type="mesh"/>
        </default>
        <default class="door">
            <geom rgba="0.9 0.8 0.9 1.0" type="mesh"/>
        </default>
        <default class="door_knob">
            <geom condim="4" rgba="0.28 0.73 0.77 1.0" type="mesh"/>
        </default>
        <default class="robot">
			<geom rgba="0.792157 0.819608 0.933333 1"/>
		</default>
    </default>
	<option gravity="0 0 0" integrator="RK4" timestep="0.01"/>
	<worldbody>
		<!-- Robot -->
        <body childclass="robot" name="robotwrist_rolllink" pos="1.0 0 1.2" euler="0 0 0">
            <inertial pos="-0.0641638075944594 2.70691865020822e-05 0.00526385736219506" quat="0.999999 0.000484212 -0.00134643 -0.000743041" mass="0.657109755986862" fullinertia="0.0057866591250737 0.00530223654324281 0.00342399181200673 3.71515699629511e-07 -6.32890111626103e-05 8.9999884666805e-07" />
            <geom name="link" type="mesh" rgba="0.792157 0.819608 0.933333 1" mesh="wrist_roll_link" contype="16" conaffinity="7" euler="0 1.57 0" />
            <joint name="wrist_x_slide_joint" type="slide" pos="-0.0641638075944594 2.70691865020822e-05 0.00526385736219506" axis="1 0 0" limited="true" range="-3.0 3.0" />
            <joint name="wrist_y_slide_joint" type="slide" pos="-0.0641638075944594 2.70691865020822e-05 0.00526385736219506" axis="0 1 0" limited="true" range="-3.0 3.0" />
            <joint name="wrist_z_slide_joint" type="slide" pos="-0.0641638075944594 2.70691865020822e-05 0.00526385736219506" axis="0 0 1" limited="true" range="-3.0 3.0" />
            <joint name="wrist_z_hinge_joint" type="hinge" pos="-0.0641638075944594 2.70691865020822e-05 0.00526385736219506" axis="0 0 1" limited="true" range="-1.57 1.57" />
            <joint name="wrist_y_hinge_joint" type="hinge" pos="-0.0641638075944594 2.70691865020822e-05 0.00526385736219506" axis="0 1 0" limited="true" range="-1.57 1.57" />
            <joint name="wrist_x_hinge_joint" type="hinge" pos="-0.0641638075944594 2.70691865020822e-05 0.00526385736219506" axis="1 0 0" limited="true" range="0 3.13" />
            <body name="robotfinger_hook" pos="-0.06 -0.02 0" euler="0 0 0">
                <inertial pos="0 0 0" quat="1 0 0 0" mass="0.0001" diaginertia="3.916e-5 4.278e-5 4.8095e-6"/>
                <geom friction="1 1 1" type="mesh" mesh="hook_0" name="hookfinger_0" euler="0 0 0" condim="3"/>
                <geom friction="1 1 1" type="mesh" mesh="hook_3" name="hookfinger_3" euler="0 0 0" condim="3"/>
                <geom friction="1 1 1" type="mesh" mesh="hook_1" name="hookfinger_1" euler="0 0 0" condim="3"/>
                <body name="robotfinger_hook_target">
                    <geom friction="1 1 1" type="mesh" mesh="hook_2" name="hookfinger_2" euler="0 0 0" condim="3" rgba="0.1 0.1 0.1 1"/>
                </body>
            </body>
        </body>

		<!-- Target -->
        <geom name="floor" pos="2.0 0 -0.05" size="4.0 3.0 0.05" type="plane"/>
		<body childclass="wall" name="wall_link" pos="-0.036 0.159 0.0">
			<inertial mass="100" pos="0 0 0" diaginertia="0.0001 0.0001 0.0001"/>
			<geom name="wall_0" pos="0 -1.5425 1.1400000000000001" size="0.15 1.0 1.1400000000000001" type="box" euler="0 0 0"/>
			<geom name="wall_1" pos="0 1.5725 1.1400000000000001" size="0.15 1.0 1.1400000000000001" type="box" euler="0 0 0"/>
			<geom name="wall_2" pos="0 0 2.7800000000000002" size="0.15 2.5725 0.5" type="box" euler="0 0 0"/>
			<body childclass="frame" name="frame_link" pos="0 -0.29295 1.2">
				<inertial mass="100" pos="0 0 0" diaginertia="0.0001 0.0001 0.0001"/>
				<geom name="door_frame_0" pos="0 -0.20955 -0.05999999999999983" size="0.012 0.05 1.1400000000000001" type="box" euler="0 0 0"/>
				<geom name="door_frame_1" pos="0 0.83545 -0.05999999999999983" size="0.012 0.05 1.1400000000000001" type="box" euler="0 0 0"/>
				<geom name="door_frame_2" pos="0 0.29295 1.0300000000000002" size="0.012 0.5725 0.05" type="box" euler="0 0 0"/>
				<geom name="door_frame_3" pos="-0.044 -0.20955 -0.05999999999999983" size="0.012 0.05 1.1400000000000001" type="box" euler="0 0 0"/>
				<geom name="door_frame_4" pos="-0.044 0.83545 -0.05999999999999983" size="0.012 0.05 1.1400000000000001" type="box" euler="0 0 0"/>
				<geom name="door_frame_5" pos="-0.044 0.29295 1.0300000000000002" size="0.012 0.5725 0.05" type="box" euler="0 0 0"/>
				<body childclass="door" name="door_link" pos="0.026400000000000003 0 0">
					<joint armature="0.0001" axis="0 0 1" damping="0.1" frictionloss="0" limited="false" name="hinge0" pos="0 0.8032499999999999 0" range="-0.5 0.5" stiffness="0.1" type="hinge"/>
					<geom name="door0" pos="0 0.29295 -0.10999999999999988" size="0.012 0.4725 1.09" type="box" euler="0 0 0"/>
					<inertial mass="5.733835200000001" pos="0 0.29295 -0.10999999999999988" diaginertia="6.931563465330001 5.835797091129601 1.0971808223796"/>
					<body name="knob_link" pos="0 0 0">
                        <joint armature="0" axis="0 1 0" damping="300" limited="true" name="target_y" pos="0 0 0" range="-.2 .3" ref="-.1" stiffness="0" type="slide"/>
                        <joint armature="0" axis="0 0 1" damping="300" limited="true" name="target_z" pos="0 0 0" range="-.5 .5" ref="-.1" stiffness="0" type="slide"/>
                        <inertial mass="1" pos="0 0 0" diaginertia="0.001 0.001 0.001"/>
						<body childclass="door_knob" name="pullknob_link" pos="0.005 0 0">
							<geom friction="0.85 0.004 0.004" mesh="door_knob_1" name="door_knob_1" euler="-1.57 1.57 0"/>
							<geom friction="0.85 0.004 0.004" mesh="door_knob_2" name="door_knob_2" euler="-1.57 1.57 0"/>
							<geom friction="0.85 0.004 0.004" mesh="door_knob_3" name="door_knob_3" euler="-1.57 1.57 0"/>
							<geom friction="0.85 0.004 0.004" mesh="door_knob_4" name="door_knob_4" euler="-1.57 1.57 0"/>
							<geom friction="0.85 0.004 0.004" mesh="door_knob_6" name="door_knob_6" euler="-1.57 1.57 0"/>
							<geom friction="0.85 0.004 0.004" mesh="door_knob_7" name="door_knob_7" euler="-1.57 1.57 0"/>
                            <body childclass='door_knob' name='door_knob_target1'>
                                <geom friction="0.85 0.004 0.004" mesh="door_knob_5" name="door_knob_5" euler="-1.57 1.57 0" rgba="0.1 0.1 0.1 1"/>
                            </body>
                            <body childclass='door_knob' name='door_knob_target2'>
                                <geom friction="0.85 0.004 0.004" mesh="door_knob_8" name="door_knob_8" euler="-1.57 1.57 0" rgba="0.1 0.1 0.1 1"/>
                            </body>
                        </body>
					</body>
				</body>
			</body>
		</body>

	</worldbody>
	<actuator>
        <motor ctrllimited="true" ctrlrange="-1.0 1.0" gear="2.0" joint="wrist_x_slide_joint" />
        <motor ctrllimited="true" ctrlrange="-1.0 1.0" gear="2.0" joint="wrist_y_slide_joint" />
        <motor ctrllimited="true" ctrlrange="-1.0 1.0" gear="2.0" joint="wrist_z_slide_joint" />
        <motor ctrllimited="true" ctrlrange="-1.0 1.0" gear="2.0" joint="wrist_z_hinge_joint" />
        <motor ctrllimited="true" ctrlrange="-1.0 1.0" gear="2.0" joint="wrist_y_hinge_joint" />
        <motor ctrllimited="true" ctrlrange="-1.0 1.0" gear="2.0" joint="wrist_x_hinge_joint" />        
	</actuator>
    
</mujoco>