<?xml version="1.0" encoding="utf-8"?>
<mujoco model="door_knob">
	<compiler angle="radian"/>
	<include file="../../robot/blue_right_v2_gripper_position.xml"/>
	<option gravity="0 0 0" timestep="0.001"/>
	<visual>
		<map fogend="5" fogstart="3" force="0.1" zfar="10" znear="0.01"/>
		<quality shadowsize="2048"/>
		<global offheight="256" offwidth="256"/>
	</visual>
	<asset>
		<mesh file="../../door/pullknobs/1555112003/body_1.stl" name="door_knob_1" scale="0.001 0.001 0.001"/>
		<mesh file="../../door/pullknobs/1555112003/body_2.stl" name="door_knob_2" scale="0.001 0.001 0.001"/>
		<mesh file="../../door/pullknobs/1555112003/body_3.stl" name="door_knob_3" scale="0.001 0.001 0.001"/>
		<mesh file="../../door/pullknobs/1555112003/body_4.stl" name="door_knob_4" scale="0.001 0.001 0.001"/>
		<mesh file="../../door/pullknobs/1555112003/body_5.stl" name="door_knob_5" scale="0.001 0.001 0.001"/>
		<mesh file="../../door/pullknobs/1555112003/body_6.stl" name="door_knob_6" scale="0.001 0.001 0.001"/>
		<mesh file="../../door/pullknobs/1555112003/body_7.stl" name="door_knob_7" scale="0.001 0.001 0.001"/>
		<mesh file="../../door/pullknobs/1555112003/body_8.stl" name="door_knob_8" scale="0.001 0.001 0.001"/>
		<texture builtin="flat" height="32" name="wall_geom" type="2d" width="32"/>
		<texture builtin="flat" height="32" name="frame_geom" type="2d" width="32"/>
		<texture builtin="flat" height="32" name="door_geom" type="2d" width="32"/>
		<texture builtin="flat" height="32" name="knob_geom" type="2d" width="32"/>
		<texture builtin="gradient" height="128" rgb1="0.4 0.6 0.8" rgb2="0 0 0" type="skybox" width="128"/>
		<texture builtin="gradient" height="512" name="texplane" rgb1="0.16 0.33 0.13" rgb2="0.32 0.48 0.08" type="2d" width="512"/>
		<material name="Paint" shininess="0.01" specular="0.39" texture="wall_geom"/>
		<material name="Wood" shininess="0.1" specular="0.08" texture="frame_geom"/>
		<material name="Carpet" shininess="0.02" specular="0.04" texture="door_geom"/>
		<material name="Metal" shininess="0.87" specular="0.8" texture="knob_geom"/>
		<material name="Floor" texture="texplane"/>
	</asset>
	<contact/>
	<default>
		<joint armature="1" damping="1" limited="true"/>
		<default class="wall">
			<geom rgba="0.3 0.53 0.33 1.0" type="mesh"/>
		</default>
		<default class="frame">
			<geom rgba="0.7 0.82 0.76 1.0" type="mesh"/>
		</default>
		<default class="door">
			<geom rgba="0.41 0.61 0.33 1.0" type="mesh"/>
		</default>
		<default class="door_knob">
			<geom condim="4" rgba="0.27 0.09 0.32 1.0" type="mesh"/>
		</default>
		<default class="robot">
			<joint damping="0.09"/>
		</default>
	</default>
	<worldbody>
		<light diffuse="0.9 0.9 0.9" dir="-0.23 0.42 -0.37" directional="true" pos="1.99 -1.81 6.19"/>
		<light diffuse="0.9 0.9 1.0" dir="-0.08 -0.01 -0.43" directional="true" pos="2.23 -2.32 5.98"/>
		<light diffuse="0.9 0.9 0.9" dir="0.02 -0.45 -0.34" directional="true" pos="2.63 -0.35 3.94"/>
		<light diffuse="0.9 0.9 1.0" dir="0.49 -0.25 -0.39" directional="true" pos="2.74 2.99 5.93"/>
		<light diffuse="0.9 0.9 0.9" dir="0.09 0.47 -0.5" directional="true" pos="3.07 2.31 6.76"/>
		<geom material="Floor" name="floor" pos="0 0 -0.05" size="15.0 15.0 0.05" type="plane"/>
		<camera fovy="60" mode="fixed" name="camera1" pos="0.99 -0.5 1.0" euler="0.0 1.57 1.57"/>
		<camera fovy="60" mode="fixed" name="camera2" pos="0.5 0.0 1.99" euler="0 0 0"/>
		<body childclass="wall" name="wall_link" pos="0.0 -0.085 0.0">
			<inertial mass="100" pos="0 0 0" diaginertia="0.0001 0.0001 0.0001"/>
			<geom material="Carpet" name="wall_0" pos="-0.15 -1.5439999999999998 1.27" size="0.15 1.0 1.27" type="box" euler="0 0 0"/>
			<geom material="Carpet" name="wall_1" pos="-0.15 1.5739999999999998 1.27" size="0.15 1.0 1.27" type="box" euler="0 0 0"/>
			<geom material="Carpet" name="wall_2" pos="-0.15 0 3.04" size="0.15 2.574 0.5" type="box" euler="0 0 0"/>
			<body childclass="frame" name="frame_link" pos="0 -0.3318 1.005">
				<inertial mass="500" pos="0 0 0" diaginertia="0.0001 0.0001 0.0001"/>
				<geom material="Wood" name="door_frame_0" pos="0 -0.2022 0.2650000000000001" size="0.013 0.05 1.27" type="box" euler="0 0 0"/>
				<geom material="Wood" name="door_frame_1" pos="0 0.8658 0.2650000000000001" size="0.013 0.05 1.27" type="box" euler="0 0 0"/>
				<geom material="Wood" name="door_frame_2" pos="0 0.3318 1.485" size="0.013 0.574 0.05" type="box" euler="0 0 0"/>
				<geom material="Wood" name="door_frame_3" pos="-0.0455 -0.2022 0.2650000000000001" size="0.013 0.05 1.27" type="box" euler="0 0 0"/>
				<geom material="Wood" name="door_frame_4" pos="-0.0455 0.8658 0.2650000000000001" size="0.013 0.05 1.27" type="box" euler="0 0 0"/>
				<geom material="Wood" name="door_frame_5" pos="-0.0455 0.3318 1.485" size="0.013 0.574 0.05" type="box" euler="0 0 0"/>
				<body childclass="door" name="door_link" pos="0 0 0">
					<joint armature="0.0001" axis="0 0 1" damping="1.2" frictionloss="0" limited="true" name="hinge0" pos="0 0.8058 0" range="-0.0 1.57" stiffness="0.13" type="hinge"/>
					<geom material="Wood" name="door0" pos="0 0.3318 0.21500000000000008" size="0.013 0.474 1.2078" type="box" euler="0 0 0"/>
					<inertial mass="54.668278079999986" pos="0 0.3318 0.21500000000000008" diaginertia="31.216971713391352 27.125834677755833 4.0972963282991985"/>
					<body childclass="door_knob" name="knob_link" pos="0 0 0">
						<inertial mass="1" pos="0 0 0" diaginertia="0.001 0.001 0.001"/>
						<joint armature="0" axis="0 1 0" damping="30000" frictionloss="0" limited="true" name="target0" range="-0.2 0.3" stiffness="0" type="slide"/>
						<joint armature="0" axis="0 0 1" damping="30000" frictionloss="0" limited="true" name="target1" range="-0.5 0.5" stiffness="0" type="slide"/>
						<body childclass="door_knob" name="pullknob_link" pos="0.006999999999999999 0 0">
							<geom friction="0.72 0.001 0.001" material="Carpet" mesh="door_knob_1" name="door_knob_1" euler="-1.57 1.57 0"/>
							<geom friction="0.72 0.001 0.001" material="Carpet" mesh="door_knob_2" name="door_knob_2" euler="-1.57 1.57 0"/>
							<geom friction="0.72 0.001 0.001" material="Carpet" mesh="door_knob_3" name="door_knob_3" euler="-1.57 1.57 0"/>
							<geom friction="0.72 0.001 0.001" material="Carpet" mesh="door_knob_4" name="door_knob_4" euler="-1.57 1.57 0"/>
							<geom friction="0.72 0.001 0.001" material="Carpet" mesh="door_knob_5" name="door_knob_5" euler="-1.57 1.57 0"/>
							<geom friction="0.72 0.001 0.001" material="Carpet" mesh="door_knob_6" name="door_knob_6" euler="-1.57 1.57 0"/>
							<geom friction="0.72 0.001 0.001" material="Carpet" mesh="door_knob_7" name="door_knob_7" euler="-1.57 1.57 0"/>
							<geom friction="0.72 0.001 0.001" material="Carpet" mesh="door_knob_8" name="door_knob_8" euler="-1.57 1.57 0"/>
						</body>
					</body>
				</body>
			</body>
		</body>
	</worldbody>
</mujoco>