<?xml version="1.0" encoding="utf-8"?>
<mujoco model="door_knob">
	<compiler angle="radian"/>
	<include file="../../robot/blue_right_v2_position.xml"/>
	<option gravity="0 0 -9.81" timestep="0.001"/>
	<visual>
		<map fogend="5" fogstart="3" force="0.1" zfar="10" znear="0.01"/>
		<quality shadowsize="2048"/>
		<global offheight="256" offwidth="256"/>
	</visual>
	<asset>
		<mesh file="../../door/leverknobs/1551849078/body_1.stl" name="door_knob_1" scale="0.0015 0.0015 0.0015"/>
		<mesh file="../../door/leverknobs/1551849078/body_2.stl" name="door_knob_2" scale="0.0015 0.0015 0.0015"/>
		<mesh file="../../door/leverknobs/1551849078/body_3.stl" name="door_knob_3" scale="0.0015 0.0015 0.0015"/>
		<mesh file="../../door/leverknobs/1551849078/body_4.stl" name="door_knob_4" scale="0.0015 0.0015 0.0015"/>
		<mesh file="../../door/leverknobs/1551849078/body_5.stl" name="door_knob_5" scale="0.0015 0.0015 0.0015"/>
		<texture builtin="flat" height="32" name="wall_geom" type="2d" width="32"/>
		<texture builtin="flat" height="32" name="frame_geom" type="2d" width="32"/>
		<texture builtin="flat" height="32" name="door_geom" type="2d" width="32"/>
		<texture builtin="flat" height="32" name="knob_geom" type="2d" width="32"/>
		<texture builtin="gradient" height="128" rgb1="0.4 0.6 0.8" rgb2="0 0 0" type="skybox" width="128"/>
		<texture builtin="gradient" height="512" name="texplane" rgb1="0.48 0.49 0.37" rgb2="0.4 0.48 0.42" type="2d" width="512"/>
		<material name="Paint" shininess="0.03" specular="0.29" texture="wall_geom"/>
		<material name="Wood" shininess="0.1" specular="0.18" texture="frame_geom"/>
		<material name="Carpet" shininess="0.04" specular="0.02" texture="door_geom"/>
		<material name="Metal" shininess="0.82" specular="0.83" texture="knob_geom"/>
		<material name="Floor" texture="texplane"/>
	</asset>
	<contact>
		<pair geom1="knob_latch" geom2="door_frame_0" solref="0.01 1"/>
		<pair geom1="knob_latch" geom2="door_frame_1" solref="0.01 1"/>
		<pair geom1="knob_latch" geom2="door_frame_2" solref="0.01 1"/>
		<pair geom1="knob_latch" geom2="door_frame_3" solref="0.01 1"/>
	</contact>
	<default>
		<joint armature="1" damping="1" limited="true"/>
		<default class="wall">
			<geom rgba="0.82 0.8 0.09 1.0" type="mesh"/>
		</default>
		<default class="frame">
			<geom rgba="0.74 0.73 0.78 1.0" type="mesh"/>
		</default>
		<default class="door">
			<geom rgba="0.75 0.45 0.25 1.0" type="mesh"/>
		</default>
		<default class="door_knob">
			<geom condim="4" rgba="0.16 0.44 0.88 1.0" type="mesh"/>
		</default>
		<default class="robot">
			<joint damping="0.09"/>
		</default>
	</default>
	<worldbody>
		<light diffuse="0.9 1.0 0.9" dir="0.4 -0.33 -0.44" directional="true" pos="1.51 -4.58 6.26"/>
		<light diffuse="0.9 0.9 1.0" dir="-0.48 0.09 -0.28" directional="true" pos="3.52 -0.9 5.19"/>
		<light diffuse="0.9 0.9 1.0" dir="0.29 0.48 -0.27" directional="true" pos="4.16 4.84 4.04"/>
		<light diffuse="1.0 0.9 0.9" dir="-0.45 -0.32 -0.43" directional="true" pos="4.36 -3.37 3.22"/>
		<light diffuse="0.9 1.0 1.0" dir="0.12 0.05 -0.39" directional="true" pos="2.24 -0.88 6.23"/>
		<geom material="Floor" name="floor" pos="0 0 -0.05" size="15.0 15.0 0.05" type="plane"/>
		<camera fovy="60" mode="fixed" name="camera1" pos="0.99 -0.5 1.0" euler="0.0 1.57 1.57"/>
		<camera fovy="60" mode="fixed" name="camera2" pos="0.5 0.0 1.99" euler="0 0 0"/>
		<body childclass="wall" name="wall_link" pos="0.0 -0.014 0.0">
			<inertial mass="100" pos="0 0 0" diaginertia="0.0001 0.0001 0.0001"/>
			<geom material="Paint" name="wall_0" pos="-0.15 -1.489 1.244" size="0.15 1.0 1.244" type="box" euler="0 0 0"/>
			<geom material="Paint" name="wall_1" pos="-0.15 1.5190000000000001 1.244" size="0.15 1.0 1.244" type="box" euler="0 0 0"/>
			<geom material="Paint" name="wall_2" pos="-0.15 0 2.988" size="0.15 2.519 0.5" type="box" euler="0 0 0"/>
			<body childclass="frame" name="frame_link" pos="0 -0.28491999999999995 1.007">
				<inertial mass="500" pos="0 0 0" diaginertia="0.0001 0.0001 0.0001"/>
				<geom material="Paint" name="door_frame_0" pos="0 -0.19408000000000003 0.2370000000000001" size="0.0145 0.05 1.244" type="box" euler="0 0 0"/>
				<geom material="Paint" name="door_frame_1" pos="0 0.76392 0.2370000000000001" size="0.0145 0.05 1.244" type="box" euler="0 0 0"/>
				<geom material="Paint" name="door_frame_2" pos="0 0.28491999999999995 1.431" size="0.0145 0.519 0.05" type="box" euler="0 0 0"/>
				<geom material="Paint" name="door_frame_3" pos="-0.0485 -0.19408000000000003 0.2370000000000001" size="0.0145 0.05 1.244" type="box" euler="0 0 0"/>
				<geom material="Paint" name="door_frame_4" pos="-0.0485 0.76392 0.2370000000000001" size="0.0145 0.05 1.244" type="box" euler="0 0 0"/>
				<geom material="Paint" name="door_frame_5" pos="-0.0485 0.28491999999999995 1.431" size="0.0145 0.519 0.05" type="box" euler="0 0 0"/>
				<body childclass="door" name="door_link" pos="0 0 0">
					<joint armature="0.0001" axis="0 0 1" damping="1.3" frictionloss="0" limited="true" name="hinge0" pos="0 0.70392 0" range="-0.0 1.57" stiffness="0.16" type="hinge"/>
					<geom material="Carpet" name="door0" pos="0 0.28491999999999995 0.18700000000000006" size="0.0145 0.419 1.1820599999999999" type="box" euler="0 0 0"/>
					<inertial mass="57.56891059200001" pos="0 0.28491999999999995 0.18700000000000006" diaginertia="30.726388977726213 27.361471761396164 3.3729864586313605"/>
					<body childclass="door_knob" name="knob_link" pos="0 0 0">
						<inertial mass="1" pos="0 0 0" diaginertia="0.001 0.001 0.001"/>
						<joint armature="0" axis="0 1 0" damping="30000" frictionloss="0" limited="true" name="target0" range="-0.2 0.3" stiffness="0" type="slide"/>
						<joint armature="0" axis="0 0 1" damping="30000" frictionloss="0" limited="true" name="target1" range="-0.5 0.5" stiffness="0" type="slide"/>
						<joint armature="0.0001" axis="1 0 0" damping="1.25" frictionloss="0" limited="true" name="hinge1" pos="0 0 0" range="-1.3432222222222223 1.3432222222222223" stiffness="1.18" type="hinge"/>
						<body childclass="door_knob" name="leverknob_link" pos="0.0145 0 0">
							<geom friction="0.64 0.002 0.003" material="Paint" mesh="door_knob_1" name="door_knob_1" euler="-1.57 1.57 0"/>
							<geom friction="0.64 0.002 0.003" material="Paint" mesh="door_knob_2" name="door_knob_2" euler="-1.57 1.57 0"/>
							<geom friction="0.64 0.002 0.003" material="Paint" mesh="door_knob_3" name="door_knob_3" euler="-1.57 1.57 0"/>
							<geom friction="0.64 0.002 0.003" material="Paint" mesh="door_knob_4" name="door_knob_4" euler="-1.57 1.57 0"/>
							<geom friction="0.64 0.002 0.003" material="Paint" mesh="door_knob_5" name="door_knob_5" euler="-1.57 1.57 0"/>
							<geom material="Carpet" name="knob_latch" pos="-0.03875 0 0" size="0.0075 0.16741333333333333 0.05" type="box" euler="0 0 0"/>
							<inertial mass="1" pos="-0.07065 0 0" diaginertia="0.002543935348148148 0.00022708333333333337 0.002354352014814815"/>
						</body>
					</body>
				</body>
			</body>
		</body>
	</worldbody>
</mujoco>