<?xml version="1.0" encoding="utf-8"?>
<mujoco model="door_knob">
	<compiler angle="radian"/>
	<include file="../../robot/blue_right_v2_position.xml"/>
	<option gravity="0 0 -9.81" timestep="0.001"/>
	<visual>
		<map fogend="5" fogstart="3" force="0.1" zfar="10" znear="0.01"/>
		<quality shadowsize="2048"/>
		<global offheight="256" offwidth="256"/>
	</visual>
	<asset>
		<mesh file="../../door/leverknobs/1551848929/body_1.stl" name="door_knob_1" scale="0.0015 0.0015 0.0015"/>
		<mesh file="../../door/leverknobs/1551848929/body_2.stl" name="door_knob_2" scale="0.0015 0.0015 0.0015"/>
		<mesh file="../../door/leverknobs/1551848929/body_3.stl" name="door_knob_3" scale="0.0015 0.0015 0.0015"/>
		<mesh file="../../door/leverknobs/1551848929/body_4.stl" name="door_knob_4" scale="0.0015 0.0015 0.0015"/>
		<mesh file="../../door/leverknobs/1551848929/body_5.stl" name="door_knob_5" scale="0.0015 0.0015 0.0015"/>
		<texture builtin="flat" height="32" name="wall_geom" type="2d" width="32"/>
		<texture builtin="flat" height="32" name="frame_geom" type="2d" width="32"/>
		<texture builtin="flat" height="32" name="door_geom" type="2d" width="32"/>
		<texture builtin="flat" height="32" name="knob_geom" type="2d" width="32"/>
		<texture builtin="gradient" height="128" rgb1="0.4 0.6 0.8" rgb2="0 0 0" type="skybox" width="128"/>
		<texture builtin="gradient" height="512" name="texplane" rgb1="0.27 0.29 0.1" rgb2="0.43 0.05 0.29" type="2d" width="512"/>
		<material name="Paint" shininess="0.1" specular="0.17" texture="wall_geom"/>
		<material name="Wood" shininess="0.14" specular="0.13" texture="frame_geom"/>
		<material name="Carpet" shininess="0.02" specular="0.03" texture="door_geom"/>
		<material name="Metal" shininess="0.96" specular="0.83" texture="knob_geom"/>
		<material name="Floor" texture="texplane"/>
	</asset>
	<contact>
		<pair geom1="knob_latch" geom2="door_frame_0" solref="0.01 1"/>
		<pair geom1="knob_latch" geom2="door_frame_1" solref="0.01 1"/>
		<pair geom1="knob_latch" geom2="door_frame_2" solref="0.01 1"/>
		<pair geom1="knob_latch" geom2="door_frame_3" solref="0.01 1"/>
	</contact>
	<default>
		<joint armature="1" damping="1" limited="true"/>
		<default class="wall">
			<geom rgba="0.67 0.4 0.42 1.0" type="mesh"/>
		</default>
		<default class="frame">
			<geom rgba="0.8 0.81 0.74 1.0" type="mesh"/>
		</default>
		<default class="door">
			<geom rgba="0.09 0.83 0.57 1.0" type="mesh"/>
		</default>
		<default class="door_knob">
			<geom condim="4" rgba="0.15 0.16 0.27 1.0" type="mesh"/>
		</default>
		<default class="robot">
			<joint damping="0.09"/>
		</default>
	</default>
	<worldbody>
		<light diffuse="1.0 0.9 0.9" dir="0.13 0.42 -0.29" directional="true" pos="3.82 2.31 6.84"/>
		<light diffuse="0.9 1.0 0.9" dir="-0.4 0.45 -0.47" directional="true" pos="4.6 -3.03 4.11"/>
		<geom material="Floor" name="floor" pos="0 0 -0.05" size="15.0 15.0 0.05" type="plane"/>
		<camera fovy="60" mode="fixed" name="camera1" pos="0.99 -0.5 1.0" euler="0.0 1.57 1.57"/>
		<camera fovy="60" mode="fixed" name="camera2" pos="0.5 0.0 1.99" euler="0 0 0"/>
		<body childclass="wall" name="wall_link" pos="0.0 0.043 0.0">
			<inertial mass="100" pos="0 0 0" diaginertia="0.0001 0.0001 0.0001"/>
			<geom material="Carpet" name="wall_0" pos="-0.15 -1.5765 1.119" size="0.15 1.0 1.119" type="box" euler="0 0 0"/>
			<geom material="Carpet" name="wall_1" pos="-0.15 1.6065 1.119" size="0.15 1.0 1.119" type="box" euler="0 0 0"/>
			<geom material="Carpet" name="wall_2" pos="-0.15 0 2.738" size="0.15 2.6065 0.5" type="box" euler="0 0 0"/>
			<body childclass="frame" name="frame_link" pos="0 -0.39507 0.987">
				<inertial mass="500" pos="0 0 0" diaginertia="0.0001 0.0001 0.0001"/>
				<geom material="Carpet" name="door_frame_0" pos="0 -0.17143 0.132" size="0.0115 0.05 1.119" type="box" euler="0 0 0"/>
				<geom material="Carpet" name="door_frame_1" pos="0 0.9615699999999999 0.132" size="0.0115 0.05 1.119" type="box" euler="0 0 0"/>
				<geom material="Carpet" name="door_frame_2" pos="0 0.39507 1.2009999999999998" size="0.0115 0.6064999999999999 0.05" type="box" euler="0 0 0"/>
				<geom material="Carpet" name="door_frame_3" pos="-0.042499999999999996 -0.17143 0.132" size="0.0115 0.05 1.119" type="box" euler="0 0 0"/>
				<geom material="Carpet" name="door_frame_4" pos="-0.042499999999999996 0.9615699999999999 0.132" size="0.0115 0.05 1.119" type="box" euler="0 0 0"/>
				<geom material="Carpet" name="door_frame_5" pos="-0.042499999999999996 0.39507 1.2009999999999998" size="0.0115 0.6064999999999999 0.05" type="box" euler="0 0 0"/>
				<body childclass="door" name="door_link" pos="0 0 0">
					<joint armature="0.0001" axis="0 0 1" damping="1.2" frictionloss="0" limited="true" name="hinge0" pos="0 0.9015699999999999 0" range="-0.0 1.57" stiffness="0.17" type="hinge"/>
					<geom material="Wood" name="door0" pos="0 0.39507 0.08199999999999996" size="0.0115 0.5065 1.0583099999999999" type="box" euler="0 0 0"/>
					<inertial mass="48.11961109199999" pos="0 0.39507 0.08199999999999996" diaginertia="22.44464272992388 18.33185956989064 4.117025705744517"/>
					<body childclass="door_knob" name="knob_link" pos="0 0 0">
						<inertial mass="1" pos="0 0 0" diaginertia="0.001 0.001 0.001"/>
						<joint armature="0" axis="0 1 0" damping="30000" frictionloss="0" limited="true" name="target0" range="-0.2 0.3" stiffness="0" type="slide"/>
						<joint armature="0" axis="0 0 1" damping="30000" frictionloss="0" limited="true" name="target1" range="-0.5 0.5" stiffness="0" type="slide"/>
						<joint armature="0.0001" axis="1 0 0" damping="1.27" frictionloss="0" limited="true" name="hinge1" pos="0 0 0" range="-1.3606666666666667 1.3606666666666667" stiffness="1.2" type="hinge"/>
						<body childclass="door_knob" name="leverknob_link" pos="0.0115 0 0">
							<geom friction="0.92 0.002 0.002" material="Wood" mesh="door_knob_1" name="door_knob_1" euler="-1.57 1.57 0"/>
							<geom friction="0.92 0.002 0.002" material="Wood" mesh="door_knob_2" name="door_knob_2" euler="-1.57 1.57 0"/>
							<geom friction="0.92 0.002 0.002" material="Wood" mesh="door_knob_3" name="door_knob_3" euler="-1.57 1.57 0"/>
							<geom friction="0.92 0.002 0.002" material="Wood" mesh="door_knob_4" name="door_knob_4" euler="-1.57 1.57 0"/>
							<geom friction="0.92 0.002 0.002" material="Wood" mesh="door_knob_5" name="door_knob_5" euler="-1.57 1.57 0"/>
							<geom material="Paint" name="knob_latch" pos="-0.03275 0 0" size="0.0075 0.14476333333333333 0.05" type="box" euler="0 0 0"/>
							<inertial mass="1" pos="-0.058050000000000004 0 0" diaginertia="0.0019547018898148144 0.00022708333333333337 0.0017651185564814813"/>
						</body>
					</body>
				</body>
			</body>
		</body>
	</worldbody>
</mujoco>