<?xml version="1.0" encoding="utf-8"?>
<mujoco model="door_knob">
	<compiler angle="radian"/>
	<include file="../../robot/blue_right_v2_position.xml"/>
	<option gravity="0 0 -9.81" timestep="0.001"/>
	<visual>
		<map fogend="5" fogstart="3" force="0.1" zfar="10" znear="0.01"/>
		<quality shadowsize="2048"/>
		<global offheight="256" offwidth="256"/>
	</visual>
	<asset>
		<mesh file="../../door/leverknobs/1551849051/body_1.stl" name="door_knob_1" scale="0.0015 0.0015 0.0015"/>
		<mesh file="../../door/leverknobs/1551849051/body_2.stl" name="door_knob_2" scale="0.0015 0.0015 0.0015"/>
		<mesh file="../../door/leverknobs/1551849051/body_3.stl" name="door_knob_3" scale="0.0015 0.0015 0.0015"/>
		<mesh file="../../door/leverknobs/1551849051/body_4.stl" name="door_knob_4" scale="0.0015 0.0015 0.0015"/>
		<mesh file="../../door/leverknobs/1551849051/body_5.stl" name="door_knob_5" scale="0.0015 0.0015 0.0015"/>
		<texture builtin="flat" height="32" name="wall_geom" type="2d" width="32"/>
		<texture builtin="flat" height="32" name="frame_geom" type="2d" width="32"/>
		<texture builtin="flat" height="32" name="door_geom" type="2d" width="32"/>
		<texture builtin="flat" height="32" name="knob_geom" type="2d" width="32"/>
		<texture builtin="gradient" height="128" rgb1="0.4 0.6 0.8" rgb2="0 0 0" type="skybox" width="128"/>
		<texture builtin="gradient" height="512" name="texplane" rgb1="0.0 0.17 0.09" rgb2="0.28 0.48 0.34" type="2d" width="512"/>
		<material name="Paint" shininess="0.03" specular="0.18" texture="wall_geom"/>
		<material name="Wood" shininess="0.06" specular="0.14" texture="frame_geom"/>
		<material name="Carpet" shininess="0.01" specular="0.03" texture="door_geom"/>
		<material name="Metal" shininess="0.93" specular="0.89" texture="knob_geom"/>
		<material name="Floor" texture="texplane"/>
	</asset>
	<contact>
		<pair geom1="knob_latch" geom2="door_frame_0" solref="0.01 1"/>
		<pair geom1="knob_latch" geom2="door_frame_1" solref="0.01 1"/>
		<pair geom1="knob_latch" geom2="door_frame_2" solref="0.01 1"/>
		<pair geom1="knob_latch" geom2="door_frame_3" solref="0.01 1"/>
	</contact>
	<default>
		<joint armature="1" damping="1" limited="true"/>
		<default class="wall">
			<geom rgba="0.3 0.13 0.46 1.0" type="mesh"/>
		</default>
		<default class="frame">
			<geom rgba="0.78 0.74 0.82 1.0" type="mesh"/>
		</default>
		<default class="door">
			<geom rgba="0.55 0.04 0.32 1.0" type="mesh"/>
		</default>
		<default class="door_knob">
			<geom condim="4" rgba="0.78 0.02 0.59 1.0" type="mesh"/>
		</default>
		<default class="robot">
			<joint damping="0.09"/>
		</default>
	</default>
	<worldbody>
		<light diffuse="0.9 1.0 1.0" dir="0.29 -0.28 -0.26" directional="true" pos="2.04 -2.23 3.36"/>
		<light diffuse="0.9 1.0 1.0" dir="-0.36 -0.27 -0.37" directional="true" pos="0.98 1.92 5.63"/>
		<geom material="Floor" name="floor" pos="0 0 -0.05" size="15.0 15.0 0.05" type="plane"/>
		<camera fovy="60" mode="fixed" name="camera1" pos="0.99 -0.5 1.0" euler="0.0 1.57 1.57"/>
		<camera fovy="60" mode="fixed" name="camera2" pos="0.5 0.0 1.99" euler="0 0 0"/>
		<body childclass="wall" name="wall_link" pos="0.0 -0.052 0.0">
			<inertial mass="100" pos="0 0 0" diaginertia="0.0001 0.0001 0.0001"/>
			<geom material="Paint" name="wall_0" pos="-0.15 -1.583 1.1325" size="0.15 1.0 1.1325" type="box" euler="0 0 0"/>
			<geom material="Paint" name="wall_1" pos="-0.15 1.613 1.1325" size="0.15 1.0 1.1325" type="box" euler="0 0 0"/>
			<geom material="Paint" name="wall_2" pos="-0.15 0 2.765" size="0.15 2.613 0.5" type="box" euler="0 0 0"/>
			<body childclass="frame" name="frame_link" pos="0 -0.3591 0.921">
				<inertial mass="500" pos="0 0 0" diaginertia="0.0001 0.0001 0.0001"/>
				<geom material="Paint" name="door_frame_0" pos="0 -0.21390000000000003 0.21150000000000002" size="0.011 0.05 1.1325" type="box" euler="0 0 0"/>
				<geom material="Paint" name="door_frame_1" pos="0 0.9321 0.21150000000000002" size="0.011 0.05 1.1325" type="box" euler="0 0 0"/>
				<geom material="Paint" name="door_frame_2" pos="0 0.3591 1.294" size="0.011 0.613 0.05" type="box" euler="0 0 0"/>
				<geom material="Paint" name="door_frame_3" pos="-0.041499999999999995 -0.21390000000000003 0.21150000000000002" size="0.011 0.05 1.1325" type="box" euler="0 0 0"/>
				<geom material="Paint" name="door_frame_4" pos="-0.041499999999999995 0.9321 0.21150000000000002" size="0.011 0.05 1.1325" type="box" euler="0 0 0"/>
				<geom material="Paint" name="door_frame_5" pos="-0.041499999999999995 0.3591 1.294" size="0.011 0.613 0.05" type="box" euler="0 0 0"/>
				<body childclass="door" name="door_link" pos="0 0 0">
					<joint armature="0.0001" axis="0 0 1" damping="1.5" frictionloss="0" limited="true" name="hinge0" pos="0 0.8721 0" range="-0.0 1.57" stiffness="0.12" type="hinge"/>
					<geom material="Carpet" name="door0" pos="0 0.3591 0.16149999999999998" size="0.011 0.513 1.071675" type="box" euler="0 0 0"/>
					<inertial mass="46.71817128" pos="0 0.3591 0.16149999999999998" diaginertia="22.346473170686938 18.250099331066462 4.1001424387703995"/>
					<body childclass="door_knob" name="knob_link" pos="0 0 0">
						<inertial mass="1" pos="0 0 0" diaginertia="0.001 0.001 0.001"/>
						<joint armature="0" axis="0 1 0" damping="30000" frictionloss="0" limited="true" name="target0" range="-0.2 0.3" stiffness="0" type="slide"/>
						<joint armature="0" axis="0 0 1" damping="30000" frictionloss="0" limited="true" name="target1" range="-0.5 0.5" stiffness="0" type="slide"/>
						<joint armature="0.0001" axis="1 0 0" damping="1.36" frictionloss="0" limited="true" name="hinge1" pos="0 0 0" range="-1.3606666666666667 1.3606666666666667" stiffness="1.1" type="hinge"/>
						<body childclass="door_knob" name="leverknob_link" pos="0.011 0 0">
							<geom friction="0.89 0.003 0.004" material="Carpet" mesh="door_knob_1" name="door_knob_1" euler="-1.57 1.57 0"/>
							<geom friction="0.89 0.003 0.004" material="Carpet" mesh="door_knob_2" name="door_knob_2" euler="-1.57 1.57 0"/>
							<geom friction="0.89 0.003 0.004" material="Carpet" mesh="door_knob_3" name="door_knob_3" euler="-1.57 1.57 0"/>
							<geom friction="0.89 0.003 0.004" material="Carpet" mesh="door_knob_4" name="door_knob_4" euler="-1.57 1.57 0"/>
							<geom friction="0.89 0.003 0.004" material="Carpet" mesh="door_knob_5" name="door_knob_5" euler="-1.57 1.57 0"/>
							<geom material="Paint" name="knob_latch" pos="-0.03175 0 0" size="0.0075 0.18723333333333333 0.05" type="box" euler="0 0 0"/>
							<inertial mass="1" pos="-0.05595 0 0" diaginertia="0.0031296934259259263 0.00022708333333333337 0.002940110092592593"/>
						</body>
					</body>
				</body>
			</body>
		</body>
	</worldbody>
</mujoco>