<?xml version="1.0" encoding="utf-8"?>
<mujoco model="door_knob">
	<compiler angle="radian"/>
	<include file="../../robot/blue_right_v2_position.xml"/>
	<option gravity="0 0 -9.81" timestep="0.001"/>
	<visual>
		<map fogend="5" fogstart="3" force="0.1" zfar="10" znear="0.01"/>
		<quality shadowsize="2048"/>
		<global offheight="256" offwidth="256"/>
	</visual>
	<asset>
		<mesh file="../../door/leverknobs/1551848946/body_1.stl" name="door_knob_1" scale="0.0015 0.0015 0.0015"/>
		<mesh file="../../door/leverknobs/1551848946/body_2.stl" name="door_knob_2" scale="0.0015 0.0015 0.0015"/>
		<mesh file="../../door/leverknobs/1551848946/body_3.stl" name="door_knob_3" scale="0.0015 0.0015 0.0015"/>
		<mesh file="../../door/leverknobs/1551848946/body_4.stl" name="door_knob_4" scale="0.0015 0.0015 0.0015"/>
		<mesh file="../../door/leverknobs/1551848946/body_5.stl" name="door_knob_5" scale="0.0015 0.0015 0.0015"/>
		<texture builtin="flat" height="32" name="wall_geom" type="2d" width="32"/>
		<texture builtin="flat" height="32" name="frame_geom" type="2d" width="32"/>
		<texture builtin="flat" height="32" name="door_geom" type="2d" width="32"/>
		<texture builtin="flat" height="32" name="knob_geom" type="2d" width="32"/>
		<texture builtin="gradient" height="128" rgb1="0.4 0.6 0.8" rgb2="0 0 0" type="skybox" width="128"/>
		<texture builtin="gradient" height="512" name="texplane" rgb1="0.37 0.23 0.14" rgb2="0.23 0.35 0.39" type="2d" width="512"/>
		<material name="Paint" shininess="0.41" specular="0.44" texture="wall_geom"/>
		<material name="Wood" shininess="0.08" specular="0.09" texture="frame_geom"/>
		<material name="Carpet" shininess="0.01" specular="0.01" texture="door_geom"/>
		<material name="Metal" shininess="0.85" specular="0.86" texture="knob_geom"/>
		<material name="Floor" texture="texplane"/>
	</asset>
	<contact>
		<pair geom1="knob_latch" geom2="door_frame_0" solref="0.01 1"/>
		<pair geom1="knob_latch" geom2="door_frame_1" solref="0.01 1"/>
		<pair geom1="knob_latch" geom2="door_frame_2" solref="0.01 1"/>
		<pair geom1="knob_latch" geom2="door_frame_3" solref="0.01 1"/>
	</contact>
	<default>
		<joint armature="1" damping="1" limited="true"/>
		<default class="wall">
			<geom rgba="0.23 0.73 0.02 1.0" type="mesh"/>
		</default>
		<default class="frame">
			<geom rgba="0.81 0.79 0.81 1.0" type="mesh"/>
		</default>
		<default class="door">
			<geom rgba="0.72 0.54 0.36 1.0" type="mesh"/>
		</default>
		<default class="door_knob">
			<geom condim="4" rgba="0.14 0.66 0.25 1.0" type="mesh"/>
		</default>
		<default class="robot">
			<joint damping="0.1"/>
		</default>
	</default>
	<worldbody>
		<light diffuse="1.0 0.9 0.9" dir="0.49 -0.45 -0.48" directional="true" pos="1.66 0.6 4.64"/>
		<light diffuse="0.9 1.0 1.0" dir="0.34 0.01 -0.39" directional="true" pos="3.67 -1.39 5.88"/>
		<light diffuse="0.9 0.9 0.9" dir="-0.34 -0.04 -0.4" directional="true" pos="2.11 -2.01 4.71"/>
		<geom material="Floor" name="floor" pos="0 0 -0.05" size="15.0 15.0 0.05" type="plane"/>
		<camera fovy="60" mode="fixed" name="camera1" pos="0.99 -0.5 1.0" euler="0.0 1.57 1.57"/>
		<camera fovy="60" mode="fixed" name="camera2" pos="0.5 0.0 1.99" euler="0 0 0"/>
		<body childclass="wall" name="wall_link" pos="0.0 0.098 0.0">
			<inertial mass="100" pos="0 0 0" diaginertia="0.0001 0.0001 0.0001"/>
			<geom material="Paint" name="wall_0" pos="-0.15 -1.643 1.1485" size="0.15 1.0 1.1485" type="box" euler="0 0 0"/>
			<geom material="Paint" name="wall_1" pos="-0.15 1.673 1.1485" size="0.15 1.0 1.1485" type="box" euler="0 0 0"/>
			<geom material="Paint" name="wall_2" pos="-0.15 0 2.797" size="0.15 2.673 0.5" type="box" euler="0 0 0"/>
			<body childclass="frame" name="frame_link" pos="0 -0.35525999999999996 0.977">
				<inertial mass="500" pos="0 0 0" diaginertia="0.0001 0.0001 0.0001"/>
				<geom material="Paint" name="door_frame_0" pos="0 -0.27774 0.1715000000000001" size="0.012 0.05 1.1485" type="box" euler="0 0 0"/>
				<geom material="Paint" name="door_frame_1" pos="0 0.9882599999999999 0.1715000000000001" size="0.012 0.05 1.1485" type="box" euler="0 0 0"/>
				<geom material="Paint" name="door_frame_2" pos="0 0.35525999999999996 1.2700000000000002" size="0.012 0.6729999999999999 0.05" type="box" euler="0 0 0"/>
				<geom material="Paint" name="door_frame_3" pos="-0.0435 -0.27774 0.1715000000000001" size="0.012 0.05 1.1485" type="box" euler="0 0 0"/>
				<geom material="Paint" name="door_frame_4" pos="-0.0435 0.9882599999999999 0.1715000000000001" size="0.012 0.05 1.1485" type="box" euler="0 0 0"/>
				<geom material="Paint" name="door_frame_5" pos="-0.0435 0.35525999999999996 1.2700000000000002" size="0.012 0.6729999999999999 0.05" type="box" euler="0 0 0"/>
				<body childclass="door" name="door_link" pos="0 0 0">
					<joint armature="0.0001" axis="0 0 1" damping="1.5" frictionloss="0" limited="true" name="hinge0" pos="0 0.9282599999999999 0" range="-0.0 1.57" stiffness="0.18" type="hinge"/>
					<geom material="Paint" name="door0" pos="0 0.35525999999999996 0.12150000000000005" size="0.012 0.573 1.087515" type="box" euler="0 0 0"/>
					<inertial mass="58.43222049599999" pos="0 0.35525999999999996 0.12150000000000005" diaginertia="29.89842815608349 23.506235394923575 6.397802254327533"/>
					<body childclass="door_knob" name="knob_link" pos="0 0 0">
						<inertial mass="1" pos="0 0 0" diaginertia="0.001 0.001 0.001"/>
						<joint armature="0" axis="0 1 0" damping="30000" frictionloss="0" limited="true" name="target0" range="-0.2 0.3" stiffness="0" type="slide"/>
						<joint armature="0" axis="0 0 1" damping="30000" frictionloss="0" limited="true" name="target1" range="-0.5 0.5" stiffness="0" type="slide"/>
						<joint armature="0.0001" axis="1 0 0" damping="1.61" frictionloss="0" limited="true" name="hinge1" pos="0 0 0" range="-1.3432222222222223 1.3432222222222223" stiffness="1.29" type="hinge"/>
						<body childclass="door_knob" name="leverknob_link" pos="0.012 0 0">
							<geom friction="0.81 0.004 0.002" material="Paint" mesh="door_knob_1" name="door_knob_1" euler="-1.57 1.57 0"/>
							<geom friction="0.81 0.004 0.002" material="Paint" mesh="door_knob_2" name="door_knob_2" euler="-1.57 1.57 0"/>
							<geom friction="0.81 0.004 0.002" material="Paint" mesh="door_knob_3" name="door_knob_3" euler="-1.57 1.57 0"/>
							<geom friction="0.81 0.004 0.002" material="Paint" mesh="door_knob_4" name="door_knob_4" euler="-1.57 1.57 0"/>
							<geom friction="0.81 0.004 0.002" material="Paint" mesh="door_knob_5" name="door_knob_5" euler="-1.57 1.57 0"/>
							<geom material="Wood" name="knob_latch" pos="-0.03375 0 0" size="0.0075 0.2510733333333333 0.05" type="box" euler="0 0 0"/>
							<inertial mass="1" pos="-0.06015 0 0" diaginertia="0.005461484892592591 0.00022708333333333337 0.005271901559259258"/>
						</body>
					</body>
				</body>
			</body>
		</body>
	</worldbody>
</mujoco>